<?xml version="1.0"?>
<robot name="igris_c_v2_parallel_right_wrist">
  <!-- NOTE: In this model, the base link is rotated -90 degree in Z axis to align the motor axis to the Y-axis -->
  <link name="base_link">
    <inertial>
      <mass value="2.428" />
      <origin xyz="0.00453 0.00011 0.15224" />
      <inertia ixx="0.00984" ixy="0.00000" ixz="0.00001" iyy="0.00890" iyz="-0.00003" izz="0.00313" />
    </inertial>
    <visual>
      <origin xyz="0.005 0 0.2395" rpy="0 0 1.570796327"/>
      <geometry>
        <mesh filename="package://igris_c_description/meshes/igris_c_v2/Wrist_Yaw_Right.stl" scale="0.01 0.01 0.01"/>
      </geometry>
      <material name="random">
        <color rgba="0.0706 0.0706 0.0706 0.7" />
      </material>
    </visual>
    <collision>
      <origin xyz="0.005 0 0.2395" rpy="0 0 1.570796327"/>
      <geometry>
        <mesh filename="package://igris_c_description/meshes/igris_c_v2/Wrist_Yaw_Right.stl" scale="0.01 0.01 0.01"/>
      </geometry>
    </collision>
  </link>

  <link name="p_link_1">
    <inertial>
      <mass value="0.012" />
      <origin xyz="0.00604 0.00000 0.00031" />
      <inertia ixx="0.00001" ixy="0.00000" ixz="0.00000" iyy="0.00001" iyz="0.00000" izz="0.00001" />
    </inertial>
    <visual>
      <origin xyz="0 0 0" rpy="0 0 1.570796327"/>
      <geometry>
        <mesh filename="package://igris_c_description/meshes/igris_c_v2/Wrist_Roll_Right.stl" scale="0.01 0.01 0.01"/>
      </geometry>
      <material name="random">
        <color rgba="0.0706 0.0706 0.0706 0.7" />
      </material>
    </visual>
    <collision>
      <geometry>
        <mesh filename="package://igris_c_description/meshes/igris_c_v2/Wrist_Roll_Right.stl" scale="0.01 0.01 0.01"/>
      </geometry>
    </collision>
  </link>

  <link name="p_link_2">
    <inertial>
      <mass value="0.020" />
      <origin xyz="0.01019 0.00000 -0.01687" />
      <inertia ixx="0.00001" ixy="0.00000" ixz="0.00000" iyy="0.00001" iyz="0.00000" izz="0.00001" />
    </inertial>
    <visual>
      <origin xyz="0 0 0" rpy="0 0 1.570796327"/>
      <geometry>
        <mesh filename="package://igris_c_description/meshes/igris_c_v2/Wrist_Pitch_Right.stl" scale="0.01 0.01 0.01"/>
      </geometry>
      <material name="random">
        <color rgba="0.0706 0.0706 0.0706 0.7" />
      </material>
    </visual>
    <collision>
      <geometry>
        <mesh filename="package://igris_c_description/meshes/igris_c_v2/Wrist_Pitch_Right.stl" scale="0.01 0.01 0.01"/>
      </geometry>
    </collision>
  </link>

  <link name="motor_1_output">
    <inertial>
      <mass value="0.009" />
      <origin xyz="0.01879 -0.00357 0.00461" />
      <inertia ixx="0.00001" ixy="0.00000" ixz="0.00000" iyy="0.00001" iyz="0.00000" izz="0.00001" />
    </inertial>
    <visual>
      <origin xyz="0 0 0" rpy="0 0 1.570796327"/>
      <geometry>
        <mesh filename="package://igris_c_description/meshes/igris_c_v2/Wrist_Flange_Front_Right.stl" scale="0.01 0.01 0.01"/>
      </geometry>
      <material name="random">
        <color rgba="0.0706 0.0706 0.0706 0.7" />
      </material>
    </visual>
    <collision>
      <geometry>
        <mesh filename="package://igris_c_description/meshes/igris_c_v2/Wrist_Flange_Front_Right.stl" scale="0.01 0.01 0.01"/>
      </geometry>
    </collision>
  </link>
  
  <link name="motor_2_output">
    <inertial>
      <mass value="0.009" />
      <origin xyz="0.01879 0.00357 0.00461" />
      <inertia ixx="0.00001" ixy="0.00000" ixz="0.00000" iyy="0.00001" iyz="0.00000" izz="0.00001" />
    </inertial>
    <visual>
      <origin xyz="0 0 0" rpy="0 0 1.570796327"/>
      <geometry>
        <mesh filename="package://igris_c_description/meshes/igris_c_v2/Wrist_Flange_Back_Right.stl" scale="0.01 0.01 0.01"/>
      </geometry>
      <material name="random">
        <color rgba="0.0706 0.0706 0.0706 0.7" />
      </material>
    </visual>
    <collision>
      <geometry>
        <mesh filename="package://igris_c_description/meshes/igris_c_v2/Wrist_Flange_Back_Right.stl" scale="0.01 0.01 0.01"/>
      </geometry>
    </collision>
  </link>

  <joint name="joint_1" type="revolute">
    <parent link="base_link" />
    <child link="p_link_1" />
    <origin xyz="0 0 0" rpy="0 0 0" />
    <axis xyz="0 1 0"/>
    <limit lower="-0.872664626" upper="1.221730476" effort="1000" velocity="100.0" />
  </joint>

  <joint name="joint_2" type="revolute">
    <parent link="p_link_1" />
    <child link="p_link_2" />
    <origin xyz="0 0 0" rpy="0 0 0" />
    <axis xyz="-1 0 0" />
    <limit lower="-0.698131701" upper="0.698131701" effort="1000" velocity="100.0" />
  </joint>

  <joint name="motor_1" type="revolute">
    <parent link="base_link" />
    <child link="motor_1_output" />
    <origin xyz="-0.004341 0.02000 0.02462" rpy="0 0 0" />
    <axis xyz="0 1 0" />
    <limit lower="-1.570796327" upper="1.570796327" effort="1000" velocity="100.0" />
  </joint>

  <joint name="motor_2" type="revolute">
    <parent link="base_link" />
    <child link="motor_2_output" />
    <origin xyz="-0.004341 -0.02000 0.02462" rpy="0 0 0" />
    <axis xyz="0 1 0" />
    <limit lower="-1.570796327" upper="1.570796327" effort="1000" velocity="100.0" />
  </joint>
</robot>