<?xml version="1.0"?>
<robot name="igris_c_v2_parallel">

  <link name="base_link">
    <inertial>
      <mass value="12.974" />
      <origin xyz="0.00175 0.00112 0.15154" />
      <inertia ixx="0.15110" ixy="-0.00136" ixz="0.00843" iyy="0.12880" iyz="-0.00089" izz="0.08070" />
    </inertial>
    <visual>
      <geometry>
        <mesh filename="package://igris_c_description_public/meshes/igris_c_v2/Waist_Yaw.stl" scale="0.01 0.01 0.01"/>
      </geometry>
      <material name="random">
        <color rgba="0.0706 0.0706 0.0706 0.7" />
      </material>
    </visual>
    <collision>
      <geometry>
        <mesh filename="package://igris_c_description_public/meshes/igris_c_v2/Waist_Yaw.stl" scale="0.01 0.01 0.01"/>
      </geometry>
    </collision>
  </link>

  <link name="Link_Waist_Yaw">
    <inertial>
      <mass value="0.208" />
      <origin xyz="0.02597 0.00000 -0.00927" />
      <inertia ixx="0.00031" ixy="0.00000" ixz="0.00003" iyy="0.00031" iyz="0.00000" izz="0.00058" />
    </inertial>
    <visual>
      <geometry>
        <mesh filename="package://igris_c_description_public/meshes/igris_c_v2/Waist_Yaw_B.stl" scale="0.01 0.01 0.01"/>
      </geometry>
      <material name="random">
        <color rgba="0.0706 0.0706 0.0706 0.7" />
      </material>
    </visual>
    <collision>
      <geometry>
        <mesh filename="package://igris_c_description_public/meshes/igris_c_v2/Waist_Yaw_B.stl" scale="0.01 0.01 0.01"/>
      </geometry>
    </collision>
  </link>

  <link name="Link_Waist_Roll">
    <inertial>
      <mass value="0.136" />
      <origin xyz="0.00000 0.00000 -0.00829" />
      <inertia ixx="0.00005" ixy="0.00000" ixz="0.00000" iyy="0.00011" iyz="0.00000" izz="0.00007" />
    </inertial>
    <visual>
      <geometry>
        <mesh filename="package://igris_c_description_public/meshes/igris_c_v2/Waist_Roll_B.stl" scale="0.01 0.01 0.01"/>
      </geometry>
      <material name="random">
        <color rgba="0.0706 0.0706 0.0706 0.7" />
      </material>
    </visual>
    <collision>
      <geometry>
        <mesh filename="package://igris_c_description_public/meshes/igris_c_v2/Waist_Roll_B.stl" scale="0.01 0.01 0.01"/>
      </geometry>
    </collision>
  </link>


  <link name="Link_Waist_Pitch">
    <inertial>
      <mass value="8.124" />
      <origin xyz="-0.03810 -0.00001 0.08837" />
      <inertia ixx="0.04342" ixy="0.00001" ixz="0.00325" iyy="0.05156" iyz="0.00000" izz="0.04212" />
    </inertial>
    <visual>
      <geometry>
        <mesh filename="package://igris_c_description_public/meshes/igris_c_v2/Waist_Pitch_B.stl" scale="0.01 0.01 0.01"/>
      </geometry>
      <material name="random">
        <color rgba="0.0706 0.0706 0.0706 0.7" />
      </material>
    </visual>
    <collision>
      <geometry>
        <mesh filename="package://igris_c_description_public/meshes/igris_c_v2/Waist_Pitch_B.stl" scale="0.01 0.01 0.01"/>
      </geometry>
    </collision>
  </link>
 
 
  <link name="Link_Waist_Flange_Left">
    <inertial>
      <mass value="0.043" />
      <origin xyz="-0.01470 -0.00883 -0.00167" />
      <inertia ixx="0.00001" ixy="0.00000" ixz="0.00000" iyy="0.00004" iyz="0.00000" izz="0.00003" />
    </inertial>
    <visual>
      <geometry>
        <mesh filename="package://igris_c_description_public/meshes/igris_c_v2/Waist_Flange_Left.stl" scale="0.01 0.01 0.01"/>
      </geometry>
      <material name="random">
        <color rgba="0.0706 0.0706 0.0706 0.7" />
      </material>
    </visual>
    <collision>
      <geometry>
        <mesh filename="package://igris_c_description_public/meshes/igris_c_v2/Waist_Flange_Left.stl" scale="0.01 0.01 0.01"/>
      </geometry>
    </collision>
  </link>



  <link name="Link_Waist_Parallel_Left">
    <inertial>
      <mass value="0.030" />
      <origin xyz="0.00083 0.00172 0.02995" />
      <inertia ixx="0.00002" ixy="0.00000" ixz="0.00000" iyy="0.00002" iyz="0.00000" izz="0.00001" />
    </inertial>
    <visual>
      <geometry>
        <mesh filename="package://igris_c_description_public/meshes/igris_c_v2/Waist_Parallel_Left.stl" scale="0.01 0.01 0.01"/>
      </geometry>
      <material name="random">
        <color rgba="0.0706 0.0706 0.0706 0.7" />
      </material>
    </visual>
    <collision>
      <geometry>
        <mesh filename="package://igris_c_description_public/meshes/igris_c_v2/Waist_Parallel_Left.stl" scale="0.01 0.01 0.01"/>
      </geometry>
    </collision>
  </link>



  <link name="Link_Waist_Flange_Right">
    <inertial>
      <mass value="0.043" />
      <origin xyz="-0.01470 0.00883 -0.00167" />
      <inertia ixx="0.00001" ixy="0.00000" ixz="0.00000" iyy="0.00004" iyz="0.00000" izz="0.00003" />
    </inertial>
    <visual>
      <geometry>
        <mesh filename="package://igris_c_description_public/meshes/igris_c_v2/Waist_Flange_Right.stl" scale="0.01 0.01 0.01"/>
      </geometry>
      <material name="random">
        <color rgba="0.0706 0.0706 0.0706 0.7" />
      </material>
    </visual>
    <collision>
      <geometry>
        <mesh filename="package://igris_c_description_public/meshes/igris_c_v2/Waist_Flange_Right.stl" scale="0.01 0.01 0.01"/>
      </geometry>
    </collision>
  </link>


  <link name="Link_Waist_Parallel_Right">
    <inertial>
      <mass value="0.030" />
      <origin xyz="0.00083 -0.00172 0.02995" />
      <inertia ixx="0.00002" ixy="0.00000" ixz="0.00000" iyy="0.00002" iyz="0.00000" izz="0.000001" />
    </inertial>
    <visual>
      <geometry>
        <mesh filename="package://igris_c_description_public/meshes/igris_c_v2/Waist_Parallel_Right.stl" scale="0.01 0.01 0.01"/>
      </geometry>
      <material name="random">
        <color rgba="0.0706 0.0706 0.0706 0.7" />
      </material>
    </visual>
    <collision>
      <geometry>
        <mesh filename="package://igris_c_description_public/meshes/igris_c_v2/Waist_Parallel_Right.stl" scale="0.01 0.01 0.01"/>
      </geometry>
    </collision>
  </link>



  <!-- LEFT LEG -->
  <link name="Link_Hip_Pitch_Left">
    <inertial>
      <mass value="1.894" />
      <origin xyz="0.00973 -0.00102 0.00002" />
      <inertia ixx="0.00261" ixy="-0.00001" ixz="0.00000" iyy="0.00267" iyz="0.00000" izz="0.00258" />
    </inertial>
    <visual>
      <geometry>
        <mesh filename="package://igris_c_description_public/meshes/igris_c_v2/Hip_Pitch_Left.stl" scale="0.01 0.01 0.01"/>
      </geometry>
      <material name="random">
        <color rgba="0.0706 0.0706 0.0706 0.7" />
      </material>
    </visual>
    <collision>
      <geometry>
        <mesh filename="package://igris_c_description_public/meshes/igris_c_v2/Hip_Pitch_Left.stl" scale="0.01 0.01 0.01"/>
      </geometry>
    </collision>
  </link>

  <link name="Link_Hip_Roll_Left">
    <inertial>
      <mass value="0.573" />
      <origin xyz="-0.01497 0.00570 -0.03564" />
      <inertia ixx="0.00103" ixy="-0.00006" ixz="0.00012" iyy="0.00226" iyz="0.00006" izz="0.00206" />
    </inertial>
    <visual>
      <geometry>
        <mesh filename="package://igris_c_description_public/meshes/igris_c_v2/Hip_Roll_Left.stl" scale="0.01 0.01 0.01"/>
      </geometry>
      <material name="random">
        <color rgba="0.0706 0.0706 0.0706 0.7" />
      </material>
    </visual>
    <collision>
      <geometry>
        <mesh filename="package://igris_c_description_public/meshes/igris_c_v2/Hip_Roll_Left.stl" scale="0.01 0.01 0.01"/>
      </geometry>
    </collision>
  </link>

  <link name="Link_Hip_Yaw_Left">
    <inertial>
      <mass value="4.813" />
      <origin xyz="-0.01286 -0.00388 -0.10563" />
      <inertia ixx="0.03161" ixy="-0.00007" ixz="-0.00101" iyy="0.03396" iyz="-0.00084" izz="0.01135" />
    </inertial>
    <visual>
      <geometry>
        <mesh filename="package://igris_c_description_public/meshes/igris_c_v2/Hip_Yaw_Left.stl" scale="0.01 0.01 0.01"/>
      </geometry>
      <material name="random">
        <color rgba="0.0706 0.0706 0.0706 0.7" />
      </material>
    </visual>
    <collision>
      <geometry>
        <mesh filename="package://igris_c_description_public/meshes/igris_c_v2/Hip_Yaw_Left.stl" scale="0.01 0.01 0.01"/>
      </geometry>
    </collision>
  </link>

  <link name="Link_Knee_Pitch_Left">
    <inertial>
      <mass value="3.212" />
      <origin xyz="0.01044 0.00096 -0.12320" />
      <inertia ixx="0.02686" ixy="0.00000" ixz="-0.00201" iyy="0.02845" iyz="-0.00048" izz="0.00520" />
    </inertial>
    <visual>
      <geometry>
        <mesh filename="package://igris_c_description_public/meshes/igris_c_v2/Knee_Pitch_Left.stl" scale="0.01 0.01 0.01"/>
      </geometry>
      <material name="random">
        <color rgba="0.0706 0.0706 0.0706 0.7" />
      </material>
    </visual>
    <collision>
      <geometry>
        <mesh filename="package://igris_c_description_public/meshes/igris_c_v2/Knee_Pitch_Left.stl" scale="0.01 0.01 0.01"/>
      </geometry>
    </collision>
  </link>

  <link name="Link_Ankle_Pitch_Left">
    <inertial>
      <mass value="0.084" />
      <origin xyz="0.00000 0.00000 0.00000" />
      <inertia ixx="0.00003" ixy="0.00000" ixz="0.00000" iyy="0.00002" iyz="0.00000" izz="0.00003" />
    </inertial>
    <visual>
      <geometry>
        <mesh filename="package://igris_c_description_public/meshes/igris_c_v2/Ankle_Pitch_Left.stl" scale="0.01 0.01 0.01"/>
      </geometry>
      <material name="random">
        <color rgba="0.0706 0.0706 0.0706 0.7" />
      </material>
    </visual>
    <collision>
      <geometry>
        <mesh filename="package://igris_c_description_public/meshes/igris_c_v2/Ankle_Pitch_Left.stl" scale="0.01 0.01 0.01"/>
      </geometry>
    </collision>
  </link>

  <link name="Link_Ankle_Roll_Left">
    <inertial>
      <mass value="0.459" />
      <origin xyz="0.02167 0.00000 -0.05193" />
      <inertia ixx="0.00045" ixy="0.00000" ixz="0.00024" iyy="0.00166" iyz="0.00000" izz="0.00158" />
    </inertial>
    <visual>
      <geometry>
        <mesh filename="package://igris_c_description_public/meshes/igris_c_v2/Ankle_Roll_Left.stl" scale="0.01 0.01 0.01"/>
      </geometry>
      <material name="random">
        <color rgba="0.0706 0.0706 0.0706 0.7" />
      </material>
    </visual>
    <collision>
      <geometry>
        <mesh filename="package://igris_c_description_public/meshes/igris_c_v2/Ankle_Roll_Left.stl" scale="0.01 0.01 0.01"/>
      </geometry>
    </collision>
  </link>

  <link name="Link_Ankle_Flange_Out_Left">
    <inertial>
      <mass value="0.026" />
      <origin xyz="-0.01128 -0.00742 -0.00003" />
      <inertia ixx="0.00001" ixy="0.00000" ixz="0.00000" iyy="0.00002" iyz="0.00000" izz="0.00001" />
    </inertial>
    <visual>
      <geometry>
        <mesh filename="package://igris_c_description_public/meshes/igris_c_v2/Ankle_Flange_Out_Left.stl" scale="0.01 0.01 0.01"/>
      </geometry>
      <material name="random">
        <color rgba="0.0706 0.0706 0.0706 0.7" />
      </material>
    </visual>
    <collision>
      <geometry>
        <mesh filename="package://igris_c_description_public/meshes/igris_c_v2/Ankle_Flange_Out_Left.stl" scale="0.01 0.01 0.01"/>
      </geometry>
    </collision>
  </link>

  <link name="Link_Ankle_Parallel_Out_Left">
    <inertial>
      <mass value="0.130" />
      <origin xyz="0.00183 -0.00357 -0.13606" />
      <inertia ixx="0.00092" ixy="0.00000" ixz="0.00001" iyy="0.00092" iyz="-0.00002" izz="0.000001" />
    </inertial>
    <visual>
      <geometry>
        <mesh filename="package://igris_c_description_public/meshes/igris_c_v2/Ankle_Parallel_Out_Left.stl" scale="0.01 0.01 0.01"/>
      </geometry>
      <material name="random">
        <color rgba="0.0706 0.0706 0.0706 0.7" />
      </material>
    </visual>
    <collision>
      <geometry>
        <mesh filename="package://igris_c_description_public/meshes/igris_c_v2/Ankle_Parallel_Out_Left.stl" scale="0.01 0.01 0.01"/>
      </geometry>
    </collision>
  </link>

  <link name="Link_Ankle_Flange_In_Left">
    <inertial>
      <mass value="0.026" />
      <origin xyz="-0.01128 0.00742 -0.00006" />
      <inertia ixx="0.00001" ixy="0.00000" ixz="0.00000" iyy="0.00002" iyz="0.00000" izz="0.00001" />
    </inertial>
    <visual>
      <geometry>
        <mesh filename="package://igris_c_description_public/meshes/igris_c_v2/Ankle_Flange_In_Left.stl" scale="0.01 0.01 0.01"/>
      </geometry>
      <material name="random">
        <color rgba="0.0706 0.0706 0.0706 0.7" />
      </material>
    </visual>
    <collision>
      <geometry>
        <mesh filename="package://igris_c_description_public/meshes/igris_c_v2/Ankle_Flange_In_Left.stl" scale="0.01 0.01 0.01"/>
      </geometry>
    </collision>
  </link>

  <link name="Link_Ankle_Parallel_In_Left">
    <inertial>
      <mass value="0.083" />
      <origin xyz="0.00187 0.00365 -0.08089" />
      <inertia ixx="0.00022" ixy="0.00000" ixz="0.00001" iyy="0.00022" iyz="0.00001" izz="0.000001" />
    </inertial>
    <visual>
      <geometry>
        <mesh filename="package://igris_c_description_public/meshes/igris_c_v2/Ankle_Parallel_In_Left.stl" scale="0.01 0.01 0.01"/>
      </geometry>
      <material name="random">
        <color rgba="0.0706 0.0706 0.0706 0.7" />
      </material>
    </visual>
    <collision>
      <geometry>
        <mesh filename="package://igris_c_description_public/meshes/igris_c_v2/Ankle_Parallel_In_Left.stl" scale="0.01 0.01 0.01"/>
      </geometry>
    </collision>
  </link>

  <!-- RIGHT LEG -->
  <link name="Link_Hip_Pitch_Right">
    <inertial>
      <mass value="1.894" />
      <origin xyz="0.00973 0.00102 -0.00002" />
      <inertia ixx="0.00261" ixy="0.00001" ixz="0.00000" iyy="0.00267" iyz="0.00000" izz="0.00258" />
    </inertial>
    <visual>
      <geometry>
        <mesh filename="package://igris_c_description_public/meshes/igris_c_v2/Hip_Pitch_Right.stl" scale="0.01 0.01 0.01"/>
      </geometry>
      <material name="random">
        <color rgba="0.0706 0.0706 0.0706 0.7" />
      </material>
    </visual>
    <collision>
      <geometry>
        <mesh filename="package://igris_c_description_public/meshes/igris_c_v2/Hip_Pitch_Right.stl" scale="0.01 0.01 0.01"/>
      </geometry>
    </collision>
  </link>

  <link name="Link_Hip_Roll_Right">
    <inertial>
      <mass value="0.573" />
      <origin xyz="-0.01497 -0.00570 -0.03564" />
      <inertia ixx="0.00103" ixy="0.00006" ixz="0.00012" iyy="0.00226" iyz="-0.00006" izz="0.00206" />
    </inertial>
    <visual>
      <geometry>
        <mesh filename="package://igris_c_description_public/meshes/igris_c_v2/Hip_Roll_Right.stl" scale="0.01 0.01 0.01"/>
      </geometry>
      <material name="random">
        <color rgba="0.0706 0.0706 0.0706 0.7" />
      </material>
    </visual>
    <collision>
      <geometry>
        <mesh filename="package://igris_c_description_public/meshes/igris_c_v2/Hip_Roll_Right.stl" scale="0.01 0.01 0.01"/>
      </geometry>
    </collision>
  </link>

  <link name="Link_Hip_Yaw_Right">
    <inertial>
      <mass value="4.813" />
      <origin xyz="-0.01286 0.00388 -0.10564" />
      <inertia ixx="0.03161" ixy="0.00007" ixz="-0.00101" iyy="0.03398" iyz="0.00084" izz="0.01137" />
    </inertial>
    <visual>
      <geometry>
        <mesh filename="package://igris_c_description_public/meshes/igris_c_v2/Hip_Yaw_Right.stl" scale="0.01 0.01 0.01"/>
      </geometry>
      <material name="random">
        <color rgba="0.0706 0.0706 0.0706 0.7" />
      </material>
    </visual>
    <collision>
      <geometry>
        <mesh filename="package://igris_c_description_public/meshes/igris_c_v2/Hip_Yaw_Right.stl" scale="0.01 0.01 0.01"/>
      </geometry>
    </collision>
  </link>

  <link name="Link_Knee_Pitch_Right">
    <inertial>
      <mass value="3.212" />
      <origin xyz="0.01044 -0.00096 -0.12320" />
      <inertia ixx="0.02686" ixy="0.00000" ixz="-0.00201" iyy="0.02845" iyz="0.00048" izz="0.00520" />
    </inertial>
    <visual>
      <geometry>
        <mesh filename="package://igris_c_description_public/meshes/igris_c_v2/Knee_Pitch_Right.stl" scale="0.01 0.01 0.01"/>
      </geometry>
      <material name="random">
        <color rgba="0.0706 0.0706 0.0706 0.7" />
      </material>
    </visual>
    <collision>
      <geometry>
        <mesh filename="package://igris_c_description_public/meshes/igris_c_v2/Knee_Pitch_Right.stl" scale="0.01 0.01 0.01"/>
      </geometry>
    </collision>
  </link>

  <link name="Link_Ankle_Pitch_Right">
    <inertial>
      <mass value="0.084" />
      <origin xyz="0 0 0" />
      <inertia ixx="0.00003" ixy="0.00000" ixz="0.00000" iyy="0.00002" iyz="0.00000" izz="0.00003" />
    </inertial>
    <visual>
      <geometry>
        <mesh filename="package://igris_c_description_public/meshes/igris_c_v2/Ankle_Pitch_Right.stl" scale="0.01 0.01 0.01"/>
      </geometry>
      <material name="random">
        <color rgba="0.0706 0.0706 0.0706 0.7" />
      </material>
    </visual>
    <collision>
      <geometry>
        <mesh filename="package://igris_c_description_public/meshes/igris_c_v2/Ankle_Pitch_Right.stl" scale="0.01 0.01 0.01"/>
      </geometry>
    </collision>
  </link>

  <link name="Link_Ankle_Roll_Right">
    <inertial>
      <mass value="0.459" />
      <origin xyz="0.02167 0.00000 -0.05193" />
      <inertia ixx="0.00045" ixy="0.00000" ixz="0.00024" iyy="0.00166" iyz="0.00000" izz="0.00158" />
    </inertial>
    <visual>
      <geometry>
        <mesh filename="package://igris_c_description_public/meshes/igris_c_v2/Ankle_Roll_Right.stl" scale="0.01 0.01 0.01"/>
      </geometry>
      <material name="random">
        <color rgba="0.0706 0.0706 0.0706 0.7" />
      </material>
    </visual>
    <collision>
      <geometry>
        <mesh filename="package://igris_c_description_public/meshes/igris_c_v2/Ankle_Roll_Right.stl" scale="0.01 0.01 0.01"/>
      </geometry>
    </collision>
  </link>

  <link name="Link_Ankle_Flange_Out_Right">
    <inertial>
      <mass value="0.026" />
      <origin xyz="-0.01128 0.00742 -0.00003" />
      <inertia ixx="0.00001" ixy="0.00000" ixz="0.00000" iyy="0.00002" iyz="0.00000" izz="0.00001" />
    </inertial>
    <visual>
      <geometry>
        <mesh filename="package://igris_c_description_public/meshes/igris_c_v2/Ankle_Flange_Out_Right.stl" scale="0.01 0.01 0.01"/>
      </geometry>
      <material name="random">
        <color rgba="0.0706 0.0706 0.0706 0.7" />
      </material>
    </visual>
    <collision>
      <geometry>
        <mesh filename="package://igris_c_description_public/meshes/igris_c_v2/Ankle_Flange_Out_Right.stl" scale="0.01 0.01 0.01"/>
      </geometry>
    </collision>
  </link>

  <link name="Link_Ankle_Parallel_Out_Right">
    <inertial>
      <mass value="0.062" />
      <origin xyz="0.00147 0.00277 -0.10914" />
      <inertia ixx="0.00049" ixy="0.00000" ixz="0.00001" iyy="0.00050" iyz="0.00001" izz="0.00000" />
    </inertial>
    <visual>
      <geometry>
        <mesh filename="package://igris_c_description_public/meshes/igris_c_v2/Ankle_Parallel_Out_Right.stl" scale="0.01 0.01 0.01"/>
      </geometry>
      <material name="random">
        <color rgba="0.0706 0.0706 0.0706 0.7" />
      </material>
    </visual>
    <collision>
      <geometry>
        <mesh filename="package://igris_c_description_public/meshes/igris_c_v2/Ankle_Parallel_Out_Right.stl" scale="0.01 0.01 0.01"/>
      </geometry>
    </collision>
  </link>

  <link name="Link_Ankle_Flange_In_Right">
    <inertial>
      <mass value="0.026" />
      <origin xyz="-0.01128 -0.00742 -0.00006" />
      <inertia ixx="0.00001" ixy="0.00000" ixz="0.00000" iyy="0.00002" iyz="0.00000" izz="0.00001" />
    </inertial>
    <visual>
      <geometry>
        <mesh filename="package://igris_c_description_public/meshes/igris_c_v2/Ankle_Flange_In_Right.stl" scale="0.01 0.01 0.01"/>
      </geometry>
      <material name="random">
        <color rgba="0.0706 0.0706 0.0706 0.7" />
      </material>
    </visual>
    <collision>
      <geometry>
        <mesh filename="package://igris_c_description_public/meshes/igris_c_v2/Ankle_Flange_In_Right.stl" scale="0.01 0.01 0.01"/>
      </geometry>
    </collision>
  </link>

  <link name="Link_Ankle_Parallel_In_Right">
    <inertial>
      <mass value="0.046" />
      <origin xyz="0.00144 -0.00267 -0.06221" />
      <inertia ixx="0.00012" ixy="0.00000" ixz="0.00000" iyy="0.00012" iyz="-0.00001" izz="0.00000" />
    </inertial>
    <visual>
      <geometry>
        <mesh filename="package://igris_c_description_public/meshes/igris_c_v2/Ankle_Parallel_In_Right.stl" scale="0.01 0.01 0.01"/>
      </geometry>
      <material name="random">
        <color rgba="0.0706 0.0706 0.0706 0.7" />
      </material>
    </visual>
    <collision>
      <geometry>
        <mesh filename="package://igris_c_description_public/meshes/igris_c_v2/Ankle_Parallel_In_Right.stl" scale="0.01 0.01 0.01"/>
      </geometry>
    </collision>
  </link>

  <!-- LEFT ARM -->
  <link name="Link_Shoulder_Pitch_Left">
    <inertial>
      <mass value="1.105" />
      <origin xyz="0.00039 -0.00330 0.00004" />
      <inertia ixx="0.00118" ixy="0.00001" ixz="0.00000" iyy="0.00097" iyz="0.00000" izz="0.00107" />
    </inertial>
    <visual>
      <geometry>
        <mesh filename="package://igris_c_description_public/meshes/igris_c_v2/Shoulder_Pitch_Left.stl" scale="0.01 0.01 0.01"/>
      </geometry>
      <material name="random">
        <color rgba="0.0706 0.0706 0.0706 0.7" />
      </material>
    </visual>
    <collision>
      <geometry>
        <mesh filename="package://igris_c_description_public/meshes/igris_c_v2/Shoulder_Pitch_Left.stl" scale="0.01 0.01 0.01"/>
      </geometry>
    </collision>
  </link>

  <link name="Link_Shoulder_Roll_Left">
    <inertial>
      <mass value="0.253" />
      <origin xyz="0.02322 0.00000 -0.03100" />
      <inertia ixx="0.00046" ixy="0.00000" ixz="-0.00013" iyy="0.00046" iyz="0.00000" izz="0.00034" />
    </inertial>
    <visual>
      <geometry>
        <mesh filename="package://igris_c_description_public/meshes/igris_c_v2/Shoulder_Roll_Left.stl" scale="0.01 0.01 0.01"/>
      </geometry>
      <material name="random">
        <color rgba="0.0706 0.0706 0.0706 0.7" />
      </material>
    </visual>
    <collision>
      <geometry>
        <mesh filename="package://igris_c_description_public/meshes/igris_c_v2/Shoulder_Roll_Left.stl" scale="0.01 0.01 0.01"/>
      </geometry>
    </collision>
  </link>

  <link name="Link_Shoulder_Yaw_Left">
    <inertial>
      <mass value="2.144" />
      <origin xyz="0.00289 0.00039 -0.14632" />
      <inertia ixx="0.00708" ixy="0.00000" ixz="0.00045" iyy="0.00723" iyz="0.00002" izz="0.00213" />
    </inertial>
    <visual>
      <geometry>
        <mesh filename="package://igris_c_description_public/meshes/igris_c_v2/Shoulder_Yaw_Left.stl" scale="0.01 0.01 0.01"/>
      </geometry>
      <material name="random">
        <color rgba="0.0706 0.0706 0.0706 0.7" />
      </material>
    </visual>
    <collision>
      <geometry>
        <mesh filename="package://igris_c_description_public/meshes/igris_c_v2/Shoulder_Yaw_Left.stl" scale="0.01 0.01 0.01"/>
      </geometry>
    </collision>
  </link>

  <link name="Link_Elbow_Pitch_Left">
    <inertial>
      <mass value="0.137" />
      <origin xyz="-0.00506 0.02516 -0.02257" />
      <inertia ixx="0.00017" ixy="-0.00001" ixz="-0.00002" iyy="0.00017" iyz="-0.00005" izz="0.00013" />
    </inertial>
    <visual>
      <geometry>
        <mesh filename="package://igris_c_description_public/meshes/igris_c_v2/Elbow_Pitch_Left.stl" scale="0.01 0.01 0.01"/>
      </geometry>
      <material name="random">
        <color rgba="0.0706 0.0706 0.0706 0.7" />
      </material>
    </visual>
    <collision>
      <geometry>
        <mesh filename="package://igris_c_description_public/meshes/igris_c_v2/Elbow_Pitch_Left.stl" scale="0.01 0.01 0.01"/>
      </geometry>
    </collision>
  </link>

  <link name="Link_Wrist_Yaw_Left">
    <inertial>
      <mass value="2.428" />
      <origin xyz="-0.00010 -0.00047 -0.08726" />
      <inertia ixx="0.00890" ixy="0.00000" ixz="-0.00003" iyy="0.00984" iyz="-0.00002" izz="0.00313" />
    </inertial>
    <visual>
      <geometry>
        <mesh filename="package://igris_c_description_public/meshes/igris_c_v2/Wrist_Yaw_Left.stl" scale="0.01 0.01 0.01"/>
      </geometry>
      <material name="random">
        <color rgba="0.0706 0.0706 0.0706 0.7" />
      </material>
    </visual>
    <collision>
      <geometry>
        <mesh filename="package://igris_c_description_public/meshes/igris_c_v2/Wrist_Yaw_Left.stl" scale="0.01 0.01 0.01"/>
      </geometry>
    </collision>
  </link>

  <link name="Link_Wrist_Flange_Front_Left">
    <inertial>
      <mass value="0.009" />
      <origin xyz="-0.00357 0.01879 0.00461" />
      <inertia ixx="0.00001" ixy="0.00000" ixz="0.00000" iyy="0.00001" iyz="0.00000" izz="0.00001" />
    </inertial>
    <visual>
      <geometry>
        <mesh filename="package://igris_c_description_public/meshes/igris_c_v2/Wrist_Flange_Front_Left.stl" scale="0.01 0.01 0.01"/>
      </geometry>
      <material name="random">
        <color rgba="0.0706 0.0706 0.0706 0.7" />
      </material>
    </visual>
    <collision>
      <geometry>
        <mesh filename="package://igris_c_description_public/meshes/igris_c_v2/Wrist_Flange_Front_Left.stl" scale="0.01 0.01 0.01"/>
      </geometry>
    </collision>
  </link>


  <link name="Link_Wrist_Flange_Back_Left">
    <inertial>
      <mass value="0.009" />
      <origin xyz="0.00357 0.01879 0.00461" />
      <inertia ixx="0.00001" ixy="0.00000" ixz="0.00000" iyy="0.00001" iyz="0.00000" izz="0.00001" />
    </inertial>
    <visual>
      <geometry>
        <mesh filename="package://igris_c_description_public/meshes/igris_c_v2/Wrist_Flange_Back_Left.stl" scale="0.01 0.01 0.01"/>
      </geometry>
      <material name="random">
        <color rgba="0.0706 0.0706 0.0706 0.7" />
      </material>
    </visual>
    <collision>
      <geometry>
        <mesh filename="package://igris_c_description_public/meshes/igris_c_v2/Wrist_Flange_Back_Left.stl" scale="0.01 0.01 0.01"/>
      </geometry>
    </collision>
  </link>

  <link name="Link_Wrist_Roll_Left">
    <inertial>
      <mass value="0.012" />
      <origin xyz="0.00000 0.00604 0.00031" />
      <inertia ixx="0.00001" ixy="0.00000" ixz="0.00000" iyy="0.00001" iyz="0.00000" izz="0.00001" />
    </inertial>
    <visual>
      <geometry>
        <mesh filename="package://igris_c_description_public/meshes/igris_c_v2/Wrist_Roll_Left.stl" scale="0.01 0.01 0.01"/>
      </geometry>
      <material name="random">
        <color rgba="0.0706 0.0706 0.0706 0.7" />
      </material>
    </visual>
    <collision>
      <geometry>
        <mesh filename="package://igris_c_description_public/meshes/igris_c_v2/Wrist_Roll_Left.stl" scale="0.01 0.01 0.01"/>
      </geometry>
    </collision>
  </link>

  <link name="Link_Wrist_Pitch_Left">
    <inertial>
      <mass value="0.020" />
      <origin xyz="0 0.01019 -0.01687" />
      <inertia ixx="0.00000" ixy="0.00000" ixz="0.00000" iyy="0.00000" iyz="0.00000" izz="0.00000" />
    </inertial>
    <visual>
      <geometry>
        <mesh filename="package://igris_c_description_public/meshes/igris_c_v2/Wrist_Pitch_Left.stl" scale="0.01 0.01 0.01"/>
      </geometry>
      <material name="random">
        <color rgba="0.0706 0.0706 0.0706 0.7" />
      </material>
    </visual>
    <collision>
      <geometry>
        <mesh filename="package://igris_c_description_public/meshes/igris_c_v2/Wrist_Pitch_Left.stl" scale="0.01 0.01 0.01"/>
      </geometry>
    </collision>
  </link>

  <link name="Left_Hand">
    <inertial>
      <mass value="0.333" />
      <origin xyz="0.00910 0.00371 0.07839" />
      <inertia ixx="0.00081" ixy="-0.00004" ixz="0.00012" iyy="0.00117" iyz="0.00005" izz="0.00042" />
    </inertial>
    <visual>
      <geometry>
        <mesh filename="package://igris_c_description_public/meshes/igris_c_v2/Hand_Left.stl" scale="0.01 0.01 0.01"/>
      </geometry>
      <material name="random">
        <color rgba="0.0706 0.0706 0.0706 0.7" />
      </material>
    </visual>
    <collision>
        <geometry>
          <mesh filename="package://igris_c_description_public/meshes/igris_c_v2/Hand_Left.stl" scale="0.01 0.01 0.01"/>
        </geometry>
    </collision>
  </link>

  <link name="Link_Wrist_Universal_Front_Left">
    <inertial>
      <mass value="0.002" />
      <origin xyz="0.00000 -0.00189 -0.00004" />
      <inertia ixx="0.00001" ixy="0.00000" ixz="0.00000" iyy="0.00001" iyz="0.00000" izz="0.00001" />
    </inertial>
    <visual>
      <geometry>
        <mesh filename="package://igris_c_description_public/meshes/igris_c_v2/Wrist_Universal_Front_Left.stl" scale="0.01 0.01 0.01"/>
      </geometry>
      <material name="random">
        <color rgba="0.0706 0.0706 0.0706 0.7" />
      </material>
    </visual>
    <collision>
      <geometry>
        <mesh filename="package://igris_c_description_public/meshes/igris_c_v2/Wrist_Universal_Front_Left.stl" scale="0.01 0.01 0.01"/>
      </geometry>
    </collision>
  </link>

  <link name="Link_Wrist_Parallel_Front_Left">
    <inertial>
      <mass value="0.017" />
      <origin xyz="-0.00094 -0.00038 -0.01026" />
      <inertia ixx="0.00001" ixy="0.00000" ixz="0.00000" iyy="0.00001" iyz="0.00000" izz="0.00001" />
    </inertial>
    <visual>
      <geometry>
        <mesh filename="package://igris_c_description_public/meshes/igris_c_v2/Wrist_Parallel_Front_Left.stl" scale="0.01 0.01 0.01"/>
      </geometry>
      <material name="random">
        <color rgba="0.0706 0.0706 0.0706 0.7" />
      </material>
    </visual>
    <collision>
      <geometry>
        <mesh filename="package://igris_c_description_public/meshes/igris_c_v2/Wrist_Parallel_Front_Left.stl" scale="0.01 0.01 0.01"/>
      </geometry>
    </collision>
  </link>

  <link name="Link_Wrist_Universal_Back_Left">
    <inertial>
      <mass value="0.002" />
      <origin xyz="0.00000 -0.00189 -0.00004" />
      <inertia ixx="0.00001" ixy="0.00000" ixz="0.00000" iyy="0.00001" iyz="0.00000" izz="0.00001" />
    </inertial>
    <visual>
      <geometry>
        <mesh filename="package://igris_c_description_public/meshes/igris_c_v2/Wrist_Universal_Back_Left.stl" scale="0.01 0.01 0.01"/>
      </geometry>
      <material name="random">
        <color rgba="0.0706 0.0706 0.0706 0.7" />
      </material>
    </visual>
    <collision>
      <geometry>
        <mesh filename="package://igris_c_description_public/meshes/igris_c_v2/Wrist_Universal_Back_Left.stl" scale="0.01 0.01 0.01"/>
      </geometry>
    </collision>
  </link>

  <link name="Link_Wrist_Parallel_Back_Left">
    <inertial>
      <mass value="0.017" />
      <origin xyz="0.00094 -0.00038 -0.01026" />
      <inertia ixx="0.00001" ixy="0.00000" ixz="0.00000" iyy="0.00001" iyz="0.00000" izz="0.00001" />
    </inertial>
    <visual>
      <geometry>
        <mesh filename="package://igris_c_description_public/meshes/igris_c_v2/Wrist_Parallel_Back_Left.stl" scale="0.01 0.01 0.01"/>
      </geometry>
      <material name="random">
        <color rgba="0.0706 0.0706 0.0706 0.7" />
      </material>
    </visual>
    <collision>
      <geometry>
        <mesh filename="package://igris_c_description_public/meshes/igris_c_v2/Wrist_Parallel_Back_Left.stl" scale="0.01 0.01 0.01"/>
      </geometry>
    </collision>
  </link>

  <!-- RIGHT ARM -->
  <link name="Link_Shoulder_Pitch_Right">
    <inertial>
      <mass value="1.105" />
      <origin xyz="0.00039 0.00330 -0.00004" />
      <inertia ixx="0.00118" ixy="-0.00001" ixz="0.00000" iyy="0.00097" iyz="0.00000" izz="0.00107" />
    </inertial>
    <visual>
      <geometry>
        <mesh filename="package://igris_c_description_public/meshes/igris_c_v2/Shoulder_Pitch_Right.stl" scale="0.01 0.01 0.01"/>
      </geometry>
      <material name="random">
        <color rgba="0.0706 0.0706 0.0706 0.7" />
      </material>
    </visual>
    <collision>
      <geometry>
        <mesh filename="package://igris_c_description_public/meshes/igris_c_v2/Shoulder_Pitch_Right.stl" scale="0.01 0.01 0.01"/>
      </geometry>
    </collision>
  </link>

  <link name="Link_Shoulder_Roll_Right">
    <inertial>
      <mass value="0.253" />
      <origin xyz="0.02322 0.00000 -0.03100" />
      <inertia ixx="0.00046" ixy="0.00000" ixz="-0.00013" iyy="0.00046" iyz="0.00000" izz="0.00034" />
    </inertial>
    <visual>
      <geometry>
        <mesh filename="package://igris_c_description_public/meshes/igris_c_v2/Shoulder_Roll_Right.stl" scale="0.01 0.01 0.01"/>
      </geometry>
      <material name="random">
        <color rgba="0.0706 0.0706 0.0706 0.7" />
      </material>
    </visual>
    <collision>
      <geometry>
        <mesh filename="package://igris_c_description_public/meshes/igris_c_v2/Shoulder_Roll_Right.stl" scale="0.01 0.01 0.01"/>
      </geometry>
    </collision>
  </link>

  <link name="Link_Shoulder_Yaw_Right">
    <inertial>
      <mass value="2.144" />
      <origin xyz="0.00289 -0.00018 -0.14632" />
      <inertia ixx="0.00708" ixy="0.00001" ixz="0.00045" iyy="0.00723" iyz="-0.00002" izz="0.00213" />
    </inertial>
    <visual>
      <geometry>
        <mesh filename="package://igris_c_description_public/meshes/igris_c_v2/Shoulder_Yaw_Right.stl" scale="0.01 0.01 0.01"/>
      </geometry>
      <material name="random">
        <color rgba="0.0706 0.0706 0.0706 0.7" />
      </material>
    </visual>
    <collision>
      <geometry>
        <mesh filename="package://igris_c_description_public/meshes/igris_c_v2/Shoulder_Yaw_Right.stl" scale="0.01 0.01 0.01"/>
      </geometry>
    </collision>
  </link>

  <link name="Link_Elbow_Pitch_Right">
    <inertial>
      <mass value="0.137" />
      <origin xyz="-0.00506 -0.02516 -0.02257" />
      <inertia ixx="0.00017" ixy="0.00001" ixz="-0.00002" iyy="0.00017" iyz="0.00005" izz="0.00013" />
    </inertial>
    <visual>
      <geometry>
        <mesh filename="package://igris_c_description_public/meshes/igris_c_v2/Elbow_Pitch_Right.stl" scale="0.01 0.01 0.01"/>
      </geometry>
      <material name="random">
        <color rgba="0.0706 0.0706 0.0706 0.7" />
      </material>
    </visual>
    <collision>
      <geometry>
        <mesh filename="package://igris_c_description_public/meshes/igris_c_v2/Elbow_Pitch_Right.stl" scale="0.01 0.01 0.01"/>
      </geometry>
    </collision>
  </link>

  <link name="Link_Wrist_Yaw_Right">
    <inertial>
      <mass value="2.428" />
      <origin xyz="0.00011 0.00044 -0.08726" />
      <inertia ixx="0.00890" ixy="0.00000" ixz="0.00003" iyy="0.00984" iyz="0.00001" izz="0.00313" />
    </inertial>
    <visual>
      <geometry>
        <mesh filename="package://igris_c_description_public/meshes/igris_c_v2/Wrist_Yaw_Right.stl" scale="0.01 0.01 0.01"/>
      </geometry>
      <material name="random">
        <color rgba="0.0706 0.0706 0.0706 0.7" />
      </material>
    </visual>
    <collision>
      <geometry>
        <mesh filename="package://igris_c_description_public/meshes/igris_c_v2/Wrist_Yaw_Right.stl" scale="0.01 0.01 0.01"/>
      </geometry>
    </collision>
  </link>

  <link name="Link_Wrist_Flange_Front_Right">
    <inertial>
      <mass value="0.009" />
      <origin xyz="-0.00357 -0.01879 0.00461" />
      <inertia ixx="0.00001" ixy="0.00000" ixz="0.00000" iyy="0.00001" iyz="0.00000" izz="0.00001" />
    </inertial>
    <visual>
      <geometry>
        <mesh filename="package://igris_c_description_public/meshes/igris_c_v2/Wrist_Flange_Front_Right.stl" scale="0.01 0.01 0.01"/>
      </geometry>
      <material name="random">
        <color rgba="0.0706 0.0706 0.0706 0.7" />
      </material>
    </visual>
    <collision>
      <geometry>
        <mesh filename="package://igris_c_description_public/meshes/igris_c_v2/Wrist_Flange_Front_Right.stl" scale="0.01 0.01 0.01"/>
      </geometry>
    </collision>
  </link>

  <link name="Link_Wrist_Flange_Back_Right">
    <inertial>
      <mass value="0.009" />
      <origin xyz="0.00357 -0.01879 0.00461" />
      <inertia ixx="0.00001" ixy="0.00000" ixz="0.00000" iyy="0.00001" iyz="0.00000" izz="0.00001" />
    </inertial>
    <visual>
      <geometry>
        <mesh filename="package://igris_c_description_public/meshes/igris_c_v2/Wrist_Flange_Back_Right.stl" scale="0.01 0.01 0.01"/>
      </geometry>
      <material name="random">
        <color rgba="0.0706 0.0706 0.0706 0.7" />
      </material>
    </visual>
    <collision>
      <geometry>
        <mesh filename="package://igris_c_description_public/meshes/igris_c_v2/Wrist_Flange_Back_Right.stl" scale="0.01 0.01 0.01"/>
      </geometry>
    </collision>
  </link>

  <link name="Link_Wrist_Roll_Right">
    <inertial>
      <mass value="0.012" />
      <origin xyz="0.00000 -0.00604 0.00031" />
      <inertia ixx="0.00001" ixy="0.00000" ixz="0.00000" iyy="0.00001" iyz="0.00000" izz="0.00001" />
    </inertial>
    <visual>
      <geometry>
        <mesh filename="package://igris_c_description_public/meshes/igris_c_v2/Wrist_Roll_Right.stl" scale="0.01 0.01 0.01"/>
      </geometry>
      <material name="random">
        <color rgba="0.0706 0.0706 0.0706 0.7" />
      </material>
    </visual>
    <collision>
      <geometry>
        <mesh filename="package://igris_c_description_public/meshes/igris_c_v2/Wrist_Roll_Right.stl" scale="0.01 0.01 0.01"/>
      </geometry>
    </collision>
  </link>

  <link name="Link_Wrist_Pitch_Right">
    <inertial>
      <mass value="0.020" />
      <origin xyz="0.00000 -0.01019 -0.01687" />
      <inertia ixx="0.00001" ixy="0.00000" ixz="0.00000" iyy="0.00001" iyz="0.00000" izz="0.00001" />
    </inertial>
    <visual>
      <geometry>
        <mesh filename="package://igris_c_description_public/meshes/igris_c_v2/Wrist_Pitch_Right.stl" scale="0.01 0.01 0.01"/>
      </geometry>
      <material name="random">
        <color rgba="0.0706 0.0706 0.0706 0.7" />
      </material>
    </visual>
    <collision>
      <geometry>
        <mesh filename="package://igris_c_description_public/meshes/igris_c_v2/Wrist_Pitch_Right.stl" scale="0.01 0.01 0.01"/>
      </geometry>
    </collision>
  </link>

  <link name="Link_Wrist_Universal_Front_Right">
    <inertial>
      <mass value="0.002" />
      <origin xyz="0.00000 0.00189 -0.00004" />
      <inertia ixx="0.00001" ixy="0.00000" ixz="0.00000" iyy="0.00001" iyz="0.00000" izz="0.00001" />
    </inertial>
    <visual>
      <geometry>
        <mesh filename="package://igris_c_description_public/meshes/igris_c_v2/Wrist_Universal_Front_Right.stl" scale="0.01 0.01 0.01"/>
      </geometry>
      <material name="random">
        <color rgba="0.0706 0.0706 0.0706 0.7" />
      </material>
    </visual>
    <collision>
      <geometry>
        <mesh filename="package://igris_c_description_public/meshes/igris_c_v2/Wrist_Universal_Front_Right.stl" scale="0.01 0.01 0.01"/>
      </geometry>
    </collision>
  </link>

  <link name="Link_Wrist_Parallel_Front_Right">
    <inertial>
      <mass value="0.017" />
      <origin xyz="-0.00094 0.00038 -0.01026" />
      <inertia ixx="0.00001" ixy="0.00000" ixz="0.00000" iyy="0.00001" iyz="0.00000" izz="0.00001" />
    </inertial>
    <visual>
      <geometry>
        <mesh filename="package://igris_c_description_public/meshes/igris_c_v2/Wrist_Parallel_Front_Right.stl" scale="0.01 0.01 0.01"/>
      </geometry>
      <material name="random">
        <color rgba="0.0706 0.0706 0.0706 0.7" />
      </material>
    </visual>
    <collision>
      <geometry>
        <mesh filename="package://igris_c_description_public/meshes/igris_c_v2/Wrist_Parallel_Front_Right.stl" scale="0.01 0.01 0.01"/>
      </geometry>
    </collision>
  </link>

  <link name="Link_Wrist_Universal_Back_Right">
    <inertial>
      <mass value="0.002" />
      <origin xyz="0.00000 0.00189 -0.00004" />
      <inertia ixx="0.00001" ixy="0.00000" ixz="0.00000" iyy="0.00001" iyz="0.00000" izz="0.00001" />
    </inertial>
    <visual>
      <geometry>
        <mesh filename="package://igris_c_description_public/meshes/igris_c_v2/Wrist_Universal_Back_Right.stl" scale="0.01 0.01 0.01"/>
      </geometry>
      <material name="random">
        <color rgba="0.0706 0.0706 0.0706 0.7" />
      </material>
    </visual>
    <collision>
      <geometry>
        <mesh filename="package://igris_c_description_public/meshes/igris_c_v2/Wrist_Universal_Back_Right.stl" scale="0.01 0.01 0.01"/>
      </geometry>
    </collision>
  </link>

  <link name="Link_Wrist_Parallel_Back_Right">
    <inertial>
      <mass value="0.017" />
      <origin xyz="0.00094 0.00038 -0.01026" />
      <inertia ixx="0.00001" ixy="0.00000" ixz="0.00000" iyy="0.00001" iyz="0.00000" izz="0.00001" />
    </inertial>
    <visual>
      <geometry>
        <mesh filename="package://igris_c_description_public/meshes/igris_c_v2/Wrist_Parallel_Back_Right.stl" scale="0.01 0.01 0.01"/>
      </geometry>
      <material name="random">
        <color rgba="0.0706 0.0706 0.0706 0.7" />
      </material>
    </visual>
    <collision>
      <geometry>
        <mesh filename="package://igris_c_description_public/meshes/igris_c_v2/Wrist_Parallel_Back_Right.stl" scale="0.01 0.01 0.01"/>
      </geometry>
    </collision>
  </link>

  <link name="Right_Hand">
    <inertial>
      <mass value="0.333" />
      <origin xyz="0.00910 -0.00371 0.07839" />
      <inertia ixx="0.00081" ixy="0.00004" ixz="0.00012" iyy="0.00117" iyz="-0.00005" izz="0.00042" />
    </inertial>
    <visual>
      <geometry>
        <mesh filename="package://igris_c_description_public/meshes/igris_c_v2/Hand_Right.stl" scale="0.01 0.01 0.01"/>
      </geometry>
      <material name="random">
        <color rgba="0.0706 0.0706 0.0706 0.7" />
      </material>
    </visual>
   <collision>
      <geometry>
        <mesh filename="package://igris_c_description_public/meshes/igris_c_v2/Hand_Right.stl" scale="0.01 0.01 0.01"/>
      </geometry>
   </collision>
  </link>

  <!-- NECK -->
  <link name="Link_Neck_Yaw">
    <inertial>
      <mass value="0.310" />
      <origin xyz="-0.00005 -0.00130 -0.00264" />
      <inertia ixx="0.00017" ixy="0.00000" ixz="0.00000" iyy="0.00010" iyz="0.00001" izz="0.00016" />
    </inertial>
    <visual>
      <geometry>
        <mesh filename="package://igris_c_description_public/meshes/igris_c_v2/Neck_Yaw.stl" scale="0.01 0.01 0.01"/>
      </geometry>
      <material name="random">
        <color rgba="0.0706 0.0706 0.0706 0.7" />
      </material>
    </visual>
    <collision>
      <geometry>
        <mesh filename="package://igris_c_description_public/meshes/igris_c_v2/Neck_Yaw.stl" scale="0.01 0.01 0.01"/>
      </geometry>
    </collision>
  </link>

  <link name="Link_Neck_Pitch">
    <inertial>
      <mass value="1.468" />
      <origin xyz="0.02850 0.00290 0.12862" />
      <inertia ixx="0.00574" ixy="-0.00008" ixz="0.00025" iyy="0.00727" iyz="0.00013" izz="0.00503" />
    </inertial>
    <visual>
      <geometry>
        <mesh filename="package://igris_c_description_public/meshes/igris_c_v2/Neck_Pitch.stl" scale="0.01 0.01 0.01"/>
      </geometry>
      <material name="random">
        <color rgba="0.0706 0.0706 0.0706 0.7" />
      </material>
    </visual>
    <collision>
      <geometry>
        <mesh filename="package://igris_c_description_public/meshes/igris_c_v2/Neck_Pitch.stl" scale="0.01 0.01 0.01"/>
      </geometry>
    </collision>
  </link>
  

  <link name="Link_dummy1x">
  </link>

  <link name="Link_dummy1y">
  </link>

  <link name="Link_dummy2x">
  </link>

  <link name="Link_dummy2y">
  </link>

  <link name="Link_dummy3x">
  </link>

  <link name="Link_dummy3y">
  </link>

  <link name="Link_dummy4x">
  </link>

  <link name="Link_dummy4y">
  </link>

  <link name="Link_dummy5x">
  </link>

  <link name="Link_dummy5y">
  </link>

  <link name="Link_dummy6x">
  </link>

  <link name="Link_dummy6y">
  </link>

  <!-- JOINT -->
  <joint name="Joint_Waist_Yaw" type="revolute">
    <parent link="base_link" />
    <child link="Link_Waist_Yaw" />
    <origin xyz="0 0 0" rpy="0 0 0" />
    <axis xyz="0 0 1"  />
    <limit lower="-1.570796327" upper="1.570796327" effort="1000" velocity="100.0" />
  </joint>

  <joint name="Joint_Waist_Roll" type="revolute">
    <parent link="Link_Waist_Yaw" />
    <child link="Link_Waist_Roll" />
    <origin xyz="0.05 0 -0.026" rpy="0 0 0" />
    <axis xyz="1 0 0" />
    <limit lower="-0.453785606" upper="0.453785606" effort="1000" velocity="100.0" />
  </joint>

  <joint name="Joint_Waist_Pitch" type="revolute">
    <parent link="Link_Waist_Roll" />
    <child link="Link_Waist_Pitch" />
    <origin xyz="0 0 -0.04" rpy="0 0 0" />
    <axis xyz="0 1 0" />
    <limit lower="-0.436332313" upper="0.436332313" effort="1000" velocity="100.0" />
  </joint>

  <joint name="Joint_Waist_Flange_Left" type="revolute">
    <parent link="Link_Waist_Pitch" />
    <child link="Link_Waist_Flange_Left" />
    <origin xyz="0 0.0905 0" rpy="0 0 0" />
    <axis xyz="0 1 0" />
    <limit lower="-1.570796327" upper="1.570796327" effort="1000" velocity="100.0" />
  </joint>

  <joint name="Joint_Waist_Parallel_Left_x" type="revolute">
    <parent link="Link_Waist_Flange_Left" />
    <child link="Link_dummy1x" />
    <origin xyz="-0.05167 0.00000 -0.00587" rpy="0 0 0" />
    <axis xyz="1 0 0" />
    <limit lower="-1.570796327" upper="1.570796327" effort="1000" velocity="100.0" />
  </joint>

  <joint name="Joint_Waist_Parallel_Left_y" type="revolute">
    <parent link="Link_dummy1x" />
    <child link="Link_dummy1y" />
    <origin xyz="0 0 0" rpy="0 0 0" />
    <axis xyz="0 1 0" />
    <limit lower="-1.570796327" upper="1.570796327" effort="1000" velocity="100.0" />
  </joint>

  <joint name="Joint_Waist_Parallel_Left_z" type="revolute">
    <parent link="Link_dummy1y" />
    <child link="Link_Waist_Parallel_Left" />
    <origin xyz="0 0 0" rpy="0 0 0" />
    <axis xyz="0 0 1" />
    <limit lower="-1.570796327" upper="1.570796327" effort="1000" velocity="100.0" />
  </joint>

  <joint name="Joint_Waist_Flange_Right" type="revolute">
    <parent link="Link_Waist_Pitch" />
    <child link="Link_Waist_Flange_Right" />
    <origin xyz="0 -0.0905 0" rpy="0 0 0" />
    <axis xyz="0 1 0" />
    <limit lower="-1.570796327" upper="1.570796327" effort="1000" velocity="100.0" />
  </joint>

  <joint name="Joint_Waist_Parallel_Right_x" type="revolute">
    <parent link="Link_Waist_Flange_Right" />
    <child link="Link_dummy2x" />
    <origin xyz="-0.05167 0.00000 -0.00587" rpy="0 0 0" />
    <axis xyz="1 0 0" />
    <limit lower="-1.570796327" upper="1.570796327" effort="1000" velocity="100.0" />
  </joint>


  <joint name="Joint_Waist_Parallel_Right_y" type="revolute">
    <parent link="Link_dummy2x" />
    <child link="Link_dummy2y" />
    <origin xyz="0 0 0" rpy="0 0 0" />
    <axis xyz="0 1 0" />
    <limit lower="-1.570796327" upper="1.570796327" effort="1000" velocity="100.0" />
  </joint>

  <joint name="Joint_Waist_Parallel_Right_z" type="revolute">
    <parent link="Link_dummy2y" />
    <child link="Link_Waist_Parallel_Right" />
    <origin xyz="0 0 0 " rpy="0 0 0" />
    <axis xyz="0 0 1" />
    <limit lower="-1.570796327" upper="1.570796327" effort="1000" velocity="100.0" />
  </joint>

  <joint name="Joint_Hip_Pitch_Left" type="revolute">
    <parent link="Link_Waist_Pitch" />
    <child link="Link_Hip_Pitch_Left" />
    <origin xyz="-0.0115 0.0897 -0.14" rpy="0 0 0" />
    <axis xyz="0 1 0" />
    <limit lower="-2.042035225" upper="0.523598776" effort="1000" velocity="100.0" />
  </joint>

  <joint name="Joint_Hip_Roll_Left" type="revolute">
    <parent link="Link_Hip_Pitch_Left" />
    <child link="Link_Hip_Roll_Left" />
    <origin xyz="0 0 0" rpy="0 0 0" />
    <axis xyz="1 0 0" />
    <limit lower="-0.331612558" upper="2.35619449" effort="1000" velocity="100.0" />
  </joint>

<!-- 213 -->
  <joint name="Joint_Hip_Yaw_Left" type="revolute">
    <parent link="Link_Hip_Roll_Left" />
    <child link="Link_Hip_Yaw_Left" />
    <origin xyz="0.002 0 -0.076" rpy="0 0 0" />
    <axis xyz="0 0 1" />
    <limit lower="-1.570796327" upper="1.570796327" effort="1000" velocity="100.0" />
  </joint>

<!-- 214 -->
  <joint name="Joint_Knee_Pitch_Left" type="revolute">
    <parent link="Link_Hip_Yaw_Left" />
    <child link="Link_Knee_Pitch_Left" />
    <origin xyz="-0.055 0 -0.263" rpy="0 0 0" />
    <axis xyz="0 1 0" />
    <limit lower="0" upper="2.28638132" effort="1000" velocity="100.0" />
  </joint>

<!-- 215 -->
  <joint name="Joint_Ankle_Pitch_Left" type="revolute">
    <parent link="Link_Knee_Pitch_Left" />
    <child link="Link_Ankle_Pitch_Left" />
    <origin xyz="0.005 0 -0.34" rpy="0 0 0" />
    <axis xyz="0 1 0" />
    <limit lower="-0.698131701" upper="0.698131701" effort="1000" velocity="100.0" />
  </joint>

<!-- 216 -->
  <joint name="Joint_Ankle_Roll_Left" type="revolute">
    <parent link="Link_Ankle_Pitch_Left" />
    <child link="Link_Ankle_Roll_Left" />
    <origin xyz="0 0 0" rpy="0 0 0" />
    <axis xyz="1 0 0" />
    <limit lower="-0.261799388" upper="0.261799388" effort="1000" velocity="100.0" />
  </joint>

<!-- 217 -->
  <joint name="Joint_Ankle_Flange_In_Left" type="revolute">
    <parent link="Link_Knee_Pitch_Left" />
    <child link="Link_Ankle_Flange_In_Left" />
    <origin xyz="0.00500 -0.03775 -0.18800" rpy="0 0 0" />
    <axis xyz="0 1 0" />
    <limit lower="-1.570796327" upper="1.570796327" effort="1000" velocity="100.0" />
  </joint>

<!-- 218x -->
  <joint name="Joint_Ankle_Parallel_In_Left_x" type="revolute">
    <parent link="Link_Ankle_Flange_In_Left" />
    <child link="Link_dummy3x" />
    <origin xyz="-0.03750 0.00000 -0.00019" rpy="0 0 0" />
    <axis xyz="1 0 0" />
    <limit lower="-1.570796327" upper="1.570796327" effort="1000" velocity="100.0" />
  </joint>

<!-- 218y -->
  <joint name="Joint_Ankle_Parallel_In_Left_y" type="revolute">
    <parent link="Link_dummy3x" />
    <child link="Link_dummy3y" />
    <origin xyz="0 0 0" rpy="0 0 0" />
    <axis xyz="0 1 0" />
    <limit lower="-1.570796327" upper="1.570796327" effort="1000" velocity="100.0" />
  </joint>

<!-- 218z -->
  <joint name="Joint_Ankle_Parallel_In_Left_z" type="revolute">
    <parent link="Link_dummy3y" />
    <child link="Link_Ankle_Parallel_In_Left" />
    <origin xyz="0 0 0" rpy="0 0 0" />
    <axis xyz="0 0 1" />
    <limit lower="-1.570796327" upper="1.570796327" effort="1000" velocity="100.0" />
  </joint>

<!-- 219 -->
  <joint name="Joint_Ankle_Flange_Out_Left" type="revolute">
    <parent link="Link_Knee_Pitch_Left" />
    <child link="Link_Ankle_Flange_Out_Left" />
    <origin xyz="0.00500 0.03775 -0.08000" rpy="0 0 0" />
    <axis xyz="0 1 0" />
    <limit lower="-1.570796327" upper="1.570796327" effort="1000" velocity="100.0" />
  </joint>

<!-- 2110x -->
  <joint name="Joint_Ankle_Parallel_Out_Left_x" type="revolute">
    <parent link="Link_Ankle_Flange_Out_Left" />
    <child link="Link_dummy4x" />
    <origin xyz="-0.03750 0.00000 -0.00001" rpy="0 0 0" />
    <axis xyz="1 0 0" />
    <limit lower="-1.570796327" upper="1.570796327" effort="1000" velocity="100.0" />
  </joint>

<!-- 2110y -->
  <joint name="Joint_Ankle_Parallel_Out_Left_y" type="revolute">
    <parent link="Link_dummy4x" />
    <child link="Link_dummy4y" />
    <origin xyz="0 0 0" rpy="0 0 0" />
    <axis xyz="0 1 0" />
    <limit lower="-1.570796327" upper="1.570796327" effort="1000" velocity="100.0" />
  </joint>

<!-- 2110z -->
  <joint name="Joint_Ankle_Parallel_Out_Left_z" type="revolute">
    <parent link="Link_dummy4y" />
    <child link="Link_Ankle_Parallel_Out_Left" />
    <origin xyz="0 0 0" rpy="0 0 0" />
    <axis xyz="0 0 1" />
    <limit lower="-1.570796327" upper="1.570796327" effort="1000" velocity="100.0" />
  </joint>

<!-- 221 -->
  <joint name="Joint_Hip_Pitch_Right" type="revolute">
    <parent link="Link_Waist_Pitch" />
    <child link="Link_Hip_Pitch_Right" />
    <origin xyz="-0.0115 -0.0897 -0.14" rpy="0 0 0" />
    <axis xyz="0 1 0" />
    <limit lower="-2.059488517" upper="0.523598776" effort="1000" velocity="100.0" />
  </joint>

<!-- 222 -->
  <joint name="Joint_Hip_Roll_Right" type="revolute">
    <parent link="Link_Hip_Pitch_Right" />
    <child link="Link_Hip_Roll_Right" />
    <origin xyz="0 0 0" rpy="0 0 0" />
    <axis xyz="1 0 0" />
    <limit lower="-2.35619449" upper="0.331612558" effort="1000" velocity="100.0" />
  </joint>

<!-- 223 -->
  <joint name="Joint_Hip_Yaw_Right" type="revolute">
    <parent link="Link_Hip_Roll_Right" />
    <child link="Link_Hip_Yaw_Right" />
    <origin xyz="0.002 0 -0.076" rpy="0 0 0" />
    <axis xyz="0 0 1" />
    <limit lower="-1.570796327" upper="1.570796327" effort="1000" velocity="100.0" />
  </joint>

<!-- 224 -->
  <joint name="Joint_Knee_Pitch_Right" type="revolute">
    <parent link="Link_Hip_Yaw_Right" />
    <child link="Link_Knee_Pitch_Right" />
    <origin xyz="-0.055 0 -0.263" rpy="0 0 0" />
    <axis xyz="0 1 0" />
    <limit lower="0" upper="2.28638132" effort="1000" velocity="100.0" />
  </joint>

<!-- 225 -->
  <joint name="Joint_Ankle_Pitch_Right" type="revolute">
    <parent link="Link_Knee_Pitch_Right" />
    <child link="Link_Ankle_Pitch_Right" />
    <origin xyz="0.005 0 -0.34" rpy="0 0 0" />
    <axis xyz="0 1 0" />
    <limit lower="-0.698131701" upper="0.698131701" effort="1000" velocity="100.0" />
  </joint>

<!-- 226 -->
  <joint name="Joint_Ankle_Roll_Right" type="revolute">
    <parent link="Link_Ankle_Pitch_Right" />
    <child link="Link_Ankle_Roll_Right" />
    <origin xyz="0 0 0" rpy="0 0 0" />
    <axis xyz="1 0 0" />
    <limit lower="-0.261799388" upper="0.261799388" effort="1000" velocity="100.0" />
  </joint>

<!-- 227 -->
  <joint name="Joint_Ankle_Flange_In_Right" type="revolute">
    <parent link="Link_Knee_Pitch_Right" />
    <child link="Link_Ankle_Flange_In_Right" />
    <origin xyz="0.00500 0.03775 -0.18800" rpy="0 0 0" />
    <axis xyz="0 1 0" />
    <limit lower="-1.570796327" upper="1.570796327" effort="1000" velocity="100.0" />
  </joint>

<!-- 228x -->
  <joint name="Joint_Ankle_Parallel_In_Right_x" type="revolute">
    <parent link="Link_Ankle_Flange_In_Right" />
    <child link="Link_dummy5x" />
    <origin xyz="-0.03750 0.00000 -0.00019" rpy="0 0 0" />
    <axis xyz="1 0 0" />
    <limit lower="-1.570796327" upper="1.570796327" effort="1000" velocity="100.0" />
  </joint>

<!-- 228y -->
  <joint name="Joint_Ankle_Parallel_In_Right_y" type="revolute">
    <parent link="Link_dummy5x" />
    <child link="Link_dummy5y" />
    <origin xyz="0 0 0" rpy="0 0 0" />
    <axis xyz="0 1 0" />
    <limit lower="-1.570796327" upper="1.570796327" effort="1000" velocity="100.0" />
  </joint>

<!-- 228z -->
  <joint name="Joint_Ankle_Parallel_In_Right_z" type="revolute">
    <parent link="Link_dummy5y" />
    <child link="Link_Ankle_Parallel_In_Right" />
    <origin xyz="0 0 0" rpy="0 0 0" />
    <axis xyz="0 0 1" />
    <limit lower="-1.570796327" upper="1.570796327" effort="1000" velocity="100.0" />
  </joint>

<!-- 229 -->
  <joint name="Joint_Ankle_Flange_Out_Right" type="revolute">
    <parent link="Link_Knee_Pitch_Right" />
    <child link="Link_Ankle_Flange_Out_Right" />
    <origin xyz="0.00500 -0.03775 -0.08000" rpy="0 0 0" />
    <axis xyz="0 1 0" />
    <limit lower="-1.570796327" upper="1.570796327" effort="1000" velocity="100.0" />
  </joint>

<!-- 2210x -->
  <joint name="Joint_Ankle_Parallel_Out_Right_x" type="revolute">
    <parent link="Link_Ankle_Flange_Out_Right" />
    <child link="Link_dummy6x" />
    <origin xyz="-0.03750 0.00000 -0.00011" rpy="0 0 0" />
    <axis xyz="1 0 0" />
    <limit lower="-1.570796327" upper="1.570796327" effort="1000" velocity="100.0" />
  </joint>

<!-- 2210y -->
  <joint name="Joint_Ankle_Parallel_Out_Right_y" type="revolute">
    <parent link="Link_dummy6x" />
    <child link="Link_dummy6y" />
    <origin xyz="0 0 0" rpy="0 0 0" />
    <axis xyz="0 1 0" />
    <limit lower="-1.570796327" upper="1.570796327" effort="1000" velocity="100.0" />
  </joint>

<!-- 2210z -->
  <joint name="Joint_Ankle_Parallel_Out_Right_z" type="revolute">
    <parent link="Link_dummy6y" />
    <child link="Link_Ankle_Parallel_Out_Right" />
    <origin xyz="0 0 0" rpy="0 0 0" />
    <axis xyz="0 0 1" />
    <limit lower="-1.570796327" upper="1.570796327" effort="1000" velocity="100.0" />
  </joint>

<!-- 311 -->
  <joint name="Joint_Shoulder_Pitch_Left" type="revolute">
    <parent link="base_link" />
    <child link="Link_Shoulder_Pitch_Left" />
    <origin xyz="0 0.171 0.266" rpy="0 0 0" />
    <axis xyz="0 1 0" />
    <limit lower="-3.141592654" upper="1.047197551" effort="1000" velocity="100.0" />
  </joint>

<!-- 312 -->
  <joint name="Joint_Shoulder_Roll_Left" type="revolute">
    <parent link="Link_Shoulder_Pitch_Left" />
    <child link="Link_Shoulder_Roll_Left" />
    <origin xyz="0 0 0" rpy="0 0 0" />
    <axis xyz="1 0 0" />
    <limit lower="-0.174532925" upper="3.141592654" effort="1000" velocity="100.0" />
  </joint>

<!-- 313 -->
  <joint name="Joint_Shoulder_Yaw_Left" type="revolute">
    <parent link="Link_Shoulder_Roll_Left" />
    <child link="Link_Shoulder_Yaw_Left" />
    <origin xyz="0 0 0" rpy="0 0 0" />
    <axis xyz="0 0 1" />
    <limit lower="-1.570796327" upper="1.570796327" effort="1000" velocity="100.0" />
  </joint>

<!-- 314 -->
  <joint name="Joint_Elbow_Pitch_Left" type="revolute">
    <parent link="Link_Shoulder_Yaw_Left" />
    <child link="Link_Elbow_Pitch_Left" />
    <origin xyz="0.01 0 -0.197" rpy="0 0 0" />
    <axis xyz="0 1 0" />
    <limit lower="-2.094395102" upper="0" effort="1000" velocity="100.0" />
  </joint>

<!-- 315 -->
  <joint name="Joint_Wrist_Yaw_Left" type="revolute">
    <parent link="Link_Elbow_Pitch_Left" />
    <child link="Link_Wrist_Yaw_Left" />
    <origin xyz="-0.01 0 -0.05" rpy="0 0 0" />
    <axis xyz="0 0 1" />
    <limit lower="-1.570796327" upper="1.570796327" effort="1000" velocity="100.0" />
  </joint>

<!-- 316 -->
  <joint name="Joint_Wrist_Flange_Front_Left" type="revolute">
    <parent link="Link_Wrist_Yaw_Left" />
    <child link="Link_Wrist_Flange_Front_Left" />
    <origin xyz="0.02000 -0.00934 -0.21488" rpy="0 0 0" />
    <axis xyz="1 0 0" />
    <limit lower="-1.570796327" upper="1.570796327" effort="1000" velocity="100.0" />
  </joint>

<!-- 317 -->
  <joint name="Joint_Wrist_Flange_Back_Left" type="revolute">
    <parent link="Link_Wrist_Yaw_Left" />
    <child link="Link_Wrist_Flange_Back_Left" />
    <origin xyz="-0.02000 -0.00934 -0.21488" rpy="0 0 0" />
    <axis xyz="1 0 0" />
    <limit lower="-1.570796327" upper="1.570796327" effort="1000" velocity="100.0" />
  </joint>

<!-- 318 -->
  <joint name="Joint_Wrist_Roll_Left" type="revolute">
    <parent link="Link_Wrist_Yaw_Left" />
    <child link="Link_Wrist_Roll_Left" />
    <origin xyz="0 -0.005 -0.2395 " rpy="0 0 0" />
    <axis xyz="1 0 0" />
    <limit lower="-0.872664626" upper="1.221730476" effort="1000" velocity="100.0" />
  </joint>

<!-- 319 -->
  <joint name="Joint_Wrist_Pitch_Left" type="revolute">
    <parent link="Link_Wrist_Roll_Left" />
    <child link="Link_Wrist_Pitch_Left" />
    <origin xyz="0 0 0" rpy="0 0 0" />
    <axis xyz="0 1 0" />
    <limit lower="-0.698131701" upper="0.698131701" effort="1000" velocity="100.0" />
  </joint>

<!-- 3110 -->
  <joint name="Joint_Wrist_Universal_Front_Left" type="revolute">
    <parent link="Link_Wrist_Pitch_Left" />
    <child link="Link_Wrist_Universal_Front_Left" />
    <origin xyz="0.01000 0.02150 -0.01000" rpy="0 0 0" />
    <axis xyz="0 1 0" />
    <limit lower="-1.570796327" upper="1.570796327" effort="1000" velocity="100.0" />
  </joint>

<!-- 3111 -->
  <joint name="Joint_Wrist_Parallel_Front_Left" type="revolute">
    <parent link="Link_Wrist_Universal_Front_Left" />
    <child link="Link_Wrist_Parallel_Front_Left" />
    <origin xyz="0 0 0" rpy="0 0 0" />
    <axis xyz="1 0 0" />
    <limit lower="-1.570796327" upper="1.570796327" effort="1000" velocity="100.0" />
  </joint>

<!-- 3112 -->
  <joint name="Joint_Wrist_Universal_Back_Left" type="revolute">
    <parent link="Link_Wrist_Pitch_Left" />
    <child link="Link_Wrist_Universal_Back_Left" />
    <origin xyz="-0.01000 0.02150 -0.01000" rpy="0 0 0" />
    <axis xyz="0 1 0" />
    <limit lower="-1.570796327" upper="1.570796327" effort="1000" velocity="100.0" />
  </joint>

<!-- 3113 -->
  <joint name="Joint_Wrist_Parallel_Back_Left" type="revolute">
    <parent link="Link_Wrist_Universal_Back_Left" />
    <child link="Link_Wrist_Parallel_Back_Left" />
    <origin xyz="0 0 0" rpy="0 0 0" />
    <axis xyz="1 0 0" />
    <limit lower="-1.570796327" upper="1.570796327" effort="1000" velocity="100.0" />
  </joint>

  <joint name="Left_Hand" type="fixed">
    <parent link="Link_Wrist_Pitch_Left" />
    <child link="Left_Hand" />
    <origin xyz="0 0.0109 -0.024" rpy="3.14 0 0" />
  </joint>

<!-- 321 -->
  <joint name="Joint_Shoulder_Pitch_Right" type="revolute">
    <parent link="base_link" />
    <child link="Link_Shoulder_Pitch_Right" />
    <origin xyz="0 -0.171 0.266" rpy="0 0 0" />
    <axis xyz="0 1 0" />
    <limit lower="-3.141592654" upper="1.047197551" effort="1000" velocity="100.0" />
  </joint>

<!-- 322 -->
  <joint name="Joint_Shoulder_Roll_Right" type="revolute">
    <parent link="Link_Shoulder_Pitch_Right" />
    <child link="Link_Shoulder_Roll_Right" />
    <origin xyz="0 0 0" rpy="0 0 0" />
    <axis xyz="1 0 0" />
    <limit lower="-3.141592654" upper="0.174532925" effort="1000" velocity="100.0" />
  </joint>

<!-- 323 -->
  <joint name="Joint_Shoulder_Yaw_Right" type="revolute">
    <parent link="Link_Shoulder_Roll_Right" />
    <child link="Link_Shoulder_Yaw_Right" />
    <origin xyz="0 0 0" rpy="0 0 0" />
    <axis xyz="0 0 1" />
    <limit lower="-1.570796327" upper="1.570796327" effort="1000" velocity="100.0" />
  </joint>

<!-- 324 -->
  <joint name="Joint_Elbow_Pitch_Right" type="revolute">
    <parent link="Link_Shoulder_Yaw_Right" />
    <child link="Link_Elbow_Pitch_Right" />
    <origin xyz="0.01 0 -0.197" rpy="0 0 0" />
    <axis xyz="0 1 0" />
    <limit lower="-2.094395102" upper="0" effort="1000" velocity="100.0" />
  </joint>

<!-- 325 -->
  <joint name="Joint_Wrist_Yaw_Right" type="revolute">
    <parent link="Link_Elbow_Pitch_Right" />
    <child link="Link_Wrist_Yaw_Right" />
    <origin xyz="-0.01 0 -0.05" rpy="0 0 0" />
    <axis xyz="0 0 1" />
    <limit lower="-1.570796327" upper="1.570796327" effort="1000" velocity="100.0" />
  </joint>

<!-- 326 -->
  <joint name="Joint_Wrist_Flange_Front_Right" type="revolute">
    <parent link="Link_Wrist_Yaw_Right" />
    <child link="Link_Wrist_Flange_Front_Right" />
    <origin xyz="0.02000 0.00934 -0.21488" rpy="0 0 0" />
    <axis xyz="1 0 0" />
    <limit lower="-1.570796327" upper="1.570796327" effort="1000" velocity="100.0" />
  </joint>

<!-- 327 -->
  <joint name="Joint_Wrist_Flange_Back_Right" type="revolute">
    <parent link="Link_Wrist_Yaw_Right" />
    <child link="Link_Wrist_Flange_Back_Right" />
    <origin xyz="-0.02000 0.00934 -0.21488" rpy="0 0 0" />
    <axis xyz="1 0 0" />
    <limit lower="-1.570796327" upper="1.570796327" effort="1000" velocity="100.0" />
  </joint>

<!-- 328 -->
  <joint name="Joint_Wrist_Roll_Right" type="revolute">
    <parent link="Link_Wrist_Yaw_Right" />
    <child link="Link_Wrist_Roll_Right" />
    <origin xyz="0 0.005 -0.2395" rpy="0 0 0" />
    <axis xyz="1 0 0"/>
    <limit lower="-1.221730476" upper="0.872664626" effort="1000" velocity="100.0" />
  </joint>

<!-- 329 -->
  <joint name="Joint_Wrist_Pitch_Right" type="revolute">
    <parent link="Link_Wrist_Roll_Right" />
    <child link="Link_Wrist_Pitch_Right" />
    <origin xyz="0 0 0" rpy="0 0 0" />
    <axis xyz="0 1 0" />
    <limit lower="-0.698131701" upper="0.698131701" effort="1000" velocity="100.0" />
  </joint>

<!-- 3210 -->
  <joint name="Joint_Wrist_Universal_Front_Right" type="revolute">
    <parent link="Link_Wrist_Pitch_Right" />
    <child link="Link_Wrist_Universal_Front_Right" />
    <origin xyz="0.01000 -0.02150 -0.01000" rpy="0 0 0" />
    <axis xyz="0 1 0" />
    <limit lower="-1.570796327" upper="1.570796327" effort="1000" velocity="100.0" />
  </joint>

<!-- 3211 -->
  <joint name="Joint_Wrist_Parallel_Front_Right" type="revolute">
    <parent link="Link_Wrist_Universal_Front_Right" />
    <child link="Link_Wrist_Parallel_Front_Right" />
    <origin xyz="0 0 0" rpy="0 0 0" />
    <axis xyz="1 0 0" />
    <limit lower="-1.570796327" upper="1.570796327" effort="1000" velocity="100.0" />
  </joint>

<!-- 3212 -->
  <joint name="Joint_Wrist_Universal_Back_Right" type="revolute">
    <parent link="Link_Wrist_Pitch_Right" />
    <child link="Link_Wrist_Universal_Back_Right" />
    <origin xyz="-0.01000 -0.02150 -0.01000" rpy="0 0 0" />
    <axis xyz="0 1 0" />
    <limit lower="-1.570796327" upper="1.570796327" effort="1000" velocity="100.0" />
  </joint>

<!-- 3213 -->
  <joint name="Joint_Wrist_Parallel_Back_Right" type="revolute">
    <parent link="Link_Wrist_Universal_Back_Right" />
    <child link="Link_Wrist_Parallel_Back_Right" />
    <origin xyz="0 0 0" rpy="0 0 0" />
    <axis xyz="1 0 0" />
    <limit lower="-1.570796327" upper="1.570796327" effort="1000" velocity="100.0" />
  </joint>

  <joint name="Right_Hand" type="fixed">
    <parent link="Link_Wrist_Pitch_Right" />
    <child link="Right_Hand" />
    <origin xyz="0 -0.0109 -0.024" rpy="3.14 0 0" />
  </joint>

  <joint name="Joint_Neck_Yaw" type="revolute">
    <parent link="base_link" />
    <child link="Link_Neck_Yaw" />
    <origin xyz="0 0 0.357" rpy="0 0 0" />
    <axis xyz="0 0 1" />
    <limit lower="-1.221730476" upper="1.221730476" effort="1000" velocity="100.0" />
  </joint>

  <joint name="Joint_Neck_Pitch" type="revolute">
    <parent link="Link_Neck_Yaw" />
    <child link="Link_Neck_Pitch" />
    <origin xyz="0 0 0" rpy="0 0 0" />
    <axis xyz="0 1 0" />
    <limit lower="-0.523598776" upper="0.523598776" effort="1000" velocity="100.0" />
  </joint>
</robot>