<?xml version='1.0' encoding='utf-8'?>
<mujoco model="igris_c_v2_pelvis_base_1dof_gripper">
  <compiler angle="radian" meshdir="../meshes/igris_c_v2/" balanceinertia="false" />
  <size njmax="8000" nconmax="4000" />
  <option timestep="0.000333333333" iterations="500" tolerance="1e-7" solver="Newton" jacobian="dense" cone="elliptic" noslip_iterations="100" noslip_tolerance="1e-7" />
  <default>
    <default class="robot">
      <default class="visual">
        <geom group="1" type="mesh" contype="0" conaffinity="0" density="0" rgba="1 1 1 1" />
      </default>
      <default class="collision">
        <geom material="collision_material" rgba="1.0 0.28 0.1 0.0" condim="3" contype="1" conaffinity="1" priority="1" group="2" solref="0.01 1" friction="1 0.005 0.0001" />
        <equality solimp="0.9 0.95 0.001 0.5 2" solref="0.01 1" />
      </default>
    </default>
    <motor ctrllimited="true" />
    <default class="actuator_150">
      <joint damping="0.0" frictionloss="2.4" limited="true" armature="0.0521" />
      <motor ctrlrange="-150.0 150.0" />
    </default>
    <default class="actuator_120">
      <joint damping="0.0" frictionloss="0.812" limited="true" armature="0.0786" />
      <motor ctrlrange="-120.0 120.0" />
    </default>
    <default class="actuator_90">
      <joint damping="0.0" frictionloss="1.81" limited="true" armature="0.0299" />
      <motor ctrlrange="-90.0 90.0" />
    </default>
    <default class="actuator_60">
      <joint damping="0.0" frictionloss="0.54" limited="true" armature="0.0307" />
      <motor ctrlrange="-60.0 60.0" />
    </default>
    <default class="actuator_8">
      <joint damping="0.0" frictionloss="0.264" limited="true" armature="0.01433" />
      <motor ctrlrange="-8.0 8.0" />
    </default>
    <default class="actuator_7">
      <joint damping="0.0" frictionloss="0.356" limited="true" armature="0.2488" />
      <motor ctrlrange="-7.0 7.0" />
    </default>
    <default class="passive">
      <joint damping="0.00" frictionloss="1e-4" limited="false" armature="1e-6" />
    </default>
  </default>
  <asset>
    <material name="random" rgba="0.0706 0.0706 0.0706 0.7" />
    <material name="default_material" rgba="0.7 0.7 0.7 1" />
    <material name="collision_material" rgba="1.0 0.28 0.1 0.9" />
    <mesh name="Upper_Body" file="Pelvis.stl" scale="0.01 0.01 0.01" />
    <mesh name="Waist_Yaw" file="Waist_Yaw.stl" scale="0.01 0.01 0.01" />
    <mesh name="Waist_Roll" file="Waist_Roll.stl" scale="0.01 0.01 0.01" />
    <mesh name="Waist_Pitch" file="Waist_Pitch.stl" scale="0.01 0.01 0.01" />
    <mesh name="Neck_Yaw" file="Neck_Yaw.stl" scale="0.01 0.01 0.01" />
    <mesh name="Neck_Pitch" file="Neck_Pitch.stl" scale="0.01 0.01 0.01" />
    <mesh name="Hip_Pitch_Left" file="Hip_Pitch_Left.stl" scale="0.01 0.01 0.01" />
    <mesh name="Hip_Roll_Left" file="Hip_Roll_Left.stl" scale="0.01 0.01 0.01" />
    <mesh name="Hip_Yaw_Left_collision" file="Hip_Yaw_CirCut.stl" scale="0.01 0.01 0.01" />
    <mesh name="Hip_Yaw_Left" file="Hip_Yaw_Left.stl" scale="0.01 0.01 0.01" />
    <mesh name="Knee_Pitch_Left" file="Knee_Pitch_Left.stl" scale="0.01 0.01 0.01" />
    <mesh name="Ankle_Pitch_Left" file="Ankle_Pitch_Left.stl" scale="0.01 0.01 0.01" />
    <mesh name="Ankle_Roll_Left_collision" file="Ankle_Roll_Shoe_v3_collision.stl" scale="0.01 0.01 0.01" />
    <mesh name="Ankle_Roll_Left" file="Ankle_Roll_Shoe_v3_visual.stl" scale="0.01 0.01 0.01" />
    <mesh name="Hip_Pitch_Right" file="Hip_Pitch_Right.stl" scale="0.01 0.01 0.01" />
    <mesh name="Hip_Roll_Right" file="Hip_Roll_Right.stl" scale="0.01 0.01 0.01" />
    <mesh name="Hip_Yaw_Right_collision" file="Hip_Yaw_CirCut.stl" scale="0.01 0.01 0.01" />
    <mesh name="Hip_Yaw_Right" file="Hip_Yaw_Right.stl" scale="0.01 0.01 0.01" />
    <mesh name="Knee_Pitch_Right" file="Knee_Pitch_Right.stl" scale="0.01 0.01 0.01" />
    <mesh name="Ankle_Pitch_Right" file="Ankle_Pitch_Right.stl" scale="0.01 0.01 0.01" />
    <mesh name="Ankle_Roll_Right_collision" file="Ankle_Roll_Shoe_v3_collision.stl" scale="0.01 0.01 0.01" />
    <mesh name="Ankle_Roll_Right" file="Ankle_Roll_Shoe_v3_visual.stl" scale="0.01 0.01 0.01" />
    <mesh name="Shoulder_Pitch_Left" file="Shoulder_Pitch_Left.stl" scale="0.01 0.01 0.01" />
    <mesh name="Shoulder_Roll_Left" file="Shoulder_Roll_Left.stl" scale="0.01 0.01 0.01" />
    <mesh name="Shoulder_Yaw_Left" file="Shoulder_Yaw_Left.stl" scale="0.01 0.01 0.01" />
    <mesh name="Elbow_Pitch_Left" file="Elbow_Pitch_Left.stl" scale="0.01 0.01 0.01" />
    <mesh name="Wrist_Yaw_Left" file="Wrist_Yaw_Left.stl" scale="0.01 0.01 0.01" />
    <mesh name="Wrist_Roll_Left" file="Wrist_Roll_Left.stl" scale="0.01 0.01 0.01" />
    <mesh name="Wrist_Pitch_Left" file="Wrist_Pitch_Left.stl" scale="0.01 0.01 0.01" />
    <mesh name="Left_Hand" file="../igris_c_end_effector/hand/Hand_Left.stl" scale="0.01 0.01 0.01" />
    <mesh name="Shoulder_Pitch_Right" file="Shoulder_Pitch_Right.stl" scale="0.01 0.01 0.01" />
    <mesh name="Shoulder_Roll_Right" file="Shoulder_Roll_Right.stl" scale="0.01 0.01 0.01" />
    <mesh name="Shoulder_Yaw_Right" file="Shoulder_Yaw_Right.stl" scale="0.01 0.01 0.01" />
    <mesh name="Elbow_Pitch_Right" file="Elbow_Pitch_Right.stl" scale="0.01 0.01 0.01" />
    <mesh name="Wrist_Yaw_Right" file="Wrist_Yaw_Right.stl" scale="0.01 0.01 0.01" />
    <mesh name="Wrist_Roll_Right" file="Wrist_Roll_Right.stl" scale="0.01 0.01 0.01" />
    <mesh name="Wrist_Pitch_Right" file="Wrist_Pitch_Right.stl" scale="0.01 0.01 0.01" />
    <mesh name="Right_Hand" file="../igris_c_end_effector/hand/Hand_Right.stl" scale="0.01 0.01 0.01" />
    <texture type="skybox" builtin="gradient" width="128" height="128" rgb1="1.0 1.0 1.0" rgb2="0.4 0.4 0.4" />
    <texture name="grid" type="2d" builtin="checker" width="512" height="512" rgb1="0.9 0.9 0.9" rgb2=".85 .85 .85" />
    <material name="grid" texture="grid" texrepeat="1 1" texuniform="true" reflectance=".2" />
    <mesh name="1_DoF_Fixed_Gripper_Left" file="../igris_c_end_effector/1_dof_gripper/1DG_Left_Fixed.stl" scale="0.01 0.01 0.01" />
    <mesh name="1_DoF_Moving_Gripper_Left" file="../igris_c_end_effector/1_dof_gripper/1DG_Left_Moving.stl" scale="0.01 0.01 0.01" />
    <mesh name="1_DoF_Fixed_Gripper_Right" file="../igris_c_end_effector/1_dof_gripper/1DG_Right_Fixed.stl" scale="0.01 0.01 0.01" />
    <mesh name="1_DoF_Moving_Gripper_Right" file="../igris_c_end_effector/1_dof_gripper/1DG_Right_Moving.stl" scale="0.01 0.01 0.01" />
  </asset>
  <worldbody>
    <geom name="floor" size="10 10 .05" type="plane" material="grid" condim="3" />
    <light directional="true" diffuse=".8 .8 .8" pos="0 0 10" dir="0.5 0.5 -5" />
    <light directional="true" diffuse=".3 .3 .3" pos="10 0 0" dir="-10 0 0" />
    <body name="base_link" pos="0.0 0.0 1.2" quat="1 0 0 0" childclass="robot">
      <site name="pelvis_link_site" pos="0.0615 0 0.187" quat="1 0 0 0" size="0.01" />
      <freejoint name="floating_base" />
      <inertial pos="-0.0356 0.0 -0.09163" mass="8.124" fullinertia="0.04342 0.05156 0.04212 0.00001 0.00325 0.00000" />
      <geom name="base_link_collision" pos="0 0 0" quat="1 0 0 0" type="mesh" mesh="Upper_Body" class="collision" />
      <geom name="base_link_visual" pos="0 0 0" quat="1 0 0 0" material="random" type="mesh" mesh="Upper_Body" class="visual" />
      <body name="Link_Hip_Pitch_Left" pos="0 0.0897 0" quat="1.0 0.0 0.0 0.0">
        <joint name="Joint_Hip_Pitch_Left" type="hinge" ref="0.0" class="actuator_150" range="-2.042035225 0.523598776" axis="0 1 0" />
        <inertial pos="0.00973 -0.00102 0.00002" quat="1.0 0.0 0.0 0.0" mass="1.894" diaginertia="0.00261 0.00267 0.00258" />
        <geom name="Link_Hip_Pitch_Left_visual" pos="0 0 0" quat="1 0 0 0" material="random" type="mesh" mesh="Hip_Pitch_Left" class="visual" />
        <body name="Link_Hip_Roll_Left" pos="0 0 0" quat="1.0 0.0 0.0 0.0">
          <joint name="Joint_Hip_Roll_Left" type="hinge" ref="0.0" class="actuator_120" range="-0.331612558 2.35619449" axis="1 0 0" />
          <inertial pos="-0.01497 0.00570 -0.03564" quat="1.0 0.0 0.0 0.0" mass="0.573" diaginertia="0.00103 0.00226 0.00206" />
          <geom name="Link_Hip_Roll_Left_collision" pos="-0.0 0.0 -0.00" quat="0.707 0 0.707 0" size="0.06 0.025" type="capsule" class="collision" />
          <geom name="Link_Hip_Roll_Left_visual" pos="0 0 0" quat="1 0 0 0" material="random" type="mesh" mesh="Hip_Roll_Left" class="visual" />
          <body name="Link_Hip_Yaw_Left" pos="0.002 0 -0.076" quat="1.0 0.0 0.0 0.0">
            <joint name="Joint_Hip_Yaw_Left" type="hinge" ref="0.0" class="actuator_60" range="-1.570796327 1.570796327" axis="0 0 1" />
            <inertial pos="-0.01286 -0.00388 -0.10563" quat="1.0 0.0 0.0 0.0" mass="4.813" diaginertia="0.03161 0.03396 0.01135" />
            <geom name="Link_Hip_Yaw_Left_collision" pos="0 0 0" quat="1 0 0 0" type="mesh" mesh="Hip_Yaw_Left_collision" class="collision" />
            <geom name="Link_Hip_Yaw_Left_visual" pos="0 0 0" quat="1 0 0 0" material="random" type="mesh" mesh="Hip_Yaw_Left" class="visual" />
            <body name="Link_Knee_Pitch_Left" pos="-0.055 0 -0.263" quat="1.0 0.0 0.0 0.0">
              <joint name="Joint_Knee_Pitch_Left" type="hinge" ref="0.0" class="actuator_150" range="0 2.28638132" axis="0 1 0" />
              <inertial pos="0.01044 0.00096 -0.12320" quat="1.0 0.0 0.0 0.0" mass="3.212" diaginertia="0.02686 0.02845 0.0052" />
              <geom name="Link_Knee_Pitch_Left_collision" pos="0 0 0" quat="1 0 0 0" type="mesh" mesh="Knee_Pitch_Left" class="collision" />
              <geom name="Link_Knee_Pitch_Left_visual" pos="0 0 0" quat="1 0 0 0" material="random" type="mesh" mesh="Knee_Pitch_Left" class="visual" />
              <body name="Link_Ankle_Pitch_Left" pos="0.005 0 -0.34" quat="1.0 0.0 0.0 0.0">
                <joint name="Joint_Ankle_Pitch_Left" type="hinge" ref="0.0" class="actuator_90" range="-0.698131701 0.698131701" axis="0 1 0" />
                <inertial pos="0.00000 0.00000 0.00000" quat="1.0 0.0 0.0 0.0" mass="0.084" diaginertia="3e-05 2e-05 3e-05" />
                <geom name="Link_Ankle_Pitch_Left_visual" pos="0 0 0" quat="1 0 0 0" material="random" type="mesh" mesh="Ankle_Pitch_Left" class="visual" />
                <body name="Link_Ankle_Roll_Left" pos="0 0 0" quat="1.0 0.0 0.0 0.0">
                  <joint name="Joint_Ankle_Roll_Left" type="hinge" ref="0.0" class="actuator_90" range="-0.261799388 0.261799388" axis="1 0 0" />
                  <inertial pos="0.02167 0.00000 -0.05193" quat="1.0 0.0 0.0 0.0" mass="0.459" diaginertia="0.00045 0.00166 0.00158" />
                  <geom name="Link_Ankle_Roll_Left_collision" pos="0 0 0" quat="1 0 0 0" type="mesh" mesh="Ankle_Roll_Left_collision" class="collision" />
                  <geom name="Link_Ankle_Roll_Left_visual" pos="0 0 0" quat="1 0 0 0" material="random" type="mesh" mesh="Ankle_Roll_Left" class="visual" />
                </body>
              </body>
            </body>
          </body>
        </body>
      </body>
      <body name="Link_Hip_Pitch_Right" pos="0 -0.0897 0" quat="1.0 0.0 0.0 0.0">
        <joint name="Joint_Hip_Pitch_Right" type="hinge" ref="0.0" class="actuator_150" range="-2.059488517 0.523598776" axis="0 1 0" />
        <inertial pos="0.00973 0.00102 -0.00002" quat="1.0 0.0 0.0 0.0" mass="1.894" diaginertia="0.00261 0.00267 0.00258" />
        <geom name="Link_Hip_Pitch_Right_visual" pos="0 0 0" quat="1 0 0 0" material="random" type="mesh" mesh="Hip_Pitch_Right" class="visual" />
        <body name="Link_Hip_Roll_Right" pos="0 0 0" quat="1.0 0.0 0.0 0.0">
          <joint name="Joint_Hip_Roll_Right" type="hinge" ref="0.0" class="actuator_120" range="-2.35619449 0.331612558" axis="1 0 0" />
          <inertial pos="-0.01497 -0.00570 -0.03564" quat="1.0 0.0 0.0 0.0" mass="0.573" diaginertia="0.00103 0.00226 0.00206" />
          <geom name="Link_Hip_Roll_Right_collision" pos="-0.0 0.0 -0.00" quat="0.707 0 0.707 0" size="0.06 0.025" type="capsule" class="collision" />
          <geom name="Link_Hip_Roll_Right_visual" pos="0 0 0" quat="1 0 0 0" material="random" type="mesh" mesh="Hip_Roll_Right" class="visual" />
          <body name="Link_Hip_Yaw_Right" pos="0.002 0 -0.076" quat="1.0 0.0 0.0 0.0">
            <joint name="Joint_Hip_Yaw_Right" type="hinge" ref="0.0" class="actuator_60" range="-1.570796327 1.570796327" axis="0 0 1" />
            <inertial pos="-0.01286 0.00388 -0.10564" quat="1.0 0.0 0.0 0.0" mass="4.813" diaginertia="0.03161 0.03398 0.01137" />
            <geom name="Link_Hip_Yaw_Right_collision" pos="0 0 0" quat="1 0 0 0" type="mesh" mesh="Hip_Yaw_Right_collision" class="collision" />
            <geom name="Link_Hip_Yaw_Right_visual" pos="0 0 0" quat="1 0 0 0" material="random" type="mesh" mesh="Hip_Yaw_Right" class="visual" />
            <body name="Link_Knee_Pitch_Right" pos="-0.055 0 -0.263" quat="1.0 0.0 0.0 0.0">
              <joint name="Joint_Knee_Pitch_Right" type="hinge" ref="0.0" class="actuator_150" range="0 2.28638132" axis="0 1 0" />
              <inertial pos="0.01044 -0.00096 -0.12320" quat="1.0 0.0 0.0 0.0" mass="3.212" diaginertia="0.02686 0.02845 0.0052" />
              <geom name="Link_Knee_Pitch_Right_collision" pos="0 0 0" quat="1 0 0 0" type="mesh" mesh="Knee_Pitch_Right" class="collision" />
              <geom name="Link_Knee_Pitch_Right_visual" pos="0 0 0" quat="1 0 0 0" material="random" type="mesh" mesh="Knee_Pitch_Right" class="visual" />
              <body name="Link_Ankle_Pitch_Right" pos="0.005 0 -0.34" quat="1.0 0.0 0.0 0.0">
                <joint name="Joint_Ankle_Pitch_Right" type="hinge" ref="0.0" class="actuator_90" range="-0.698131701 0.698131701" axis="0 1 0" />
                <inertial pos="0 0 0" quat="1.0 0.0 0.0 0.0" mass="0.084" diaginertia="3e-05 2e-05 3e-05" />
                <geom name="Link_Ankle_Pitch_Right_visual" pos="0 0 0" quat="1 0 0 0" material="random" type="mesh" mesh="Ankle_Pitch_Right" class="visual" />
                <body name="Link_Ankle_Roll_Right" pos="0 0 0" quat="1.0 0.0 0.0 0.0">
                  <joint name="Joint_Ankle_Roll_Right" type="hinge" ref="0.0" class="actuator_90" range="-0.261799388 0.261799388" axis="1 0 0" />
                  <inertial pos="0.02167 0.00000 -0.05193" quat="1.0 0.0 0.0 0.0" mass="0.459" diaginertia="0.00045 0.00166 0.00158" />
                  <geom name="Link_Ankle_Roll_Right_collision" pos="0 0 0" quat="1 0 0 0" type="mesh" mesh="Ankle_Roll_Right_collision" class="collision" />
                  <geom name="Link_Ankle_Roll_Right_visual" pos="0 0 0" quat="1 0 0 0" material="random" type="mesh" mesh="Ankle_Roll_Right" class="visual" />
                </body>
              </body>
            </body>
          </body>
        </body>
      </body>
      <body name="Link_Waist_Pitch" pos="0.0115 0 0.14" quat="1.0 0.0 0.0 0.0">
        <joint name="Joint_Waist_Pitch" type="hinge" ref="0.0" class="actuator_60" range="-0.872664626 0.287979327" axis="0 -1 0" />
        <inertial pos="0.00000 0.00000 0.03171" quat="1.0 0.0 0.0 0.0" mass="0.136" diaginertia="0.00005 0.00011 0.00007" />
        <geom name="Link_Waist_Pitch_visual" pos="0 0 0" quat="1 0 0 0" material="random" type="mesh" mesh="Waist_Pitch" class="visual" />
        <body name="Link_Waist_Roll" pos="0 0 0.04" quat="1.0 0.0 0.0 0.0">
          <joint name="Joint_Waist_Roll" type="hinge" ref="0.0" class="actuator_60" range="-0.314159265 0.314159265" axis="-1 0 0" />
          <inertial pos="-0.02403 0.00000 0.01673" quat="1.0 0.0 0.0 0.0" mass="0.208" diaginertia="0.00031 0.00031 0.00058" />
          <geom name="Link_Waist_Roll_visual" pos="0 0 0" quat="1 0 0 0" material="random" type="mesh" mesh="Waist_Roll" class="visual" />
          <body name="Link_Waist_Yaw" pos="-0.05 0 0.026" quat="1.0 0.0 0.0 0.0">
            <joint name="Joint_Waist_Yaw" type="hinge" ref="0.0" class="actuator_60" range="-1.570796327 1.570796327" axis="0 0 -1" />
            <site name="base_link_imu_site" pos="0.050 0 0.047" quat="0.7071068 0.0 0.7071068 0.0" size="0.01" />
            <inertial pos="0.00175 0.00112 0.15154" mass="12.974" fullinertia="0.15110 0.12880 0.08070 -0.00136 0.00843 -0.00089" />
            <geom name="Link_Waist_Yaw_collision" pos="0 0 0" quat="1 0 0 0" type="mesh" mesh="Waist_Yaw" class="collision" />
            <geom name="Link_Waist_Yaw_visual" pos="0 0 0" quat="1 0 0 0" material="random" type="mesh" mesh="Waist_Yaw" class="visual" />
            <body name="Link_Neck_Yaw" pos="0 0 0.357" quat="1.0 0.0 0.0 0.0">
              <joint name="Joint_Neck_Yaw" type="hinge" ref="0.0" class="actuator_7" range="-1.221730476 1.221730476" axis="0 0 1" />
              <inertial pos="-0.00005 -0.00130 -0.00264" quat="1.0 0.0 0.0 0.0" mass="0.310" diaginertia="0.00017 0.0001 0.00016" />
              <geom name="Link_Neck_Yaw_visual" pos="0 0 0" quat="1 0 0 0" material="random" type="mesh" mesh="Neck_Yaw" class="visual" />
              <body name="Link_Neck_Pitch" pos="0 0 0" quat="1.0 0.0 0.0 0.0">
                <joint name="Joint_Neck_Pitch" type="hinge" ref="0.0" class="actuator_7" range="-0.523598776 0.523598776" axis="0 1 0" />
                <inertial pos="0.02850 0.00290 0.12862" quat="1.0 0.0 0.0 0.0" mass="1.468" diaginertia="0.00574 0.00727 0.00503" />
                <geom name="Link_Neck_Pitch_visual" pos="0 0 0" quat="1 0 0 0" material="random" type="mesh" mesh="Neck_Pitch" class="visual" />
              </body>
            </body>
            <body name="Link_Shoulder_Pitch_Left" pos="0 0.171 0.266" quat="1.0 0.0 0.0 0.0">
              <joint name="Joint_Shoulder_Pitch_Left" type="hinge" ref="0.0" class="actuator_60" range="-3.141592654 1.047197551" axis="0 1 0" />
              <inertial pos="0.00039 -0.00330 0.00004" quat="1.0 0.0 0.0 0.0" mass="1.105" diaginertia="0.00118 0.00097 0.00107" />
              <geom name="Link_Shoulder_Pitch_Left_visual" pos="0 0 0" quat="1 0 0 0" material="random" type="mesh" mesh="Shoulder_Pitch_Left" class="visual" />
              <body name="Link_Shoulder_Roll_Left" pos="0 0 0" quat="0.99788824 0.06495424 0 0">
                <joint name="Joint_Shoulder_Roll_Left" type="hinge" ref="0.0" class="actuator_60" range="-0.174532925 3.141592654" axis="1 0 0" />
                <inertial pos="0.02322 0.00000 -0.03100" quat="1.0 0.0 0.0 0.0" mass="0.253" diaginertia="0.00046 0.00046 0.00034" />
                <geom name="Link_Shoulder_Roll_Left_visual" pos="0 0 0" quat="1 0 0 0" material="random" type="mesh" mesh="Shoulder_Roll_Left" class="visual" />
                <body name="Link_Shoulder_Yaw_Left" pos="0 0 0" quat="1.0 0.0 0.0 0.0">
                  <joint name="Joint_Shoulder_Yaw_Left" type="hinge" ref="0.0" class="actuator_60" range="-1.570796327 1.570796327" axis="0 0 1" />
                  <inertial pos="0.00289 0.00039 -0.14632" quat="1.0 0.0 0.0 0.0" mass="2.144" diaginertia="0.00708 0.00723 0.00213" />
                  <geom name="Link_Shoulder_Yaw_Left_collision" pos="0 0 -0.09" quat="1 0 0 0" type="capsule" size="0.055 0.03" class="collision" />
                  <geom name="Link_Shoulder_Yaw_Left_visual" pos="0 0 0" quat="1 0 0 0" material="random" type="mesh" mesh="Shoulder_Yaw_Left" class="visual" />
                  <body name="Link_Elbow_Pitch_Left" pos="0.01 0 -0.197" quat="0.58168309 0 -0.81341550 0">
                    <joint name="Joint_Elbow_Pitch_Left" type="hinge" ref="0.0" class="actuator_60" range="-2.094395102 0" axis="0 1 0" />
                    <inertial pos="-0.00506 0.02516 -0.02257" quat="1.0 0.0 0.0 0.0" mass="0.137" diaginertia="0.00017 0.00017 0.00013" />
                    <geom name="Link_Elbow_Pitch_Left_visual" pos="0 0 0" quat="1 0 0 0" material="random" type="mesh" mesh="Elbow_Pitch_Left" class="visual" />
                    <body name="Link_Wrist_Yaw_Left" pos="-0.01 0 -0.05" quat="1.0 0.0 0.0 0.0">
                      <joint name="Joint_Wrist_Yaw_Left" type="hinge" ref="0.0" class="actuator_8" range="-1.570796327 1.570796327" axis="0 0 1" />
                      <inertial pos="-0.00019 0.00001 -0.08347" quat="1.0 0.0 0.0 0.0" mass="2.299" diaginertia="0.00819 0.00912 0.00302" />
                      <geom name="Link_Wrist_Yaw_Left_collision" pos="0 0 -0.12" quat="1 0 0 0" type="capsule" size="0.055 0.07" class="collision" />
                      <geom name="Link_Wrist_Yaw_Left_visual" pos="0 0 0" quat="1 0 0 0" material="random" type="mesh" mesh="Wrist_Yaw_Left" class="visual" />
                      <body name="Link_Wrist_Roll_Left" pos="0 -0.005 -0.2395 " quat="1.0 0.0 0.0 0.0">
                        <joint name="Joint_Wrist_Roll_Left" type="hinge" ref="0.0" class="actuator_8" range="-0.872664626 1.221730476" axis="1 0 0" />
                        <inertial pos="0.00000 0.00604 0.00031" quat="1.0 0.0 0.0 0.0" mass="0.012" diaginertia="0.00001 0.00001 0.00001" />
                        <geom name="Link_Wrist_Roll_Left_visual" pos="0 0 0" quat="1 0 0 0" material="random" type="mesh" mesh="Wrist_Roll_Left" class="visual" />
                        <body name="Link_Wrist_Pitch_Left" pos="0 0 0" quat="1.0 0.0 0.0 0.0">
                          <joint name="Joint_Wrist_Pitch_Left" type="hinge" ref="0.0" class="actuator_8" range="-0.698131701 0.698131701" axis="0 1 0" />
                          <inertial pos="0 0.01019 -0.01687" quat="1.0 0.0 0.0 0.0" mass="0.020" diaginertia="0.00001 0.00001 0.00001" />
                          <geom name="Link_Wrist_Pitch_Left_visual" pos="0 0 0" quat="1 0 0 0" material="random" type="mesh" mesh="Wrist_Pitch_Left" class="visual" />
                          <body name="1_DoF_Fixed_Gripper_Left" pos="0 0 -0.024" quat="1.0 0.0 0.0 0.0">
                            <inertial pos="0.00396 0.00377 -0.05310" quat="1.0 0.0 0.0 0.0" mass="0.271" diaginertia="0.00033 0.00040 0.00021" />
                            <geom name="1_DoF_Fixed_Gripper_Left_visual" pos="0 0 0" quat="1 0 0 0" type="mesh" mesh="1_DoF_Fixed_Gripper_Left" material="random" class="visual" />
                            <body name="1_DoF_Moving_Gripper_Left" pos="0 0.02625 -0.04225" quat="1.0 0.0 0.0 0.0">
                              <joint name="1_DoF_Moving_Gripper_Left" type="hinge" ref="0.0" class="passive" range="0 1.74533" limited="true" axis="1 0 0" />
                              <inertial pos="-0.00028 -0.00857 -0.04908" quat="1.0 0.0 0.0 0.0" mass="0.093" diaginertia="0.00007 0.00009 0.00004" />
                              <geom name="1_DoF_Moving_Gripper_Left_visual" pos="0 0 0" quat="1 0 0 0" type="mesh" mesh="1_DoF_Moving_Gripper_Left" material="random" class="visual" />
                            </body>
                          </body>
                        </body>
                      </body>
                    </body>
                  </body>
                </body>
              </body>
            </body>
            <body name="Link_Shoulder_Pitch_Right" pos="0 -0.171 0.266" quat="1.0 0.0 0.0 0.0">
              <joint name="Joint_Shoulder_Pitch_Right" type="hinge" ref="0.0" class="actuator_60" range="-3.141592654 1.047197551" axis="0 1 0" />
              <inertial pos="0.00039 0.00330 -0.00004" quat="1.0 0.0 0.0 0.0" mass="1.105" diaginertia="0.00118 0.00097 0.00107" />
              <geom name="Link_Shoulder_Pitch_Right_visual" pos="0 0 0" quat="1 0 0 0" material="random" type="mesh" mesh="Shoulder_Pitch_Right" class="visual" />
              <body name="Link_Shoulder_Roll_Right" pos="0 0 0" quat="0.99788824 -0.06495424 0 0">
                <joint name="Joint_Shoulder_Roll_Right" type="hinge" ref="0.0" class="actuator_60" range="-3.141592654 0.174532925" axis="1 0 0" />
                <inertial pos="0.02322 0.00000 -0.03100" quat="1.0 0.0 0.0 0.0" mass="0.253" diaginertia="0.00046 0.00046 0.00034" />
                <geom name="Link_Shoulder_Roll_Right_visual" pos="0 0 0" quat="1 0 0 0" material="random" type="mesh" mesh="Shoulder_Roll_Right" class="visual" />
                <body name="Link_Shoulder_Yaw_Right" pos="0 0 0" quat="1.0 0.0 0.0 0.0">
                  <joint name="Joint_Shoulder_Yaw_Right" type="hinge" ref="0.0" class="actuator_60" range="-1.570796327 1.570796327" axis="0 0 1" />
                  <inertial pos="0.00289 -0.00018 -0.14632" quat="1.0 0.0 0.0 0.0" mass="2.144" diaginertia="0.00708 0.00723 0.00213" />
                  <geom name="Link_Shoulder_Yaw_Right_collision" pos="0 0 -0.09" quat="1 0 0 0" type="capsule" size="0.055 0.03" class="collision" />
                  <geom name="Link_Shoulder_Yaw_Right_visual" pos="0 0 0" quat="1 0 0 0" material="random" type="mesh" mesh="Shoulder_Yaw_Right" class="visual" />
                  <body name="Link_Elbow_Pitch_Right" pos="0.01 0 -0.197" quat="0.58168309 0 -0.81341550 0">
                    <joint name="Joint_Elbow_Pitch_Right" type="hinge" ref="0.0" class="actuator_60" range="-2.094395102 0" axis="0 1 0" />
                    <inertial pos="-0.00506 -0.02516 -0.02257" quat="1.0 0.0 0.0 0.0" mass="0.137" diaginertia="0.00017 0.00017 0.00013" />
                    <geom name="Link_Elbow_Pitch_Right_visual" pos="0 0 0" quat="1 0 0 0" material="random" type="mesh" mesh="Elbow_Pitch_Right" class="visual" />
                    <body name="Link_Wrist_Yaw_Right" pos="-0.01 0 -0.05" quat="1.0 0.0 0.0 0.0">
                      <joint name="Joint_Wrist_Yaw_Right" type="hinge" ref="0.0" class="actuator_8" range="-1.570796327 1.570796327" axis="0 0 1" />
                      <inertial pos="-0.00077 -0.00035 -0.08347" quat="1.0 0.0 0.0 0.0" mass="2.299" diaginertia="0.00819 0.00912 0.00302" />
                      <geom name="Link_Wrist_Yaw_Right_collision" pos="0 0 -0.12" quat="1 0 0 0" type="capsule" size="0.055 0.07" class="collision" />
                      <geom name="Link_Wrist_Yaw_Right_visual" pos="0 0 0" quat="1 0 0 0" material="random" type="mesh" mesh="Wrist_Yaw_Right" class="visual" />
                      <body name="Link_Wrist_Roll_Right" pos="0 0.005 -0.2395" quat="1.0 0.0 0.0 0.0">
                        <joint name="Joint_Wrist_Roll_Right" type="hinge" ref="0.0" class="actuator_8" range="-1.221730476 0.872664626" axis="1 0 0" />
                        <inertial pos="0.00000 -0.00604 0.00031" quat="1.0 0.0 0.0 0.0" mass="0.012" diaginertia="0.00001 0.00001 0.00001" />
                        <geom name="Link_Wrist_Roll_Right_visual" pos="0 0 0" quat="1 0 0 0" material="random" type="mesh" mesh="Wrist_Roll_Right" class="visual" />
                        <body name="Link_Wrist_Pitch_Right" pos="0 0 0" quat="1.0 0.0 0.0 0.0">
                          <joint name="Joint_Wrist_Pitch_Right" type="hinge" ref="0.0" class="actuator_8" range="-0.698131701 0.698131701" axis="0 1 0" />
                          <inertial pos="0.00000 -0.01019 -0.01687" quat="1.0 0.0 0.0 0.0" mass="0.020" diaginertia="0.00001 0.00001 0.00001" />
                          <geom name="Link_Wrist_Pitch_Right_visual" pos="0 0 0" quat="1 0 0 0" material="random" type="mesh" mesh="Wrist_Pitch_Right" class="visual" />
                          <body name="1_DoF_Fixed_Gripper_Right" pos="0 0 -0.024" quat="1.0 0.0 0.0 0.0">
                            <inertial pos="0.00396 0.00377 -0.05310" quat="1.0 0.0 0.0 0.0" mass="0.271" diaginertia="0.00033 0.00040 0.00021" />
                            <geom name="1_DoF_Fixed_Gripper_Right_visual" pos="0 0 0" quat="1 0 0 0" type="mesh" mesh="1_DoF_Fixed_Gripper_Right" material="random" class="visual" />
                            <body name="1_DoF_Moving_Gripper_Right" pos="0 -0.02625 -0.04225" quat="1.0 0.0 0.0 0.0">
                              <joint name="1_DoF_Moving_Gripper_Right" type="hinge" ref="0.0" class="passive" range="-1.74533 0" limited="true" axis="1 0 0" />
                              <inertial pos="-0.00028 0.00857 -0.04908" quat="1.0 0.0 0.0 0.0" mass="0.093" diaginertia="0.00007 0.00009 0.00004" />
                              <geom name="1_DoF_Moving_Gripper_Right_visual" pos="0 0 0" quat="1 0 0 0" type="mesh" mesh="1_DoF_Moving_Gripper_Right" material="random" class="visual" />
                            </body>
                          </body>
                        </body>
                      </body>
                    </body>
                  </body>
                </body>
              </body>
            </body>
          </body>
        </body>
      </body>
    </body>
  </worldbody>
  <actuator>
    <motor name="Joint_Waist_Yaw" joint="Joint_Waist_Yaw" class="actuator_60" />
    <motor name="Joint_Waist_Roll" joint="Joint_Waist_Roll" class="actuator_60" />
    <motor name="Joint_Waist_Pitch" joint="Joint_Waist_Pitch" class="actuator_60" />
    <motor name="Joint_Hip_Pitch_Left" joint="Joint_Hip_Pitch_Left" class="actuator_150" />
    <motor name="Joint_Hip_Roll_Left" joint="Joint_Hip_Roll_Left" class="actuator_120" />
    <motor name="Joint_Hip_Yaw_Left" joint="Joint_Hip_Yaw_Left" class="actuator_60" />
    <motor name="Joint_Knee_Pitch_Left" joint="Joint_Knee_Pitch_Left" class="actuator_150" />
    <motor name="Joint_Ankle_Pitch_Left" joint="Joint_Ankle_Pitch_Left" class="actuator_90" />
    <motor name="Joint_Ankle_Roll_Left" joint="Joint_Ankle_Roll_Left" class="actuator_90" />
    <motor name="Joint_Hip_Pitch_Right" joint="Joint_Hip_Pitch_Right" class="actuator_150" />
    <motor name="Joint_Hip_Roll_Right" joint="Joint_Hip_Roll_Right" class="actuator_120" />
    <motor name="Joint_Hip_Yaw_Right" joint="Joint_Hip_Yaw_Right" class="actuator_60" />
    <motor name="Joint_Knee_Pitch_Right" joint="Joint_Knee_Pitch_Right" class="actuator_150" />
    <motor name="Joint_Ankle_Pitch_Right" joint="Joint_Ankle_Pitch_Right" class="actuator_90" />
    <motor name="Joint_Ankle_Roll_Right" joint="Joint_Ankle_Roll_Right" class="actuator_90" />
    <motor name="Joint_Shoulder_Pitch_Left" joint="Joint_Shoulder_Pitch_Left" class="actuator_60" />
    <motor name="Joint_Shoulder_Roll_Left" joint="Joint_Shoulder_Roll_Left" class="actuator_60" />
    <motor name="Joint_Shoulder_Yaw_Left" joint="Joint_Shoulder_Yaw_Left" class="actuator_60" />
    <motor name="Joint_Elbow_Pitch_Left" joint="Joint_Elbow_Pitch_Left" class="actuator_60" />
    <motor name="Joint_Wrist_Yaw_Left" joint="Joint_Wrist_Yaw_Left" class="actuator_8" />
    <motor name="Joint_Wrist_Roll_Left" joint="Joint_Wrist_Roll_Left" class="actuator_8" />
    <motor name="Joint_Wrist_Pitch_Left" joint="Joint_Wrist_Pitch_Left" class="actuator_8" />
    <motor name="Joint_Shoulder_Pitch_Right" joint="Joint_Shoulder_Pitch_Right" class="actuator_60" />
    <motor name="Joint_Shoulder_Roll_Right" joint="Joint_Shoulder_Roll_Right" class="actuator_60" />
    <motor name="Joint_Shoulder_Yaw_Right" joint="Joint_Shoulder_Yaw_Right" class="actuator_60" />
    <motor name="Joint_Elbow_Pitch_Right" joint="Joint_Elbow_Pitch_Right" class="actuator_60" />
    <motor name="Joint_Wrist_Yaw_Right" joint="Joint_Wrist_Yaw_Right" class="actuator_8" />
    <motor name="Joint_Wrist_Roll_Right" joint="Joint_Wrist_Roll_Right" class="actuator_8" />
    <motor name="Joint_Wrist_Pitch_Right" joint="Joint_Wrist_Pitch_Right" class="actuator_8" />
    <motor name="Joint_Neck_Yaw" joint="Joint_Neck_Yaw" class="actuator_7" />
    <motor name="Joint_Neck_Pitch" joint="Joint_Neck_Pitch" class="actuator_7" />
    <!-- Gripper actuators are staged but disabled until a dedicated gripper controller is wired in.
    <motor name="1_DoF_Moving_Gripper_Left" joint="1_DoF_Moving_Gripper_Left" class="actuator_8" />
    <motor name="1_DoF_Moving_Gripper_Right" joint="1_DoF_Moving_Gripper_Right" class="actuator_8" />
    -->
  </actuator>
  <contact>
    <exclude body1="base_link" body2="Link_Waist_Pitch" />
    <exclude body1="Link_Waist_Pitch" body2="Link_Waist_Roll" />
    <exclude body1="Link_Waist_Roll" body2="Link_Waist_Yaw" />
    <exclude body1="Link_Waist_Yaw" body2="Link_Neck_Yaw" />
    <exclude body1="Link_Neck_Yaw" body2="Link_Neck_Pitch" />
    <exclude body1="base_link" body2="Link_Hip_Pitch_Left" />
    <exclude body1="Link_Hip_Pitch_Left" body2="Link_Hip_Roll_Left" />
    <exclude body1="Link_Hip_Roll_Left" body2="Link_Hip_Yaw_Left" />
    <exclude body1="Link_Hip_Yaw_Left" body2="Link_Knee_Pitch_Left" />
    <exclude body1="Link_Knee_Pitch_Left" body2="Link_Ankle_Pitch_Left" />
    <exclude body1="Link_Ankle_Pitch_Left" body2="Link_Ankle_Roll_Left" />
    <exclude body1="base_link" body2="Link_Hip_Pitch_Right" />
    <exclude body1="Link_Hip_Pitch_Right" body2="Link_Hip_Roll_Right" />
    <exclude body1="Link_Hip_Roll_Right" body2="Link_Hip_Yaw_Right" />
    <exclude body1="Link_Hip_Yaw_Right" body2="Link_Knee_Pitch_Right" />
    <exclude body1="Link_Knee_Pitch_Right" body2="Link_Ankle_Pitch_Right" />
    <exclude body1="Link_Ankle_Pitch_Right" body2="Link_Ankle_Roll_Right" />
    <exclude body1="Link_Waist_Yaw" body2="Link_Shoulder_Pitch_Left" />
    <exclude body1="Link_Shoulder_Pitch_Left" body2="Link_Shoulder_Roll_Left" />
    <exclude body1="Link_Shoulder_Roll_Left" body2="Link_Shoulder_Yaw_Left" />
    <exclude body1="Link_Shoulder_Yaw_Left" body2="Link_Elbow_Pitch_Left" />
    <exclude body1="Link_Elbow_Pitch_Left" body2="Link_Wrist_Yaw_Left" />
    <exclude body1="Link_Wrist_Yaw_Left" body2="Link_Wrist_Roll_Left" />
    <exclude body1="Link_Wrist_Roll_Left" body2="Link_Wrist_Pitch_Left" />
    <exclude body1="Link_Waist_Yaw" body2="Link_Shoulder_Pitch_Right" />
    <exclude body1="Link_Shoulder_Pitch_Right" body2="Link_Shoulder_Roll_Right" />
    <exclude body1="Link_Shoulder_Roll_Right" body2="Link_Shoulder_Yaw_Right" />
    <exclude body1="Link_Shoulder_Yaw_Right" body2="Link_Elbow_Pitch_Right" />
    <exclude body1="Link_Elbow_Pitch_Right" body2="Link_Wrist_Yaw_Right" />
    <exclude body1="Link_Wrist_Yaw_Right" body2="Link_Wrist_Roll_Right" />
    <exclude body1="Link_Wrist_Roll_Right" body2="Link_Wrist_Pitch_Right" />
    <exclude body1="Link_Wrist_Pitch_Left" body2="1_DoF_Fixed_Gripper_Left" />
    <exclude body1="1_DoF_Fixed_Gripper_Left" body2="1_DoF_Moving_Gripper_Left" />
    <exclude body1="Link_Wrist_Pitch_Right" body2="1_DoF_Fixed_Gripper_Right" />
    <exclude body1="1_DoF_Fixed_Gripper_Right" body2="1_DoF_Moving_Gripper_Right" />
  </contact>
  <sensor>
    <gyro site="base_link_imu_site" name="imu-pelvis-angular-velocity" cutoff="34.9" noise="0.0005" />
    <accelerometer site="base_link_imu_site" name="imu-pelvis-linear-acceleration" cutoff="157" noise="0.01" />
    <framequat name="imu-pelvis-quat" objtype="site" objname="base_link_imu_site" />
  </sensor>
  <keyframe>
    <key name="initial" qpos="0 0 0.754 1 0 0 0 -0.1 0 0 0.3 -0.2 0 -0.1 0 0 0.3 -0.2 0 0 0 0 0 0 0.3 0.13 0 0 0 0 0 0 -1.57 0 0 0 0 0 0 0" />
  </keyframe>
</mujoco>
