<?xml version="1.0"?>
<mujoco model="igris_c_v2_pelvis_base_parallel_hand">
  <compiler angle="radian" meshdir="../meshes/igris_c_v2/" balanceinertia="false"/>
  <size njmax="8000" nconmax="4000"/>
  <option timestep="0.0003333" iterations="100" tolerance="1e-7" solver="Newton" jacobian="dense" cone="elliptic" noslip_iterations="10" noslip_tolerance="1e-7"/>
  <default>
    <default class="robot">
      <default class="visual">
        <geom group="1" type="mesh" contype="0" conaffinity="0" density="0" rgba="0.9 0.9 0.9 1.0"/>
      </default>
      <default class="collision">
        <geom material="collision_material" rgba="1.0 0.28 0.1 1.0" condim="3" contype="1" conaffinity="1" priority="1" group="2" solref="0.01 1" friction="1 0.005 0.0001"/>
        <equality solimp="0.9 0.95 0.001 0.5 2" solref="0.001 1"/>
      </default>
    </default>
    <motor ctrllimited="true"/>
    <default class="actuator_150">
      <joint damping="0.5" frictionloss="0.5" limited="true" armature="0.2"/>
      <motor ctrlrange="-150.0 150.0"/>
    </default>
    <default class="actuator_120">
      <joint damping="0.5" frictionloss="2." limited="true" armature="0.12"/>
      <motor ctrlrange="-120.0 120.0"/>
    </default>
    <default class="actuator_90">
      <joint damping="0.0" frictionloss="0.1" limited="true" armature="0.1"/>
      <motor ctrlrange="-90.0 90.0"/>
    </default>
    <default class="actuator_60">
      <joint damping="0.5" frictionloss="0.54" limited="true" armature="0.019"/>
      <motor ctrlrange="-60.0 60.0"/>
    </default>
    <default class="actuator_8">
      <joint damping="0.0" frictionloss="0.264" limited="true" armature="0.01433"/>
      <motor ctrlrange="-8.0 8.0"/>
    </default>
    <default class="actuator_7">
      <joint damping="1.0" frictionloss="0.356" limited="true" armature="0.2488"/>
      <motor ctrlrange="-7.0 7.0"/>
    </default>
    <default class="passive">
      <joint damping="0.001" frictionloss="1e-4" limited="false" armature="1e-6"/>
    </default>
  </default>
  <asset>
    <material name="random" rgba="0.0706 0.0706 0.0706 0.7"/>
    <material name="default_material" rgba="0.7 0.7 0.7 1"/>
    <material name="collision_material" rgba="1.0 0.28 0.1 0.9"/>
    <mesh name="Upper_Body" file="Pelvis.stl" scale="0.01 0.01 0.01"/>
    <mesh name="Waist_Yaw" file="Waist_Yaw.stl" scale="0.01 0.01 0.01"/>
    <mesh name="Waist_Roll" file="Waist_Roll.stl" scale="0.01 0.01 0.01"/>
    <mesh name="Waist_Pitch" file="Waist_Pitch.stl" scale="0.01 0.01 0.01"/>
    <mesh name="Neck_Yaw" file="Neck_Yaw.stl" scale="0.01 0.01 0.01"/>
    <mesh name="Neck_Pitch" file="Neck_Pitch.stl" scale="0.01 0.01 0.01"/>
    <mesh name="Hip_Pitch_Left" file="Hip_Pitch_Left.stl" scale="0.01 0.01 0.01"/>
    <mesh name="Hip_Roll_Left" file="Hip_Roll_Left.stl" scale="0.01 0.01 0.01"/>
    <mesh name="Hip_Yaw_Left_collision" file="Hip_Yaw_CirCut.stl" scale="0.01 0.01 0.01"/>
    <mesh name="Hip_Yaw_Left" file="Hip_Yaw_Left.stl" scale="0.01 0.01 0.01"/>
    <mesh name="Knee_Pitch_Left" file="Knee_Pitch_Left.stl" scale="0.01 0.01 0.01"/>
    <mesh name="Ankle_Pitch_Left" file="Ankle_Pitch_Left.stl" scale="0.01 0.01 0.01"/>
    <mesh name="Ankle_Roll_Left_collision" file="Airforce_L_v1.stl" scale="0.01 0.01 0.01"/>
    <mesh name="Ankle_Roll_Left" file="Airforce_L_v1.stl" scale="0.01 0.01 0.01"/>
    <mesh name="Hip_Pitch_Right" file="Hip_Pitch_Right.stl" scale="0.01 0.01 0.01"/>
    <mesh name="Hip_Roll_Right" file="Hip_Roll_Right.stl" scale="0.01 0.01 0.01"/>
    <mesh name="Hip_Yaw_Right_collision" file="Hip_Yaw_CirCut.stl" scale="0.01 0.01 0.01"/>
    <mesh name="Hip_Yaw_Right" file="Hip_Yaw_Right.stl" scale="0.01 0.01 0.01"/>
    <mesh name="Knee_Pitch_Right" file="Knee_Pitch_Right.stl" scale="0.01 0.01 0.01"/>
    <mesh name="Ankle_Pitch_Right" file="Ankle_Pitch_Right.stl" scale="0.01 0.01 0.01"/>
    <mesh name="Ankle_Roll_Right_collision" file="Airforce_R_v1.stl" scale="0.01 0.01 0.01"/>
    <mesh name="Ankle_Roll_Right" file="Airforce_R_v1.stl" scale="0.01 0.01 0.01"/>
    <mesh name="Shoulder_Pitch_Left" file="Shoulder_Pitch_Left.stl" scale="0.01 0.01 0.01"/>
    <mesh name="Shoulder_Roll_Left" file="Shoulder_Roll_Left.stl" scale="0.01 0.01 0.01"/>
    <mesh name="Shoulder_Yaw_Left" file="Shoulder_Yaw_Left.stl" scale="0.01 0.01 0.01"/>
    <mesh name="Elbow_Pitch_Left" file="Elbow_Pitch_Left.stl" scale="0.01 0.01 0.01"/>
    <mesh name="Wrist_Yaw_Left" file="Wrist_Yaw_Left.stl" scale="0.01 0.01 0.01"/>
    <mesh name="Wrist_Roll_Left" file="Wrist_Roll_Left.stl" scale="0.01 0.01 0.01"/>
    <mesh name="Wrist_Pitch_Left" file="Wrist_Pitch_Left.stl" scale="0.01 0.01 0.01"/>
    <mesh name="Left_Hand" file="../igris_c_end_effector/hand/Palm_Left.stl" scale="0.01 0.01 0.01"/>
    <mesh name="Shoulder_Pitch_Right" file="Shoulder_Pitch_Right.stl" scale="0.01 0.01 0.01"/>
    <mesh name="Shoulder_Roll_Right" file="Shoulder_Roll_Right.stl" scale="0.01 0.01 0.01"/>
    <mesh name="Shoulder_Yaw_Right" file="Shoulder_Yaw_Right.stl" scale="0.01 0.01 0.01"/>
    <mesh name="Elbow_Pitch_Right" file="Elbow_Pitch_Right.stl" scale="0.01 0.01 0.01"/>
    <mesh name="Wrist_Yaw_Right" file="Wrist_Yaw_Right.stl" scale="0.01 0.01 0.01"/>
    <mesh name="Wrist_Roll_Right" file="Wrist_Roll_Right.stl" scale="0.01 0.01 0.01"/>
    <mesh name="Wrist_Pitch_Right" file="Wrist_Pitch_Right.stl" scale="0.01 0.01 0.01"/>
    <mesh name="Right_Hand" file="../igris_c_end_effector/hand/Palm_Right.stl" scale="0.01 0.01 0.01"/>
<mesh name="Thumb_Proximal_Left" file="../igris_c_end_effector/hand/Thumb_Proximal_Left.stl" scale="0.01 0.01 0.01"/>
    <mesh name="Thumb_Middle_Left" file="../igris_c_end_effector/hand/Thumb_Middle_Left.stl" scale="0.01 0.01 0.01"/>
    <mesh name="Thumb_Distal_Left" file="../igris_c_end_effector/hand/Thumb_Distal_Left.stl" scale="0.01 0.01 0.01"/>
    <mesh name="Thumb_Proximal_Right" file="../igris_c_end_effector/hand/Thumb_Proximal_Right.stl" scale="0.01 0.01 0.01"/>
    <mesh name="Thumb_Middle_Right" file="../igris_c_end_effector/hand/Thumb_Middle_Right.stl" scale="0.01 0.01 0.01"/>
    <mesh name="Thumb_Distal_Right" file="../igris_c_end_effector/hand/Thumb_Distal_Right.stl" scale="0.01 0.01 0.01"/>
    <mesh name="Finger_Middle" file="../igris_c_end_effector/hand/Finger_Middle.stl" scale="0.01 0.01 0.01"/>
    <mesh name="Finger_Distal" file="../igris_c_end_effector/hand/Finger_Distal.stl" scale="0.01 0.01 0.01"/>
    <mesh name="Waist_Flange_Left" file="Waist_Flange_Left.stl" scale="0.01 0.01 0.01"/>
    <mesh name="Waist_Flange_Right" file="Waist_Flange_Right.stl" scale="0.01 0.01 0.01"/>
    <mesh name="Waist_Parallel_Left" file="Waist_Parallel_Left.stl" scale="0.01 0.01 0.01"/>
    <mesh name="Waist_Parallel_Right" file="Waist_Parallel_Right.stl" scale="0.01 0.01 0.01"/>
    <mesh name="Ankle_Flange_Out_Left" file="Ankle_Flange_Out_Left.stl" scale="0.01 0.01 0.01"/>
    <mesh name="Ankle_Flange_In_Left" file="Ankle_Flange_In_Left.stl" scale="0.01 0.01 0.01"/>
    <mesh name="Ankle_Parallel_Out_Left" file="Ankle_Parallel_Out_Left.stl" scale="0.01 0.01 0.01"/>
    <mesh name="Ankle_Parallel_In_Left" file="Ankle_Parallel_In_Left.stl" scale="0.01 0.01 0.01"/>
    <mesh name="Ankle_Flange_Out_Right" file="Ankle_Flange_Out_Right.stl" scale="0.01 0.01 0.01"/>
    <mesh name="Ankle_Flange_In_Right" file="Ankle_Flange_In_Right.stl" scale="0.01 0.01 0.01"/>
    <mesh name="Ankle_Parallel_Out_Right" file="Ankle_Parallel_Out_Right.stl" scale="0.01 0.01 0.01"/>
    <mesh name="Ankle_Parallel_In_Right" file="Ankle_Parallel_In_Right.stl" scale="0.01 0.01 0.01"/>
    <mesh name="Wrist_Flange_Front_Left" file="Wrist_Flange_Front_Left.stl" scale="0.01 0.01 0.01"/>
    <mesh name="Wrist_Flange_Back_Left" file="Wrist_Flange_Back_Left.stl" scale="0.01 0.01 0.01"/>
    <mesh name="Wrist_Parallel_Front_Left" file="Wrist_Parallel_Front_Left.stl" scale="0.01 0.01 0.01"/>
    <mesh name="Wrist_Parallel_Back_Left" file="Wrist_Parallel_Back_Left.stl" scale="0.01 0.01 0.01"/>
    <mesh name="Wrist_Universal_Front_Left" file="Wrist_Universal_Front_Left.stl" scale="0.01 0.01 0.01"/>
    <mesh name="Wrist_Universal_Back_Left" file="Wrist_Universal_Back_Left.stl" scale="0.01 0.01 0.01"/>
    <mesh name="Wrist_Flange_Front_Right" file="Wrist_Flange_Front_Right.stl" scale="0.01 0.01 0.01"/>
    <mesh name="Wrist_Flange_Back_Right" file="Wrist_Flange_Back_Right.stl" scale="0.01 0.01 0.01"/>
    <mesh name="Wrist_Parallel_Front_Right" file="Wrist_Parallel_Front_Right.stl" scale="0.01 0.01 0.01"/>
    <mesh name="Wrist_Parallel_Back_Right" file="Wrist_Parallel_Back_Right.stl" scale="0.01 0.01 0.01"/>
    <mesh name="Wrist_Universal_Front_Right" file="Wrist_Universal_Front_Right.stl" scale="0.01 0.01 0.01"/>
    <mesh name="Wrist_Universal_Back_Right" file="Wrist_Universal_Back_Right.stl" scale="0.01 0.01 0.01"/>
    <mesh name="Wrist_Motor_Output_Front_Left" file="Wrist_Motor_Output_Front_Left.stl" scale="0.01 0.01 0.01"/>
    <mesh name="Wrist_Coupler_Front_Left" file="Wrist_Coupler_Front_Left.stl" scale="0.01 0.01 0.01"/>
    <mesh name="Wrist_Motor_Output_Back_Left" file="Wrist_Motor_Output_Back_Left.stl" scale="0.01 0.01 0.01"/>
    <mesh name="Wrist_Coupler_Back_Left" file="Wrist_Coupler_Back_Left.stl" scale="0.01 0.01 0.01"/>
    <mesh name="Wrist_Motor_Output_Front_Right" file="Wrist_Motor_Output_Front_Right.stl" scale="0.01 0.01 0.01"/>
    <mesh name="Wrist_Coupler_Front_Right" file="Wrist_Coupler_Front_Right.stl" scale="0.01 0.01 0.01"/>
    <mesh name="Wrist_Motor_Output_Back_Right" file="Wrist_Motor_Output_Back_Right.stl" scale="0.01 0.01 0.01"/>
    <mesh name="Wrist_Coupler_Back_Right" file="Wrist_Coupler_Back_Right.stl" scale="0.01 0.01 0.01"/>
    <texture type="skybox" builtin="gradient" width="128" height="128" rgb1="1.0 1.0 1.0" rgb2="0.4 0.4 0.4"/>
    <texture name="grid" type="2d" builtin="checker" width="512" height="512" rgb1="0.9 0.9 0.9" rgb2=".85 .85 .85"/>
    <material name="grid" texture="grid" texrepeat="1 1" texuniform="true" reflectance=".2"/>
  </asset>
  <worldbody>
    <!-- <geom name="floor" size="10 10 .05" type="plane" material="grid" condim="3" solref="0.01 1"/> -->
    <geom name="floor" size="10 10 .05" type="plane" material="grid" condim="3" euler="0 0. 0"/>
    <light directional="true" diffuse=".8 .8 .8" pos="0 0 10" dir="0.5 0.5 -5"/>
    <light directional="true" diffuse=".3 .3 .3" pos="10 0 0" dir="-10 0 0"/>
    <body name="base_link" pos="0.0 0.0 1.5" quat="1 0 0 0" childclass="robot">
      <site name="pelvis_link_site" pos="0.0615 0 0.187" quat="1 0 0 0" size="0.01"/>
      <freejoint name="floating_base"/>
      <inertial pos="-0.0356 0.0 -0.09163" mass="8.124" fullinertia="0.04342 0.05156 0.04212 0.00001 0.00325 0.00000"/>
      <geom name="base_link_collision" pos="0 0 0" quat="1 0 0 0" type="mesh" mesh="Upper_Body" class="collision"/>
      <geom name="base_link_visual" pos="0 0 0" quat="1 0 0 0" material="random" type="mesh" mesh="Upper_Body" class="visual"/>
      <body name="Link_Hip_Pitch_Left" pos="0 0.0897 0" quat="1.0 0.0 0.0 0.0">
        <joint name="Joint_Hip_Pitch_Left" type="hinge" ref="0.0" class="actuator_150" range="-2.042035225 0.523598776" axis="0 1 0"/>
        <inertial pos="0.00973 -0.00102 0.00002" quat="1.0 0.0 0.0 0.0" mass="1.894" diaginertia="0.00261 0.00267 0.00258"/>
        <!-- <geom name="Link_Hip_Pitch_Left_collision" pos="0 0 0" quat="1 0 0 0" type="mesh" mesh="Hip_Pitch_Left" class="collision" /> -->
        <geom name="Link_Hip_Pitch_Left_visual" pos="0 0 0" quat="1 0 0 0" material="random" type="mesh" mesh="Hip_Pitch_Left" class="visual"/>
        <body name="Link_Hip_Roll_Left" pos="0 0 0" quat="1.0 0.0 0.0 0.0">
          <joint name="Joint_Hip_Roll_Left" type="hinge" ref="0.0" class="actuator_120" range="-0.331612558 2.35619449" axis="1 0 0"/>
          <inertial pos="-0.01497 0.00570 -0.03564" quat="1.0 0.0 0.0 0.0" mass="0.573" diaginertia="0.00103 0.00226 0.00206"/>
          <!-- <geom name="Link_Hip_Roll_Left_collision" pos="0 0 0" quat="1 0 0 0" type="mesh" mesh="Hip_Roll_Left" class="collision" /> -->
          <!-- <geom name="Link_Hip_Roll_Left_collision" pos="-0.0 0.0 -0.00" quat="0.707 0 0.707 0" size="0.06 0.025" type="capsule" class="collision"/> -->
          <geom name="Link_Hip_Roll_Left_visual" pos="0 0 0" quat="1 0 0 0" material="random" type="mesh" mesh="Hip_Roll_Left" class="visual"/>
          <joint name="Joint_Hip_Yaw_Left" type="hinge" ref="0.0" class="actuator_60" range="-1.570796327 1.570796327" axis="0 0 1"/>
          <body name="Link_Hip_Yaw_Left" pos="0.002 0 -0.076" quat="1.0 0.0 0.0 0.0">
            <inertial pos="-0.01286 -0.00388 -0.10563" quat="1.0 0.0 0.0 0.0" mass="4.813" diaginertia="0.03161 0.03396 0.01135"/>
            <geom name="Link_Hip_Yaw_Left_collision" pos="0 0 0" quat="1 0 0 0" type="mesh" mesh="Hip_Yaw_Left_collision" class="collision"/>
            <!-- <geom name="Link_Hip_Yaw_Left_collision" pos="-0.02 0 -0.12" quat="1 0 0 0" size="0.08 0.07 0.12" type="box" class="collision" /> -->
            <geom name="Link_Hip_Yaw_Left_visual" pos="0 0 0" quat="1 0 0 0" material="random" type="mesh" mesh="Hip_Yaw_Left" class="visual"/>
            <body name="Link_Knee_Pitch_Left" pos="-0.055 0 -0.263" quat="1.0 0.0 0.0 0.0">
              <joint name="Joint_Knee_Pitch_Left" type="hinge" ref="0.0" class="actuator_150" range="0 2.28638132" axis="0 1 0"/>
              <inertial pos="0.01044 0.00096 -0.12320" quat="1.0 0.0 0.0 0.0" mass="3.212" diaginertia="0.02686 0.02845 0.0052"/>
              <geom name="Link_Knee_Pitch_Left_collision" pos="0 0 0" quat="1 0 0 0" type="mesh" mesh="Knee_Pitch_Left" class="collision"/>
              <geom name="Link_Knee_Pitch_Left_visual" pos="0 0 0" quat="1 0 0 0" material="random" type="mesh" mesh="Knee_Pitch_Left" class="visual"/>
              <body name="Link_Ankle_Pitch_Left" pos="0.005 0 -0.34" quat="1.0 0.0 0.0 0.0">
                <joint name="Joint_Ankle_Pitch_Left" type="hinge" ref="0.0" class="passive" range="-0.698131701 0.698131701" limited="true" axis="0 1 0"/>
                <inertial pos="0.00000 0.00000 0.00000" quat="1.0 0.0 0.0 0.0" mass="0.084" diaginertia="3e-05 2e-05 3e-05"/>
                <!-- <geom name="Link_Ankle_Pitch_Left_collision" pos="0 0 0" quat="1 0 0 0" type="mesh" mesh="Ankle_Pitch_Left" class="collision" /> -->
                <geom name="Link_Ankle_Pitch_Left_visual" pos="0 0 0" quat="1 0 0 0" material="random" type="mesh" mesh="Ankle_Pitch_Left" class="visual"/>
                <body name="Link_Ankle_Roll_Left" pos="0 0 0" quat="1.0 0.0 0.0 0.0">
                  <joint name="Joint_Ankle_Roll_Left" type="hinge" ref="0.0" class="passive" range="-0.34906585 0.34906585" limited="true" axis="1 0 0"/>
                  <inertial pos="0.02167 0.00000 -0.05193" quat="1.0 0.0 0.0 0.0" mass="0.459" diaginertia="0.00045 0.00166 0.00158"/>
                  <geom name="foot_box_left" pos="0.048 0 -0.0685" quat="1 0 0 0" type="box" size="0.1 0.035 0.0025" class="collision" rgba="0.1 0.1 0.1 1"/>
                  <geom name="Link_Ankle_Roll_Left_visual" pos="0.048 0 -0.0685" quat="1 0 0 0" type="box" size="0.1 0.035 0.0025" class="visual"/>
                </body>
              </body>
              <body name="Link_Ankle_Flange_Out_Left" pos="0.00500 0.03775 -0.08000" quat="1.0 0.0 0.0 0.0">
                <joint name="Joint_Ankle_Flange_Out_Left" type="hinge" ref="0.0" class="actuator_90" range="-0.63006386 0.609119909" limited="true" axis="0 1 0"/>
                <inertial pos="-0.01128 -0.00742 -0.00003" quat="1.0 0.0 0.0 0.0" mass="0.026" diaginertia="0.00001 0.00002 0.00001"/>
                <geom name="Link_Ankle_Flange_Out_Left_visual" pos="0 0 0" quat="1 0 0 0" material="random" type="mesh" mesh="Ankle_Flange_Out_Left" class="visual"/>
                <body name="Link_Ankle_Parallel_Out_Left" pos="-0.03750 0.00000 -0.00011" quat="1.0 0.0 0.0 0.0">
                  <joint name="Joint_Ankle_Parallel_Out_Left" type="ball" ref="0.0" class="passive"/>
                  <inertial pos="0.00183 -0.00357 -0.13606" quat="1.0 0.0 0.0 0.0" mass="0.130" diaginertia="0.00092 0.00092 0.000001"/>
                  <geom name="Link_Ankle_Parallel_Out_Left_visual" pos="0 0 0" quat="1 0 0 0" material="random" type="mesh" mesh="Ankle_Parallel_Out_Left" class="visual"/>
                </body>
              </body>
              <body name="Link_Ankle_Flange_In_Left" pos="0.00500 -0.03775 -0.18800" quat="1.0 0.0 0.0 0.0">
                <joint name="Joint_Ankle_Flange_In_Left" type="hinge" ref="0.0" class="actuator_90" range="-0.617846555 0.523598776" limited="true" axis="0 1 0"/>
                <inertial pos="-0.01128 0.00742 -0.00006" quat="1.0 0.0 0.0 0.0" mass="0.026" diaginertia="0.00001 0.00002 0.00001"/>
                <geom name="Link_Ankle_Flange_In_Left_visual" pos="0 0 0" quat="1 0 0 0" material="random" type="mesh" mesh="Ankle_Flange_In_Left" class="visual"/>
                <body name="Link_Ankle_Parallel_In_Left" pos="-0.03750 0.00000 -0.00019" quat="1.0 0.0 0.0 0.0">
                  <joint name="Joint_Ankle_Parallel_In_Left" type="ball" ref="0.0" class="passive"/>
                  <inertial pos="0.00187 0.00365 -0.08089" quat="1.0 0.0 0.0 0.0" mass="0.083" diaginertia="0.00022 0.00022 0.000001"/>
                  <geom name="Link_Ankle_Parallel_In_Left_visual" pos="0 0 0" quat="1 0 0 0" material="random" type="mesh" mesh="Ankle_Parallel_In_Left" class="visual"/>
                </body>
              </body>
            </body>
          </body>
        </body>
      </body>
      <body name="Link_Hip_Pitch_Right" pos="0 -0.0897 0" quat="1.0 0.0 0.0 0.0">
        <joint name="Joint_Hip_Pitch_Right" type="hinge" ref="0.0" class="actuator_150" range="-2.059488517 0.523598776" axis="0 1 0"/>
        <inertial pos="0.00973 0.00102 -0.00002" quat="1.0 0.0 0.0 0.0" mass="1.894" diaginertia="0.00261 0.00267 0.00258"/>
        <!-- <geom name="Link_Hip_Pitch_Right_collision" pos="0 0 0" quat="1 0 0 0" type="mesh" mesh="Hip_Pitch_Right" class="collision" /> -->
        <geom name="Link_Hip_Pitch_Right_visual" pos="0 0 0" quat="1 0 0 0" material="random" type="mesh" mesh="Hip_Pitch_Right" class="visual"/>
        <body name="Link_Hip_Roll_Right" pos="0 0 0" quat="1.0 0.0 0.0 0.0">
          <joint name="Joint_Hip_Roll_Right" type="hinge" ref="0.0" class="actuator_120" range="-2.35619449 0.331612558" axis="1 0 0"/>
          <inertial pos="-0.01497 -0.00570 -0.03564" quat="1.0 0.0 0.0 0.0" mass="0.573" diaginertia="0.00103 0.00226 0.00206"/>
          <!-- <geom name="Link_Hip_Roll_Right_collision" pos="0 0 0" quat="1 0 0 0" type="mesh" mesh="Hip_Roll_Right" class="collision" /> -->
          <!-- <geom name="Link_Hip_Roll_Right_collision" pos="-0.0 0.0 -0.00" quat="0.707 0 0.707 0" size="0.06 0.025" type="capsule" class="collision"/> -->
          <geom name="Link_Hip_Roll_Right_visual" pos="0 0 0" quat="1 0 0 0" material="random" type="mesh" mesh="Hip_Roll_Right" class="visual"/>
          <body name="Link_Hip_Yaw_Right" pos="0.002 0 -0.076" quat="1.0 0.0 0.0 0.0">
            <joint name="Joint_Hip_Yaw_Right" type="hinge" ref="0.0" class="actuator_60" range="-1.570796327 1.570796327" axis="0 0 1"/>
            <inertial pos="-0.01286 0.00388 -0.10564" quat="1.0 0.0 0.0 0.0" mass="4.813" diaginertia="0.03161 0.03398 0.01137"/>
            <geom name="Link_Hip_Yaw_Right_collision" pos="0 0 0" quat="1 0 0 0" type="mesh" mesh="Hip_Yaw_Right_collision" class="collision"/>
            <!-- <geom name="Link_Hip_Yaw_Right_collision" pos="-0.02 0 -0.12" quat="1 0 0 0" size="0.08 0.07 0.12" type="box" class="collision"  rgba="1.0 0.28 0.1 0.9"/> -->
            <geom name="Link_Hip_Yaw_Right_visual" pos="0 0 0" quat="1 0 0 0" material="random" type="mesh" mesh="Hip_Yaw_Right" class="visual"/>
            <body name="Link_Knee_Pitch_Right" pos="-0.055 0 -0.263" quat="1.0 0.0 0.0 0.0">
              <joint name="Joint_Knee_Pitch_Right" type="hinge" ref="0.0" class="actuator_150" range="0 2.28638132" axis="0 1 0"/>
              <inertial pos="0.01044 -0.00096 -0.12320" quat="1.0 0.0 0.0 0.0" mass="3.212" diaginertia="0.02686 0.02845 0.0052"/>
              <geom name="Link_Knee_Pitch_Right_collision" pos="0 0 0" quat="1 0 0 0" type="mesh" mesh="Knee_Pitch_Right" class="collision"/>
              <geom name="Link_Knee_Pitch_Right_visual" pos="0 0 0" quat="1 0 0 0" material="random" type="mesh" mesh="Knee_Pitch_Right" class="visual"/>
              <body name="Link_Ankle_Pitch_Right" pos="0.005 0 -0.34" quat="1.0 0.0 0.0 0.0">
                <joint name="Joint_Ankle_Pitch_Right" type="hinge" ref="0.0" class="passive" range="-0.698131701 0.698131701" limited="true" axis="0 1 0"/>
                <inertial pos="0 0 0" quat="1.0 0.0 0.0 0.0" mass="0.084" diaginertia="3e-05 2e-05 3e-05"/>
                <!-- <geom name="Link_Ankle_Pitch_Right_collision" pos="0 0 0" quat="1 0 0 0" type="mesh" mesh="Ankle_Pitch_Right" class="collision" /> -->
                <geom name="Link_Ankle_Pitch_Right_visual" pos="0 0 0" quat="1 0 0 0" material="random" type="mesh" mesh="Ankle_Pitch_Right" class="visual"/>
                <body name="Link_Ankle_Roll_Right" pos="0 0 0" quat="1.0 0.0 0.0 0.0">
                  <joint name="Joint_Ankle_Roll_Right" type="hinge" ref="0.0" class="passive" range="-0.34906585 0.34906585" limited="true" axis="1 0 0"/>
                  <inertial pos="0.02167 0.00000 -0.05193" quat="1.0 0.0 0.0 0.0" mass="0.459" diaginertia="0.00045 0.00166 0.00158"/>
                  <geom name="foot_box_right" pos="0.048 0 -0.0685" quat="1 0 0 0" type="box" size="0.1 0.035 0.0025" class="collision" rgba="0.1 0.1 0.1 1"/>
                  <geom name="Link_Ankle_Roll_Right_visual" pos="0.048 0 -0.0685" quat="1 0 0 0" type="box" size="0.1 0.035 0.0025" class="visual"/>
                </body>
              </body>
              <body name="Link_Ankle_Flange_Out_Right" pos="0.00500 -0.03775 -0.08000" quat="1.0 0.0 0.0 0.0">
                <joint name="Joint_Ankle_Flange_Out_Right" type="hinge" ref="0.0" class="actuator_90" range="-0.63006386 0.609119909" limited="true" axis="0 1 0"/>
                <inertial pos="-0.01128 -0.00742 -0.00003" quat="1.0 0.0 0.0 0.0" mass="0.026" diaginertia="0.00001 0.00002 0.00001"/>
                <geom name="Link_Ankle_Flange_Out_Right_visual" pos="0 0 0" quat="1 0 0 0" material="random" type="mesh" mesh="Ankle_Flange_Out_Right" class="visual"/>
                <body name="Link_Ankle_Parallel_Out_Right" pos="-0.03750 0.00000 -0.00011" quat="1.0 0.0 0.0 0.0">
                  <joint name="Joint_Ankle_Parallel_Out_Right" type="ball" ref="0.0" class="passive"/>
                  <inertial pos="0.00183 -0.00357 -0.13606" quat="1.0 0.0 0.0 0.0" mass="0.130" diaginertia="0.00092 0.00092 0.000001"/>
                  <geom name="Link_Ankle_Parallel_Out_Right_visual" pos="0 0 0" quat="1 0 0 0" material="random" type="mesh" mesh="Ankle_Parallel_Out_Right" class="visual"/>
                </body>
              </body>
              <body name="Link_Ankle_Flange_In_Right" pos="0.00500 0.03775 -0.18800" quat="1.0 0.0 0.0 0.0">
                <joint name="Joint_Ankle_Flange_In_Right" type="hinge" ref="0.0" class="actuator_90" range="-0.617846555 0.523598776" limited="true" axis="0 1 0"/>
                <inertial pos="-0.01128 0.00742 -0.00006" quat="1.0 0.0 0.0 0.0" mass="0.026" diaginertia="0.00001 0.00002 0.00001"/>
                <geom name="Link_Ankle_Flange_In_Right_visual" pos="0 0 0" quat="1 0 0 0" material="random" type="mesh" mesh="Ankle_Flange_In_Right" class="visual"/>
                <body name="Link_Ankle_Parallel_In_Right" pos="-0.03750 0.00000 -0.00019" quat="1.0 0.0 0.0 0.0">
                  <joint name="Joint_Ankle_Parallel_In_Right" type="ball" ref="0.0" class="passive"/>
                  <inertial pos="0.00144 -0.00267 -0.06221" quat="1.0 0.0 0.0 0.0" mass="0.046" diaginertia="0.00001 0.00002 0.00001"/>
                  <geom name="Link_Ankle_Parallel_In_Right_visual" pos="0 0 0" quat="1 0 0 0" material="random" type="mesh" mesh="Ankle_Parallel_In_Right" class="visual"/>
                </body>
              </body>
            </body>
          </body>
        </body>
      </body>
      <body name="Link_Waist_Flange_Left" pos="0.01150 0.09050 0.14000" quat="1.0 0.0 0.0 0.0">
        <joint name="Joint_Waist_Flange_Left" type="hinge" ref="0.0" class="actuator_60" range="-1.570796327 1.570796327" limited="true" axis="0 1 0"/>
        <inertial pos="-0.00320 -0.00883 0.13833" quat="1.0 0.0 0.0 0.0" mass="0.043" diaginertia="0.00001 0.00004 0.00003"/>
        <geom name="Link_Waist_Flange_Left_visual" pos="0 0 0" quat="1 0 0 0" material="random" type="mesh" mesh="Waist_Flange_Left" class="visual"/>
        <body name="Link_Waist_Parallel_Left" pos="-0.05167 0.00000 -0.00587" quat="1.0 0.0 0.0 0.0">
          <joint name="Joint_Waist_Parallel_Left" type="ball" ref="0.0" class="passive"/>
          <inertial pos="0.00083 0.00172 0.02995" quat="1.0 0.0 0.0 0.0" mass="0.030" diaginertia="0.00002 0.00002 0.000001"/>
          <geom name="Link_Waist_Parallel_Left_visual" pos="0 0 0" quat="1 0 0 0" material="random" type="mesh" mesh="Waist_Parallel_Left" class="visual"/>
        </body>
      </body>
      <body name="Link_Waist_Flange_Right" pos="0.01150 -0.09050 0.14000" quat="1.0 0.0 0.0 0.0">
        <joint name="Joint_Waist_Flange_Right" type="hinge" ref="0.0" class="actuator_60" range="-1.570796327 1.570796327" limited="true" axis="0 1 0"/>
        <inertial pos="-0.00320 0.00883 0.13833" quat="1.0 0.0 0.0 0.0" mass="0.043" diaginertia="0.00001 0.00004 0.00003"/>
        <geom name="Link_Waist_Flange_Right_visual" pos="0 0 0" quat="1 0 0 0" material="random" type="mesh" mesh="Waist_Flange_Right" class="visual"/>
        <body name="Link_Waist_Parallel_Right" pos="-0.05167 0.00000 -0.00587" quat="1.0 0.0 0.0 0.0">
          <joint name="Joint_Waist_Parallel_Right" type="ball" ref="0.0" class="passive"/>
          <inertial pos="0.00083 -0.00172 0.02995" quat="1.0 0.0 0.0 0.0" mass="0.030" diaginertia="0.00002 0.00002 0.000001"/>
          <geom name="Link_Waist_Parallel_Right_visual" pos="0 0 0" quat="1 0 0 0" material="random" type="mesh" mesh="Waist_Parallel_Right" class="visual"/>
        </body>
      </body>
      <body name="Link_Waist_Pitch" pos="0.0115 0 0.14" quat="1.0 0.0 0.0 0.0">
        <joint name="Joint_Waist_Pitch" type="hinge" ref="0.0" class="passive" range="-0.872664626 0.287979327" limited="true" axis="0 -1 0"/>
        <inertial pos="0.00000 0.00000 0.03171" quat="1.0 0.0 0.0 0.0" mass="0.136" diaginertia="0.00005 0.00011 0.00007"/>
        <geom name="Link_Waist_Pitch_collision" pos="0 0 0" quat="1 0 0 0" type="mesh" mesh="Waist_Pitch" class="collision"/>
        <geom name="Link_Waist_Pitch_visual" pos="0 0 0" quat="1 0 0 0" material="random" type="mesh" mesh="Waist_Pitch" class="visual" rgba="0.9 0.9 0.9 0.3"/>
        <body name="Link_Waist_Roll" pos="0 0 0.04" quat="1.0 0.0 0.0 0.0">
          <joint name="Joint_Waist_Roll" type="hinge" ref="0.0" class="passive" range="-0.314159265 0.314159265" limited="true" axis="-1 0 0"/>
          <inertial pos="-0.02403 0.00000 0.01673" quat="1.0 0.0 0.0 0.0" mass="0.208" diaginertia="0.00031 0.00031 0.00058"/>
          <geom name="Link_Waist_Roll_visual" pos="0 0 0" quat="1 0 0 0" material="random" type="mesh" mesh="Waist_Roll" class="visual"/>
          <body name="Link_Waist_Yaw" pos="-0.05 0 0.026" quat="1.0 0.0 0.0 0.0">
            <joint name="Joint_Waist_Yaw" type="hinge" ref="0.0" class="actuator_60" range="-1.570796327 1.570796327" axis="0 0 -1"/>
            <site name="base_link_imu_site" pos="0.050 0 0.047" quat="0.7071068 0.0 0.7071068 0.0" size="0.01"/>
            <inertial pos="0.00175 0.00112 0.15154" mass="12.974" fullinertia="0.15110 0.12880 0.08070 -0.00136 0.00843 -0.00089"/>
            <geom name="Link_Waist_Yaw_collision" pos="0 0 0" quat="1 0 0 0" type="mesh" mesh="Waist_Yaw" class="collision"/>
            <geom name="Link_Waist_Yaw_visual" pos="0 0 0" quat="1 0 0 0" material="random" type="mesh" mesh="Waist_Yaw" class="visual"/>
            <body name="Link_Shoulder_Pitch_Left" pos="0 0.171 0.266" quat="1.0 0.0 0.0 0.0">
              <joint name="Joint_Shoulder_Pitch_Left" type="hinge" ref="0.0" class="actuator_60" range="-3.141592654 1.047197551" axis="0 1 0"/>
              <inertial pos="0.00039 -0.00330 0.00004" quat="1.0 0.0 0.0 0.0" mass="1.105" diaginertia="0.00118 0.00097 0.00107"/>
              <!-- <geom name="Link_Shoulder_Pitch_Left_collision" pos="0 0 0" quat="1 0 0 0" type="mesh" mesh="Shoulder_Pitch_Left" class="collision" /> -->
              <geom name="Link_Shoulder_Pitch_Left_visual" pos="0 0 0" quat="1 0 0 0" material="random" type="mesh" mesh="Shoulder_Pitch_Left" class="visual"/>
              <body name="Link_Shoulder_Roll_Left" pos="0 0 0" quat="1.0 0.0 0.0 0.0">
                <joint name="Joint_Shoulder_Roll_Left" type="hinge" ref="0.0" class="actuator_60" range="-0.174532925 3.141592654" axis="1 0 0"/>
                <inertial pos="0.02322 0.00000 -0.03100" quat="1.0 0.0 0.0 0.0" mass="0.253" diaginertia="0.00046 0.00046 0.00034"/>
                <!-- <geom name="Link_Shoulder_Roll_Left_collision" pos="0 0 0" quat="1 0 0 0" type="mesh" mesh="Shoulder_Roll_Left" class="collision" /> -->
                <geom name="Link_Shoulder_Roll_Left_visual" pos="0 0 0" quat="1 0 0 0" material="random" type="mesh" mesh="Shoulder_Roll_Left" class="visual"/>
                <body name="Link_Shoulder_Yaw_Left" pos="0 0 0" quat="1.0 0.0 0.0 0.0">
                  <joint name="Joint_Shoulder_Yaw_Left" type="hinge" ref="0.0" class="actuator_60" range="-1.570796327 1.570796327" axis="0 0 1"/>
                  <inertial pos="0.00289 0.00039 -0.14632" quat="1.0 0.0 0.0 0.0" mass="2.144" diaginertia="0.00708 0.00723 0.00213"/>
                  <!-- <geom name="Link_Shoulder_Yaw_Left_collision" pos="0 0 0" quat="1 0 0 0" type="mesh" mesh="Shoulder_Yaw_Left" class="collision" /> -->
                  <geom name="Link_Shoulder_Yaw_Left_visual" pos="0 0 0" quat="1 0 0 0" material="random" type="mesh" mesh="Shoulder_Yaw_Left" class="visual"/>
                  <body name="Link_Elbow_Pitch_Left" pos="0.01 0 -0.197" quat="1.0 0.0 0.0 0.0">
                    <joint name="Joint_Elbow_Pitch_Left" type="hinge" ref="0.0" class="actuator_60" range="-2.094395102 0" axis="0 1 0"/>
                    <inertial pos="-0.00506 0.02516 -0.02257" quat="1.0 0.0 0.0 0.0" mass="0.137" diaginertia="0.00017 0.00017 0.00013"/>
                    <!-- <geom name="Link_Elbow_Pitch_Left_collision" pos="0 0 0" quat="1 0 0 0" type="mesh" mesh="Elbow_Pitch_Left" class="collision" /> -->
                    <geom name="Link_Elbow_Pitch_Left_visual" pos="0 0 0" quat="1 0 0 0" material="random" type="mesh" mesh="Elbow_Pitch_Left" class="visual"/>
                    <body name="Link_Wrist_Yaw_Left" pos="-0.01 0 -0.05" quat="1.0 0.0 0.0 0.0">
                      <joint name="Joint_Wrist_Yaw_Left" type="hinge" ref="0.0" class="actuator_8" range="-1.570796327 1.570796327" axis="0 0 1"/>
                      <inertial pos="-0.00019 0.00001 -0.08347" quat="1.0 0.0 0.0 0.0" mass="2.299" diaginertia="0.00819 0.00912 0.00302"/>
                      <geom name="Link_Wrist_Yaw_Left_collision" pos="0 0 0" quat="1 0 0 0" type="mesh" mesh="Wrist_Yaw_Left" class="collision"/>
                      <geom name="Link_Wrist_Yaw_Left_visual" pos="0 0 0" quat="1 0 0 0" material="random" type="mesh" mesh="Wrist_Yaw_Left" class="visual" rgba="0.9 0.9 0.9 0.3"/>
                      <body name="Link_Wrist_Motor_Output_Front_Left" pos="0.004 0 -0.08450" quat="1.0 0.0 0.0 0.0">
                        <joint name="Joint_Wrist_Motor_Output_Front_Left" type="hinge" ref="0.0" class="actuator_8" range="-0.98 0.75" limited="true" axis="1 0 0"/>
                        <inertial pos="-0.00357 0.01879 0.00461" quat="1.0 0.0 0.0 0.0" mass="0.009" diaginertia="0.00001 0.00001 0.00001"/>
                        <geom name="Link_Wrist_Motor_Output_Front_Left" pos="0 0 0" quat="1 0 0 0" material="random" type="mesh" mesh="Wrist_Motor_Output_Front_Left" class="visual"/>
                        <!-- <geom name="Link_Wrist_Motor_Output_Front_Left" pos="0 0.015 0" quat="1 0 0 0" material="random" type="box" size="0.001 0.015 0.005" class="visual" rgba="0 0 1 1"/> -->
                        <body name="Link_Wrist_Coupler_Front_Left" pos="0.0 0.029961 -0.001522" quat="1.0 0.0 0.0 0.0">
                          <joint name="Joint_Wrist_Coupler_Front_Left" type="hinge" ref="0.0" class="passive" range="-1.57 1.57" axis="1 0 0"/>
                          <inertial pos="-0.00357 0.01879 0.00461" quat="1.0 0.0 0.0 0.0" mass="0.009" diaginertia="0.00001 0.00001 0.00001"/>
                          <geom name="Link_Wrist_Coupler_Front_Left_visual" pos="0 0 0" quat="1 0 0 0" material="random" type="mesh" mesh="Wrist_Coupler_Front_Left" class="visual"/>
                          <!-- <geom name="Link_Wrist_Coupler_Front_Left_visual" pos="0 0 -0.062" quat="1 0 0 0" material="random" type="cylinder" size="0.003 0.062" class="visual" rgba="0 0 1 1"/> -->
                        </body>
                      </body>
                      <body name="Link_Wrist_Motor_Output_Back_Left" pos="-0.004 0 -0.08450" quat="1.0 0.0 0.0 0.0">
                        <joint name="Joint_Wrist_Motor_Output_Back_Left" type="hinge" ref="0.0" class="actuator_8" range="-0.98 0.75" limited="true" axis="1 0 0"/>
                        <inertial pos="0.00357 0.01879 0.00461" quat="1.0 0.0 0.0 0.0" mass="0.009" diaginertia="0.00001 0.00001 0.00001"/>
                        <geom name="Link_Wrist_Motor_Output_Back_Left_visual" pos="0 0 0" quat="1 0 0 0" material="random" type="mesh" mesh="Wrist_Motor_Output_Back_Left" class="visual"/>
                        <!-- <geom name="Link_Wrist_Motor_Output_Back_Left_visual" pos="0 0.015 0" quat="1 0 0 0" material="random" type="box" size="0.001 0.015 0.005" class="visual" rgba="0 0 1 1"/> -->
                        <body name="Link_Wrist_Coupler_Back_Left" pos="0.0 0.029961 -0.001522" quat="1.0 0.0 0.0 0.0">
                          <joint name="Joint_Wrist_Coupler_Back_Left" type="hinge" ref="0.0" class="passive" range="-1.57 1.57" axis="1 0 0"/>
                          <inertial pos="0.00357 0.01879 0.00461" quat="1.0 0.0 0.0 0.0" mass="0.009" diaginertia="0.00001 0.00001 0.00001"/>
                          <geom name="Link_Wrist_Coupler_Back_Left_visual" pos="0 0 0" quat="1 0 0 0" material="random" type="mesh" mesh="Wrist_Coupler_Back_Left" class="visual"/>
                          <!-- <geom name="Link_Wrist_Coupler_Back_Left" pos="0 0 -0.062" quat="1 0 0 0" material="random" type="cylinder" size="0.003 0.062" class="visual" rgba="0 0 1 1"/> -->
                        </body>
                      </body>
                      <body name="Link_Wrist_Flange_Front_Left" pos="0.02000 -0.009341 -0.21488" quat="1.0 0.0 0.0 0.0">
                        <joint name="Joint_Wrist_Flange_Front_Left" type="hinge" ref="0.0" class="passive" range="-1.57 1.57" axis="1 0 0"/>
                        <inertial pos="-0.00357 0.01879 0.00461" quat="1.0 0.0 0.0 0.0" mass="0.009" diaginertia="0.00001 0.00001 0.00001"/>
                        <geom name="Link_Wrist_Flange_Front_Left_visual" pos="0 0 0" quat="1 0 0 0" material="random" type="mesh" mesh="Wrist_Flange_Front_Left" class="visual"/>
                      </body>
                      <body name="Link_Wrist_Flange_Back_Left" pos="-0.02000 -0.009341 -0.21488" quat="1.0 0.0 0.0 0.0">
                        <joint name="Joint_Wrist_Flange_Back_Left" type="hinge" ref="0.0" class="passive" range="-1.57 1.57" axis="1 0 0"/>
                        <inertial pos="0.00357 0.01879 0.00461" quat="1.0 0.0 0.0 0.0" mass="0.009" diaginertia="0.00001 0.00001 0.00001"/>
                        <geom name="Link_Wrist_Flange_Back_Left_visual" pos="0 0 0" quat="1 0 0 0" material="random" type="mesh" mesh="Wrist_Flange_Back_Left" class="visual"/>
                      </body>
                      <body name="Link_Wrist_Roll_Left" pos="0 -0.005 -0.2395 " quat="1.0 0.0 0.0 0.0">
                        <joint name="Joint_Wrist_Roll_Left" type="hinge" ref="0.0" class="passive" range="-1.221730476 0.872664626" limited="true" axis="1 0 0"/>
                        <inertial pos="0.00000 0.00604 0.00031" quat="1.0 0.0 0.0 0.0" mass="0.012" diaginertia="0.00001 0.00001 0.00001"/>
                        <!-- <geom name="Link_Wrist_Roll_Left_collision" pos="0 0 0" quat="1 0 0 0" type="mesh" mesh="Wrist_Roll_Left" class="collision" /> -->
                        <geom name="Link_Wrist_Roll_Left_visual" pos="0 0 0" quat="1 0 0 0" material="random" type="mesh" mesh="Wrist_Roll_Left" class="visual"/>
                        <body name="Link_Wrist_Pitch_Left" pos="0 0 0" quat="1.0 0.0 0.0 0.0">
                          <joint name="Joint_Wrist_Pitch_Left" type="hinge" ref="0.0" class="passive" range="-0.698131701 0.698131701" limited="true" axis="0 1 0"/>
                          <inertial pos="0 0.01019 -0.01687" quat="1.0 0.0 0.0 0.0" mass="0.020" diaginertia="0.00001 0.00001 0.00001"/>
                          <!-- <geom name="Link_Wrist_Pitch_Left_collision" pos="0 0 0" quat="1 0 0 0" type="mesh" mesh="Wrist_Pitch_Left" class="collision" /> -->
                          <geom name="Link_Wrist_Pitch_Left_visual" pos="0 0 0" quat="1 0 0 0" material="random" type="mesh" mesh="Wrist_Pitch_Left" class="visual"/>
                          <body name="Left_Hand" pos="0 0.0109 -0.024" quat="0 1 0 0">
                      <inertial pos="0.00910 0.00371 0.07839" quat="1.0 0.0 0.0 0.0" mass="0.333" diaginertia="0.00081 0.00117 0.00042" />
                      <geom name="Left_Hand_collision" pos="0 0 0" quat="1 0 0 0" type="mesh" mesh="Left_Hand" class="collision" />
                      <geom name="Left_Hand_visual" pos="0 0 0" quat="1 0 0 0" material="random" type="mesh" mesh="Left_Hand" class="visual" />
                      <body name="Left_Thumb_Proximal" pos="0.026 0.0132 0.0299" quat="0.999048 -0.043619 0 0">
                        <joint name="Left_0_Joint_Thumb_Proximal" class="actuator_8" axis="0 0 1" range="0 1.727875959" />
                        <inertial pos="0 0 0" mass="0.01" diaginertia="1e-5 1e-5 1e-5" />
                        <geom type="mesh" rgba="0.5 0.5 0.5 1" mesh="Thumb_Proximal_Left" />
                        <body name="Left_Thumb_Middle" pos="0.0230 0.0036 0.015" quat="0.579228 -0.405580 0.405580 -0.579228">
                          <joint name="Left_1_Joint_Thumb_Middle" class="actuator_8" axis="1 0 0" range="0 1.221730476" />
                          <inertial pos="0 0 0" mass="0.008" diaginertia="8e-6 8e-6 8e-6" />
                          <geom type="mesh" rgba="0.5 0.5 0.5 1" mesh="Thumb_Middle_Left" />
                          <body name="Left_Thumb_Distal" pos="0 -0.001 0.04" quat="1 0 0 0">
                            <joint name="Left_2_Joint_Thumb_Distal" class="actuator_8" axis="1 0 0" range="0 1.570796327" />
                            <inertial pos="0 0 0" mass="0.006" diaginertia="6e-6 6e-6 6e-6" />
                            <geom type="mesh" rgba="0.5 0.5 0.5 1" mesh="Thumb_Distal_Left" />
                          </body>
                        </body>
                      </body>
                      <body name="Left_Index_Middle" pos="0.0305 -0.002 0.101" quat="0 0 0 1">
                        <joint name="Left_3_Joint_Index_Middle" class="actuator_8" axis="1 0 0" range="0 1.570796327" />
                        <inertial pos="0 0 0" mass="0.008" diaginertia="8e-6 8e-6 8e-6" />
                        <geom type="mesh" rgba="0.5 0.5 0.5 1" mesh="Finger_Middle" />
                        <body name="Left_Index_Distal" pos="0 -0.001 0.04" quat="1 0 0 0">
                          <joint name="Left_4_Joint_Index_Distal" class="actuator_8" axis="1 0 0" range="0 1.570796327" />
                          <inertial pos="0 0 0" mass="0.006" diaginertia="6e-6 6e-6 6e-6" />
                          <geom type="mesh" rgba="0.5 0.5 0.5 1" mesh="Finger_Distal" />
                        </body>
                      </body>
                      <body name="Left_Middle_Middle" pos="0.0085 -0.002 0.101" quat="0 0 0 1">
                        <joint name="Left_5_Joint_Middle_Middle" class="actuator_8" axis="1 0 0" range="0 1.570796327" />
                        <inertial pos="0 0 0" mass="0.008" diaginertia="8e-6 8e-6 8e-6" />
                        <geom type="mesh" rgba="0.5 0.5 0.5 1" mesh="Finger_Middle" />
                        <body name="Left_Middle_Distal" pos="0 -0.001 0.04" quat="1 0 0 0">
                          <joint name="Left_6_Joint_Middle_Distal" class="actuator_8" axis="1 0 0" range="0 1.570796327" />
                          <inertial pos="0 0 0" mass="0.006" diaginertia="6e-6 6e-6 6e-6" />
                          <geom type="mesh" rgba="0.5 0.5 0.5 1" mesh="Finger_Distal" />
                        </body>
                      </body>
                      <body name="Left_Ring_Middle" pos="-0.0139 -0.0010 0.0990" quat="0.017450 -0.017450 -0.000305 0.999695">
                        <joint name="Left_7_Joint_Ring_Middle" class="actuator_8" axis="1 0 0" range="0 1.570796327" />
                        <inertial pos="0 0 0" mass="0.008" diaginertia="8e-6 8e-6 8e-6" />
                        <geom type="mesh" rgba="0.5 0.5 0.5 1" mesh="Finger_Middle" />
                        <body name="Left_Ring_Distal" pos="0 -0.001 0.04" quat="1 0 0 0">
                          <joint name="Left_8_Joint_Ring_Distal" class="actuator_8" axis="1 0 0" range="0 1.570796327" />
                          <inertial pos="0 0 0" mass="0.006" diaginertia="6e-6 6e-6 6e-6" />
                          <geom type="mesh" rgba="0.5 0.5 0.5 1" mesh="Finger_Distal" />
                        </body>
                      </body>
                      <body name="Left_Little_Middle" pos="-0.0362 0.0012 0.0942" quat="0.026168 -0.043612 -0.000228 0.998706">
                        <joint name="Left_9_Joint_Little_Middle" class="actuator_8" axis="1 0 0" range="0 1.570796327" />
                        <inertial pos="0 0 0" mass="0.008" diaginertia="8e-6 8e-6 8e-6" />
                        <geom type="mesh" rgba="0.5 0.5 0.5 1" mesh="Finger_Middle" />
                        <body name="Left_Little_Distal" pos="0 -0.001 0.04" quat="1 0 0 0">
                          <joint name="Left_10_Joint_Little_Distal" class="actuator_8" axis="1 0 0" range="0 1.570796327" />
                          <inertial pos="0 0 0" mass="0.006" diaginertia="6e-6 6e-6 6e-6" />
                          <geom type="mesh" rgba="0.5 0.5 0.5 1" mesh="Finger_Distal" />
                        </body>
                      </body>
                    </body>
                  
                          <body name="Link_Wrist_Universal_Front_Left" pos="0.01000 0.02150 -0.01000" quat="1.0 0.0 0.0 0.0">
                            <joint name="Joint_Wrist_Universal_Front_Left" type="hinge" ref="0.0" class="passive" range="-1.57 1.57" axis="0 1 0"/>
                            <inertial pos="0.00000 -0.00189 -0.00004" quat="1.0 0.0 0.0 0.0" mass="0.005" diaginertia="0.000001 0.000001 0.000001"/>
                            <geom name="Link_Wrist_Universal_Front_Left_visual" pos="0 0 0" quat="1 0 0 0" material="random" type="mesh" mesh="Wrist_Universal_Front_Left" class="visual"/>
                            <body name="Link_Wrist_Parallel_Front_Left" pos="0 0 0" quat="1.0 0.0 0.0 0.0">
                              <joint name="Joint_Wrist_Parallel_Front_Left" type="hinge" ref="0.0" class="passive" range="-1.57 1.57" axis="1 0 0"/>
                              <inertial pos="-0.00094 -0.00038 -0.01026" quat="1.0 0.0 0.0 0.0" mass="0.017" diaginertia="0.00001 0.00001 0.00001"/>
                              <geom name="Link_Wrist_Parallel_Front_Left_visual" pos="0 0 0" quat="1 0 0 0" material="random" type="mesh" mesh="Wrist_Parallel_Front_Left" class="visual"/>
                            </body>
                          </body>
                          <body name="Link_Wrist_Universal_Back_Left" pos="-0.01000 0.02150 -0.01000" quat="1.0 0.0 0.0 0.0">
                            <joint name="Joint_Wrist_Universal_Back_Left" type="hinge" ref="0.0" class="passive" range="-1.57 1.57" axis="0 1 0"/>
                            <inertial pos="0.00000 -0.00189 -0.00004" quat="1.0 0.0 0.0 0.0" mass="0.005" diaginertia="0.000001 0.000001 0.000001"/>
                            <geom name="Link_Wrist_Universal_Back_Left_visual" pos="0 0 0" quat="1 0 0 0" material="random" type="mesh" mesh="Wrist_Universal_Back_Left" class="visual"/>
                            <body name="Link_Wrist_Parallel_Back_Left" pos="0 0 0" quat="1.0 0.0 0.0 0.0">
                              <joint name="Joint_Wrist_Parallel_Back_Left" type="hinge" ref="0.0" class="passive" range="-1.57 1.57" axis="1 0 0"/>
                              <inertial pos="0.00094 -0.00038 -0.01026" quat="1.0 0.0 0.0 0.0" mass="0.017" diaginertia="0.00001 0.00001 0.00001"/>
                              <geom name="Link_Wrist_Parallel_Back_Left_visual" pos="0 0 0" quat="1 0 0 0" material="random" type="mesh" mesh="Wrist_Parallel_Back_Left" class="visual"/>
                            </body>
                          </body>
                        </body>
                      </body>
                    </body>
                  </body>
                </body>
              </body>
            </body>
            <body name="Link_Shoulder_Pitch_Right" pos="0 -0.171 0.266" quat="1.0 0.0 0.0 0.0">
              <joint name="Joint_Shoulder_Pitch_Right" type="hinge" ref="0.0" class="actuator_60" range="-3.141592654 1.047197551" axis="0 1 0"/>
              <inertial pos="0.00039 0.00330 -0.00004" quat="1.0 0.0 0.0 0.0" mass="1.105" diaginertia="0.00118 0.00097 0.00107"/>
              <!-- <geom name="Link_Shoulder_Pitch_Right_collision" pos="0 0 0" quat="1 0 0 0" type="mesh" mesh="Shoulder_Pitch_Right" class="collision" /> -->
              <geom name="Link_Shoulder_Pitch_Right_visual" pos="0 0 0" quat="1 0 0 0" material="random" type="mesh" mesh="Shoulder_Pitch_Right" class="visual"/>
              <body name="Link_Shoulder_Roll_Right" pos="0 0 0" quat="1.0 0.0 0.0 0.0">
                <joint name="Joint_Shoulder_Roll_Right" type="hinge" ref="0.0" class="actuator_60" range="-3.141592654 0.174532925" axis="1 0 0"/>
                <inertial pos="0.02322 0.00000 -0.03100" quat="1.0 0.0 0.0 0.0" mass="0.253" diaginertia="0.00046 0.00046 0.00034"/>
                <!-- <geom name="Link_Shoulder_Roll_Right_collision" pos="0 0 0" quat="1 0 0 0" type="mesh" mesh="Shoulder_Roll_Right" class="collision" /> -->
                <geom name="Link_Shoulder_Roll_Right_visual" pos="0 0 0" quat="1 0 0 0" material="random" type="mesh" mesh="Shoulder_Roll_Right" class="visual"/>
                <body name="Link_Shoulder_Yaw_Right" pos="0 0 0" quat="1.0 0.0 0.0 0.0">
                  <joint name="Joint_Shoulder_Yaw_Right" type="hinge" ref="0.0" class="actuator_60" range="-1.570796327 1.570796327" axis="0 0 1"/>
                  <inertial pos="0.00289 -0.00018 -0.14632" quat="1.0 0.0 0.0 0.0" mass="2.144" diaginertia="0.00708 0.00723 0.00213"/>
                  <!-- <geom name="Link_Shoulder_Yaw_Right_collision" pos="0 0 0" quat="1 0 0 0" type="mesh" mesh="Shoulder_Yaw_Right" class="collision" /> -->
                  <geom name="Link_Shoulder_Yaw_Right_visual" pos="0 0 0" quat="1 0 0 0" material="random" type="mesh" mesh="Shoulder_Yaw_Right" class="visual"/>
                  <body name="Link_Elbow_Pitch_Right" pos="0.01 0 -0.197" quat="1.0 0.0 0.0 0.0">
                    <joint name="Joint_Elbow_Pitch_Right" type="hinge" ref="0.0" class="actuator_60" range="-2.094395102 0" axis="0 1 0"/>
                    <inertial pos="-0.00506 -0.02516 -0.02257" quat="1.0 0.0 0.0 0.0" mass="0.137" diaginertia="0.00017 0.00017 0.00013"/>
                    <!-- <geom name="Link_Elbow_Pitch_Right_collision" pos="0 0 0" quat="1 0 0 0" type="mesh" mesh="Elbow_Pitch_Right" class="collision" /> -->
                    <geom name="Link_Elbow_Pitch_Right_visual" pos="0 0 0" quat="1 0 0 0" material="random" type="mesh" mesh="Elbow_Pitch_Right" class="visual"/>
                    <body name="Link_Wrist_Yaw_Right" pos="-0.01 0 -0.05" quat="1.0 0.0 0.0 0.0">
                      <joint name="Joint_Wrist_Yaw_Right" type="hinge" ref="0.0" class="actuator_8" range="-1.570796327 1.570796327" axis="0 0 1"/>
                      <inertial pos="-0.00077 -0.00035 -0.08347" quat="1.0 0.0 0.0 0.0" mass="2.299" diaginertia="0.00819 0.00912 0.00302"/>
                      <geom name="Link_Wrist_Yaw_Right_collision" pos="0 0 0" quat="1 0 0 0" type="mesh" mesh="Wrist_Yaw_Right" class="collision"/>
                      <geom name="Link_Wrist_Yaw_Right_visual" pos="0 0 0" quat="1 0 0 0" material="random" type="mesh" mesh="Wrist_Yaw_Right" class="visual" rgba="0.9 0.9 0.9 0.3"/>
                      <body name="Link_Wrist_Motor_Output_Front_Right" pos="0.004 0 -0.08450" quat="1.0 0.0 0.0 0.0">
                        <joint name="Joint_Wrist_Motor_Output_Front_Right" type="hinge" ref="0.0" class="actuator_8" range="-0.75 0.98" limited="true" axis="1 0 0"/>
                        <inertial pos="-0.00357 -0.01879 0.00461" quat="1.0 0.0 0.0 0.0" mass="0.009" diaginertia="0.00001 0.00001 0.00001"/>
                        <geom name="Link_Wrist_Motor_Output_Front_Right_visual" pos="0 0 0" quat="1 0 0 0" material="random" type="mesh" mesh="Wrist_Motor_Output_Front_Right" class="visual"/>
                        <!-- <geom name="Link_Wrist_Motor_Output_Front_Right_visual" pos="0 0.015 0" quat="1 0 0 0" material="random" type="box" size="0.001 0.015 0.005" class="visual" rgba="0 0 1 1"/> -->
                        <body name="Link_Wrist_Coupler_Front_Right" pos="0.0 -0.029961 -0.001522" quat="1.0 0.0 0.0 0.0">
                          <joint name="Joint_Wrist_Coupler_Front_Right" type="hinge" ref="0.0" class="passive" range="-1.57 1.57" axis="1 0 0"/>
                          <inertial pos="-0.00357 -0.01879 0.00461" quat="1.0 0.0 0.0 0.0" mass="0.009" diaginertia="0.00001 0.00001 0.00001"/>
                          <geom name="Link_Wrist_Coupler_Front_Right_visual" pos="0 0 0" quat="1 0 0 0" material="random" type="mesh" mesh="Wrist_Coupler_Front_Right" class="visual"/>
                          <!-- <geom name="Link_Wrist_Coupler_Front_Right_visual" pos="0 0 -0.062" quat="1 0 0 0" material="random" type="cylinder" size="0.003 0.062" class="visual" rgba="0 0 1 1"/> -->
                        </body>
                      </body>
                      <body name="Link_Wrist_Motor_Output_Back_Right" pos="-0.004 0 -0.08450" quat="1.0 0.0 0.0 0.0">
                        <joint name="Joint_Wrist_Motor_Output_Back_Right" type="hinge" ref="0.0" class="actuator_8" range="-0.75 0.98" limited="true" axis="1 0 0"/>
                        <inertial pos="0.00357 -0.01879 0.00461" quat="1.0 0.0 0.0 0.0" mass="0.009" diaginertia="0.00001 0.00001 0.00001"/>
                        <geom name="Link_Wrist_Motor_Output_Back_Right_visual" pos="0 0 0" quat="1 0 0 0" material="random" type="mesh" mesh="Wrist_Motor_Output_Back_Right" class="visual"/>
                        <!-- <geom name="Link_Wrist_Motor_Output_Back_Right_visual" pos="0 0.015 0" quat="1 0 0 0" material="random" type="box" size="0.001 0.015 0.005" class="visual" rgba="0 0 1 1"/> -->
                        <body name="Link_Wrist_Coupler_Back_Right" pos="0.0 -0.029961 -0.001522" quat="1.0 0.0 0.0 0.0">
                          <joint name="Joint_Wrist_Coupler_Back_Right" type="hinge" ref="0.0" class="passive" range="-1.57 1.57" axis="1 0 0"/>
                          <inertial pos="0.00357 -0.01879 0.00461" quat="1.0 0.0 0.0 0.0" mass="0.009" diaginertia="0.00001 0.00001 0.00001"/>
                          <geom name="Link_Wrist_Coupler_Back_Right_visual" pos="0 0 0" quat="1 0 0 0" material="random" type="mesh" mesh="Wrist_Coupler_Back_Right" class="visual"/>
                          <!-- <geom name="Link_Wrist_Coupler_Back_Right_visual" pos="0 0 -0.062" quat="1 0 0 0" material="random" type="cylinder" size="0.003 0.062" class="visual" rgba="0 0 1 1"/> -->
                        </body>
                      </body>
                      <body name="Link_Wrist_Flange_Front_Right" pos="0.02000 0.009341 -0.21488" quat="1.0 0.0 0.0 0.0">
                        <joint name="Joint_Wrist_Flange_Front_Right" type="hinge" ref="0.0" class="passive" range="-1.57 1.57" axis="1 0 0"/>
                        <inertial pos="-0.00357 -0.01879 0.00461" quat="1.0 0.0 0.0 0.0" mass="0.009" diaginertia="0.00001 0.00001 0.00001"/>
                        <geom name="Link_Wrist_Flange_Front_Right_visual" pos="0 0 0" quat="1 0 0 0" material="random" type="mesh" mesh="Wrist_Flange_Front_Right" class="visual"/>
                      </body>
                      <body name="Link_Wrist_Flange_Back_Right" pos="-0.02000 0.009341 -0.21488" quat="1.0 0.0 0.0 0.0">
                        <joint name="Joint_Wrist_Flange_Back_Right" type="hinge" ref="0.0" class="passive" range="-1.57 1.57" axis="1 0 0"/>
                        <inertial pos="0.00357 -0.01879 0.00461" quat="1.0 0.0 0.0 0.0" mass="0.009" diaginertia="0.00001 0.00001 0.00001"/>
                        <geom name="Link_Wrist_Flange_Back_Right_visual" pos="0 0 0" quat="1 0 0 0" material="random" type="mesh" mesh="Wrist_Flange_Back_Right" class="visual"/>
                      </body>
                      <body name="Link_Wrist_Roll_Right" pos="0 0.005 -0.2395" quat="1.0 0.0 0.0 0.0">
                        <joint name="Joint_Wrist_Roll_Right" type="hinge" ref="0.0" class="passive" range="-0.872664626 1.221730476" limited="true" axis="1 0 0"/>
                        <inertial pos="0.00000 -0.00604 0.00031" quat="1.0 0.0 0.0 0.0" mass="0.012" diaginertia="0.00001 0.00001 0.00001"/>
                        <!-- <geom name="Link_Wrist_Roll_Right_collision" pos="0 0 0" quat="1 0 0 0" type="mesh" mesh="Wrist_Roll_Right" class="collision" /> -->
                        <geom name="Link_Wrist_Roll_Right_visual" pos="0 0 0" quat="1 0 0 0" material="random" type="mesh" mesh="Wrist_Roll_Right" class="visual"/>
                        <body name="Link_Wrist_Pitch_Right" pos="0 0 0" quat="1.0 0.0 0.0 0.0">
                          <joint name="Joint_Wrist_Pitch_Right" type="hinge" ref="0.0" class="passive" range="-0.698131701 0.698131701" limited="true" axis="0 1 0"/>
                          <inertial pos="0.00000 -0.01019 -0.01687" quat="1.0 0.0 0.0 0.0" mass="0.020" diaginertia="0.00001 0.00001 0.00001"/>
                          <!-- <geom name="Link_Wrist_Pitch_Right_collision" pos="0 0 0" quat="1 0 0 0" type="mesh" mesh="Wrist_Pitch_Right" class="collision" /> -->
                          <geom name="Link_Wrist_Pitch_Right_visual" pos="0 0 0" quat="1 0 0 0" material="random" type="mesh" mesh="Wrist_Pitch_Right" class="visual"/>
                          <body name="Right_Hand" pos="0 -0.0109 -0.024" quat="0 1 0 0">
                      <inertial pos="0.00910 -0.00371 0.07839" quat="1.0 0.0 0.0 0.0" mass="0.333" diaginertia="0.00081 0.00117 0.00042" />
                      <geom name="Right_Hand_collision" pos="0 0 0" quat="1 0 0 0" type="mesh" mesh="Right_Hand" class="collision" />
                      <geom name="Right_Hand_visual" pos="0 0 0" quat="1 0 0 0" material="random" type="mesh" mesh="Right_Hand" class="visual" />
                      <body name="Right_Thumb_Proximal" pos="0.026 -0.0132 0.0299" quat="0.999048 0.043619 0 0">
                        <joint name="Right_0_Joint_Thumb_Proximal" class="actuator_8" axis="0 0 1" range="-1.727875959 0" />
                        <inertial pos="0 0 0" mass="0.01" diaginertia="1e-5 1e-5 1e-5" />
                        <geom type="mesh" rgba="0.5 0.5 0.5 1" mesh="Thumb_Proximal_Right" />
                        <body name="Right_Thumb_Middle" pos="0.0230 -0.0035 0.015" quat="0.579228 -0.405580 0.405580 -0.579228">
                          <joint name="Right_1_Joint_Thumb_Middle" class="actuator_8" axis="1 0 0" range="0 1.221730476" />
                          <inertial pos="0 0 0" mass="0.008" diaginertia="8e-6 8e-6 8e-6" />
                          <geom type="mesh" rgba="0.5 0.5 0.5 1" mesh="Thumb_Middle_Right" />
                          <body name="Right_Thumb_Distal" pos="0 -0.001 0.04" quat="1 0 0 0">
                            <joint name="Right_2_Joint_Thumb_Distal" class="actuator_8" axis="1 0 0" range="0 1.570796327" />
                            <inertial pos="0 0 0" mass="0.006" diaginertia="6e-6 6e-6 6e-6" />
                            <geom type="mesh" rgba="0.5 0.5 0.5 1" mesh="Thumb_Distal_Right" />
                          </body>
                        </body>
                      </body>
                      <body name="Right_Index_Middle" pos="0.0305 0.002 0.101" quat="1 0 0 0">
                        <joint name="Right_3_Joint_Index_Middle" class="actuator_8" axis="1 0 0" range="0 1.570796327" />
                        <inertial pos="0 0 0" mass="0.008" diaginertia="8e-6 8e-6 8e-6" />
                        <geom type="mesh" rgba="0.5 0.5 0.5 1" mesh="Finger_Middle" />
                        <body name="Right_Index_Distal" pos="0 -0.001 0.04" quat="1 0 0 0">
                          <joint name="Right_4_Joint_Index_Distal" class="actuator_8" axis="1 0 0" range="0 1.570796327" />
                          <inertial pos="0 0 0" mass="0.006" diaginertia="6e-6 6e-6 6e-6" />
                          <geom type="mesh" rgba="0.5 0.5 0.5 1" mesh="Finger_Distal" />
                        </body>
                      </body>
                      <body name="Right_Middle_Middle" pos="0.0085 0.002 0.101" quat="1 0 0 0">
                        <joint name="Right_5_Joint_Middle_Middle" class="actuator_8" axis="1 0 0" range="0 1.570796327" />
                        <inertial pos="0 0 0" mass="0.008" diaginertia="8e-6 8e-6 8e-6" />
                        <geom type="mesh" rgba="0.5 0.5 0.5 1" mesh="Finger_Middle" />
                        <body name="Right_Middle_Distal" pos="0 -0.001 0.04" quat="1 0 0 0">
                          <joint name="Right_6_Joint_Middle_Distal" class="actuator_8" axis="1 0 0" range="0 1.570796327" />
                          <inertial pos="0 0 0" mass="0.006" diaginertia="6e-6 6e-6 6e-6" />
                          <geom type="mesh" rgba="0.5 0.5 0.5 1" mesh="Finger_Distal" />
                        </body>
                      </body>
                      <body name="Right_Ring_Middle" pos="-0.0139 0.0010 0.0990" quat="0.999695 -0.000305 -0.017450 0.017450">
                        <joint name="Right_7_Joint_Ring_Middle" class="actuator_8" axis="1 0 0" range="0 1.570796327" />
                        <inertial pos="0 0 0" mass="0.008" diaginertia="8e-6 8e-6 8e-6" />
                        <geom type="mesh" rgba="0.5 0.5 0.5 1" mesh="Finger_Middle" />
                        <body name="Right_Ring_Distal" pos="0 -0.001 0.04" quat="1 0 0 0">
                          <joint name="Right_8_Joint_Ring_Distal" class="actuator_8" axis="1 0 0" range="0 1.570796327" />
                          <inertial pos="0 0 0" mass="0.006" diaginertia="6e-6 6e-6 6e-6" />
                          <geom type="mesh" rgba="0.5 0.5 0.5 1" mesh="Finger_Distal" />
                        </body>
                      </body>
                      <body name="Right_Little_Middle" pos="-0.0362 -0.0012 0.0942" quat="0.998706 -0.000228 -0.043612 0.026168">
                        <joint name="Right_9_Joint_Little_Middle" class="actuator_8" axis="1 0 0" range="0 1.570796327" />
                        <inertial pos="0 0 0" mass="0.008" diaginertia="8e-6 8e-6 8e-6" />
                        <geom type="mesh" rgba="0.5 0.5 0.5 1" mesh="Finger_Middle" />
                        <body name="Right_Little_Distal" pos="0 -0.001 0.04" quat="1 0 0 0">
                          <joint name="Right_10_Joint_Little_Distal" class="actuator_8" axis="1 0 0" range="0 1.570796327" />
                          <inertial pos="0 0 0" mass="0.006" diaginertia="6e-6 6e-6 6e-6" />
                          <geom type="mesh" rgba="0.5 0.5 0.5 1" mesh="Finger_Distal" />
                        </body>
                      </body>
                    </body>
                  
                          <body name="Link_Wrist_Universal_Front_Right" pos="0.01000 -0.02150 -0.01000" quat="1.0 0.0 0.0 0.0">
                            <joint name="Joint_Wrist_Universal_Front_Right" type="hinge" ref="0.0" class="passive" range="-1.57 1.57" axis="0 1 0"/>
                            <inertial pos="0.00000 0.00189 -0.00004" quat="1.0 0.0 0.0 0.0" mass="0.005" diaginertia="0.000001 0.000001 0.000001"/>
                            <geom name="Link_Wrist_Universal_Front_Right_visual" pos="0 0 0" quat="1 0 0 0" material="random" type="mesh" mesh="Wrist_Universal_Front_Right" class="visual"/>
                            <body name="Link_Wrist_Parallel_Front_Right" pos="0 0 0" quat="1.0 0.0 0.0 0.0">
                              <joint name="Joint_Wrist_Parallel_Front_Right" type="hinge" ref="0.0" class="passive" range="-1.57 1.57" axis="1 0 0"/>
                              <inertial pos="-0.00094 0.00038 -0.01026" quat="1.0 0.0 0.0 0.0" mass="0.017" diaginertia="0.00001 0.00001 0.00001"/>
                              <geom name="Link_Wrist_Parallel_Front_Right_visual" pos="0 0 0" quat="1 0 0 0" material="random" type="mesh" mesh="Wrist_Parallel_Front_Right" class="visual"/>
                            </body>
                          </body>
                          <body name="Link_Wrist_Universal_Back_Right" pos="-0.01000 -0.02150 -0.01000" quat="1.0 0.0 0.0 0.0">
                            <joint name="Joint_Wrist_Universal_Back_Right" type="hinge" ref="0.0" class="passive" range="-1.57 1.57" axis="0 1 0"/>
                            <inertial pos="0.00000 0.00189 -0.00004" quat="1.0 0.0 0.0 0.0" mass="0.005" diaginertia="0.000001 0.000001 0.000001"/>
                            <geom name="Link_Wrist_Universal_Back_Right_visual" pos="0 0 0" quat="1 0 0 0" material="random" type="mesh" mesh="Wrist_Universal_Back_Right" class="visual"/>
                            <body name="Link_Wrist_Parallel_Back_Right" pos="0 0 0" quat="1.0 0.0 0.0 0.0">
                              <joint name="Joint_Wrist_Parallel_Back_Right" type="hinge" ref="0.0" class="passive" range="-1.57 1.57" axis="1 0 0"/>
                              <inertial pos="0.00094 0.00038 -0.01026" quat="1.0 0.0 0.0 0.0" mass="0.017" diaginertia="0.00001 0.00001 0.00001"/>
                              <geom name="Link_Wrist_Parallel_Back_Right_visual" pos="0 0 0" quat="1 0 0 0" material="random" type="mesh" mesh="Wrist_Parallel_Back_Right" class="visual"/>
                            </body>
                          </body>
                        </body>
                      </body>
                    </body>
                  </body>
                </body>
              </body>
            </body>
            <body name="Link_Neck_Yaw" pos="0 0 0.357" quat="1.0 0.0 0.0 0.0">
              <joint name="Joint_Neck_Yaw" type="hinge" ref="0.0" class="actuator_7" range="-1.221730476 1.221730476" axis="0 0 1"/>
              <inertial pos="-0.00005 -0.00130 -0.00264" quat="1.0 0.0 0.0 0.0" mass="0.310" diaginertia="0.00017 0.0001 0.00016"/>
              <!-- <geom name="Link_Neck_Yaw_collision" pos="0 0 0" quat="1 0 0 0" type="mesh" mesh="Neck_Yaw" class="collision" /> -->
              <geom name="Link_Neck_Yaw_visual" pos="0 0 0" quat="1 0 0 0" material="random" type="mesh" mesh="Neck_Yaw" class="visual"/>
              <body name="Link_Neck_Pitch" pos="0 0 0" quat="1.0 0.0 0.0 0.0">
                <joint name="Joint_Neck_Pitch" type="hinge" ref="0.0" class="actuator_7" range="-0.523598776 0.523598776" axis="0 1 0"/>
                <inertial pos="0.02850 0.00290 0.12862" quat="1.0 0.0 0.0 0.0" mass="1.468" diaginertia="0.00574 0.00727 0.00503"/>
                <!-- <geom name="Link_Neck_Pitch_collision" pos="0 0 0" quat="1 0 0 0" type="mesh" mesh="Neck_Pitch" class="collision" /> -->
                <geom name="Link_Neck_Pitch_visual" pos="0 0 0" quat="1 0 0 0" material="random" type="mesh" mesh="Neck_Pitch" class="visual"/>
              </body>
            </body>
          </body>
        </body>
      </body>
    </body>
  </worldbody>
  <equality>
    <connect body1="Link_Waist_Parallel_Left" body2="Link_Waist_Roll" anchor="0.00167 0.0035 0.05987" solimp="0.9 1.0 0.001 0.5 2" solref="0.001 1"/>
    <connect body1="Link_Waist_Parallel_Right" body2="Link_Waist_Roll" anchor="0.00167 -0.0035 0.05987" solimp="0.9 1.0 0.001 0.5 2" solref="0.001 1"/>
    <connect body1="Link_Ankle_Parallel_Out_Left" body2="Link_Ankle_Roll_Left" anchor="0.00350 -0.00675 -0.25989" solimp="0.9 1.0 0.001 0.5 2" solref="0.001 1"/>
    <connect body1="Link_Ankle_Parallel_In_Left" body2="Link_Ankle_Roll_Left" anchor="0.00350 0.00675 -0.15181" solimp="0.9 1.0 0.001 0.5 2" solref="0.001 1"/>
    <connect body1="Link_Ankle_Parallel_Out_Right" body2="Link_Ankle_Roll_Right" anchor="0.00350 0.00675 -0.25989" solimp="0.9 1.0 0.001 0.5 2" solref="0.001 1"/>
    <connect body1="Link_Ankle_Parallel_In_Right" body2="Link_Ankle_Roll_Right" anchor="0.00350 -0.00675 -0.15181" solimp="0.9 1.0 0.001 0.5 2" solref="0.001 1"/>
    <connect body1="Link_Wrist_Flange_Front_Left" body2="Link_Wrist_Parallel_Front_Left" anchor="0.0 0.03159 0.005098" solimp="0.9 1.0 0.001 0.5 2" solref="0.001 1"/>
    <connect body1="Link_Wrist_Flange_Back_Left" body2="Link_Wrist_Parallel_Back_Left" anchor="0.0 0.03159 0.005098" solimp="0.9 1.0 0.001 0.5 2" solref="0.001 1"/>
    <connect body1="Link_Wrist_Flange_Front_Right" body2="Link_Wrist_Parallel_Front_Right" anchor="0.0 -0.03159 0.005098" solimp="0.9 1.0 0.001 0.5 2" solref="0.001 1"/>
    <connect body1="Link_Wrist_Flange_Back_Right" body2="Link_Wrist_Parallel_Back_Right" anchor="0.0 -0.03159 0.005098" solimp="0.9 1.0 0.001 0.5 2" solref="0.001 1"/>
    <connect body1="Link_Wrist_Coupler_Front_Left" body2="Link_Wrist_Flange_Front_Left" anchor="0.0 -0.007711 -0.123760" solimp="0.9 1.0 0.001 0.5 2" solref="0.001 1"/>
    <connect body1="Link_Wrist_Coupler_Back_Left" body2="Link_Wrist_Flange_Back_Left" anchor="0.0 -0.007711 -0.123760" solimp="0.9 1.0 0.001 0.5 2" solref="0.001 1"/>
    <connect body1="Link_Wrist_Coupler_Front_Right" body2="Link_Wrist_Flange_Front_Right" anchor="0.0 0.007711 -0.123760" solimp="0.9 1.0 0.001 0.5 2" solref="0.001 1"/>
    <connect body1="Link_Wrist_Coupler_Back_Right" body2="Link_Wrist_Flange_Back_Right" anchor="0.0 0.007711 -0.123760" solimp="0.9 1.0 0.001 0.5 2" solref="0.001 1"/>
  </equality>
  <!-- NOTE: DEFINE ACTUATOR MOTOR-POSITION-VELOCITY ORDER -->
  <actuator>
    <!-- TORQUE CONTROL -->
    <motor name="Joint_Waist_Yaw" joint="Joint_Waist_Yaw" class="actuator_60"/>
    <motor name="Joint_Waist_Flange_Left" joint="Joint_Waist_Flange_Left" class="actuator_60"/>
    <motor name="Joint_Waist_Flange_Right" joint="Joint_Waist_Flange_Right" class="actuator_60"/>
    <motor name="Joint_Hip_Pitch_Left" joint="Joint_Hip_Pitch_Left" class="actuator_150"/>
    <motor name="Joint_Hip_Roll_Left" joint="Joint_Hip_Roll_Left" class="actuator_120"/>
    <motor name="Joint_Hip_Yaw_Left" joint="Joint_Hip_Yaw_Left" class="actuator_60"/>
    <motor name="Joint_Knee_Pitch_Left" joint="Joint_Knee_Pitch_Left" class="actuator_150"/>
    <motor name="Joint_Ankle_Flange_Out_Left" joint="Joint_Ankle_Flange_Out_Left" class="actuator_90"/>
    <motor name="Joint_Ankle_Flange_In_Left" joint="Joint_Ankle_Flange_In_Left" class="actuator_90"/>
    <motor name="Joint_Hip_Pitch_Right" joint="Joint_Hip_Pitch_Right" class="actuator_150"/>
    <motor name="Joint_Hip_Roll_Right" joint="Joint_Hip_Roll_Right" class="actuator_120"/>
    <motor name="Joint_Hip_Yaw_Right" joint="Joint_Hip_Yaw_Right" class="actuator_60"/>
    <motor name="Joint_Knee_Pitch_Right" joint="Joint_Knee_Pitch_Right" class="actuator_150"/>
    <motor name="Joint_Ankle_Flange_Out_Right" joint="Joint_Ankle_Flange_Out_Right" class="actuator_90"/>
    <motor name="Joint_Ankle_Flange_In_Right" joint="Joint_Ankle_Flange_In_Right" class="actuator_90"/>
    <motor name="Joint_Shoulder_Pitch_Left" joint="Joint_Shoulder_Pitch_Left" class="actuator_60"/>
    <motor name="Joint_Shoulder_Roll_Left" joint="Joint_Shoulder_Roll_Left" class="actuator_60"/>
    <motor name="Joint_Shoulder_Yaw_Left" joint="Joint_Shoulder_Yaw_Left" class="actuator_60"/>
    <motor name="Joint_Elbow_Pitch_Left" joint="Joint_Elbow_Pitch_Left" class="actuator_60"/>
    <motor name="Joint_Wrist_Yaw_Left" joint="Joint_Wrist_Yaw_Left" class="actuator_8"/>
    <motor name="Joint_Wrist_Motor_Output_Front_Left" joint="Joint_Wrist_Motor_Output_Front_Left" class="actuator_8"/>
    <motor name="Joint_Wrist_Motor_Output_Back_Left" joint="Joint_Wrist_Motor_Output_Back_Left" class="actuator_8"/>
    <!-- Hand actuators are disabled until a dedicated hand controller is wired in.
    <motor name="Left_0_Joint_Thumb_Proximal" joint="Left_0_Joint_Thumb_Proximal" class="actuator_8"/>
    <motor name="Left_1_Joint_Thumb_Middle" joint="Left_1_Joint_Thumb_Middle" class="actuator_8"/>
    <motor name="Left_2_Joint_Thumb_Distal" joint="Left_2_Joint_Thumb_Distal" class="actuator_8"/>
    <motor name="Left_3_Joint_Index_Middle" joint="Left_3_Joint_Index_Middle" class="actuator_8"/>
    <motor name="Left_4_Joint_Index_Distal" joint="Left_4_Joint_Index_Distal" class="actuator_8"/>
    <motor name="Left_5_Joint_Middle_Middle" joint="Left_5_Joint_Middle_Middle" class="actuator_8"/>
    <motor name="Left_6_Joint_Middle_Distal" joint="Left_6_Joint_Middle_Distal" class="actuator_8"/>
    <motor name="Left_7_Joint_Ring_Middle" joint="Left_7_Joint_Ring_Middle" class="actuator_8"/>
    <motor name="Left_8_Joint_Ring_Distal" joint="Left_8_Joint_Ring_Distal" class="actuator_8"/>
    <motor name="Left_9_Joint_Little_Middle" joint="Left_9_Joint_Little_Middle" class="actuator_8"/>
    <motor name="Left_10_Joint_Little_Distal" joint="Left_10_Joint_Little_Distal" class="actuator_8"/>
    -->
    <motor name="Joint_Shoulder_Pitch_Right" joint="Joint_Shoulder_Pitch_Right" class="actuator_60"/>
    <motor name="Joint_Shoulder_Roll_Right" joint="Joint_Shoulder_Roll_Right" class="actuator_60"/>
    <motor name="Joint_Shoulder_Yaw_Right" joint="Joint_Shoulder_Yaw_Right" class="actuator_60"/>
    <motor name="Joint_Elbow_Pitch_Right" joint="Joint_Elbow_Pitch_Right" class="actuator_60"/>
    <motor name="Joint_Wrist_Yaw_Right" joint="Joint_Wrist_Yaw_Right" class="actuator_8"/>
    <motor name="Joint_Wrist_Motor_Output_Front_Right" joint="Joint_Wrist_Motor_Output_Front_Right" class="actuator_8"/>
    <motor name="Joint_Wrist_Motor_Output_Back_Right" joint="Joint_Wrist_Motor_Output_Back_Right" class="actuator_8"/>
    <!-- Hand actuators are disabled until a dedicated hand controller is wired in.
    <motor name="Right_0_Joint_Thumb_Proximal" joint="Right_0_Joint_Thumb_Proximal" class="actuator_8"/>
    <motor name="Right_1_Joint_Thumb_Middle" joint="Right_1_Joint_Thumb_Middle" class="actuator_8"/>
    <motor name="Right_2_Joint_Thumb_Distal" joint="Right_2_Joint_Thumb_Distal" class="actuator_8"/>
    <motor name="Right_3_Joint_Index_Middle" joint="Right_3_Joint_Index_Middle" class="actuator_8"/>
    <motor name="Right_4_Joint_Index_Distal" joint="Right_4_Joint_Index_Distal" class="actuator_8"/>
    <motor name="Right_5_Joint_Middle_Middle" joint="Right_5_Joint_Middle_Middle" class="actuator_8"/>
    <motor name="Right_6_Joint_Middle_Distal" joint="Right_6_Joint_Middle_Distal" class="actuator_8"/>
    <motor name="Right_7_Joint_Ring_Middle" joint="Right_7_Joint_Ring_Middle" class="actuator_8"/>
    <motor name="Right_8_Joint_Ring_Distal" joint="Right_8_Joint_Ring_Distal" class="actuator_8"/>
    <motor name="Right_9_Joint_Little_Middle" joint="Right_9_Joint_Little_Middle" class="actuator_8"/>
    <motor name="Right_10_Joint_Little_Distal" joint="Right_10_Joint_Little_Distal" class="actuator_8"/>
    -->
    <motor name="Joint_Neck_Yaw" joint="Joint_Neck_Yaw" class="actuator_7"/>
    <motor name="Joint_Neck_Pitch" joint="Joint_Neck_Pitch" class="actuator_7"/>
    <!-- POSITION CONTROL -->
    <position name="Joint_Waist_Yaw_Pos" joint="Joint_Waist_Yaw" kp="2000" kv="0" dampratio="1.1" ctrlrange="-3.14 3.14"/>
    <position name="Joint_Waist_Flange_Left_Pos" joint="Joint_Waist_Flange_Left" kp="2000" kv="0" dampratio="1.1" ctrlrange="-3.14 3.14"/>
    <position name="Joint_Waist_Flange_Right_Pos" joint="Joint_Waist_Flange_Right" kp="2000" kv="0" dampratio="1.1" ctrlrange="-3.14 3.14"/>
    <position name="Joint_Hip_Pitch_Left_Pos" joint="Joint_Hip_Pitch_Left" kp="2000" kv="0" dampratio="1.1" ctrlrange="-3.14 3.14"/>
    <position name="Joint_Hip_Roll_Left_Pos" joint="Joint_Hip_Roll_Left" kp="2000" kv="0" dampratio="1.1" ctrlrange="-3.14 3.14"/>
    <position name="Joint_Hip_Yaw_Left_Pos" joint="Joint_Hip_Yaw_Left" kp="2000" kv="0" dampratio="1.1" ctrlrange="-3.14 3.14"/>
    <position name="Joint_Knee_Pitch_Left_Pos" joint="Joint_Knee_Pitch_Left" kp="2000" kv="0" dampratio="1.1" ctrlrange="-3.14 3.14"/>
    <position name="Joint_Ankle_Flange_Out_Left_Pos" joint="Joint_Ankle_Flange_Out_Left" kp="2000" kv="0" dampratio="1.1" ctrlrange="-3.14 3.14"/>
    <position name="Joint_Ankle_Flange_In_Left_Pos" joint="Joint_Ankle_Flange_In_Left" kp="2000" kv="0" dampratio="1.1" ctrlrange="-3.14 3.14"/>
    <position name="Joint_Hip_Pitch_Right_Pos" joint="Joint_Hip_Pitch_Right" kp="2000" kv="0" dampratio="1.1" ctrlrange="-3.14 3.14"/>
    <position name="Joint_Hip_Roll_Right_Pos" joint="Joint_Hip_Roll_Right" kp="2000" kv="0" dampratio="1.1" ctrlrange="-3.14 3.14"/>
    <position name="Joint_Hip_Yaw_Right_Pos" joint="Joint_Hip_Yaw_Right" kp="2000" kv="0" dampratio="1.1" ctrlrange="-3.14 3.14"/>
    <position name="Joint_Knee_Pitch_Right_Pos" joint="Joint_Knee_Pitch_Right" kp="2000" kv="0" dampratio="1.1" ctrlrange="-3.14 3.14"/>
    <position name="Joint_Ankle_Flange_Out_Right_Pos" joint="Joint_Ankle_Flange_Out_Right" kp="2000" kv="0" dampratio="1.1" ctrlrange="-3.14 3.14"/>
    <position name="Joint_Ankle_Flange_In_Right_Pos" joint="Joint_Ankle_Flange_In_Right" kp="2000" kv="0" dampratio="1.1" ctrlrange="-3.14 3.14"/>
    <position name="Joint_Shoulder_Pitch_Left_Pos" joint="Joint_Shoulder_Pitch_Left" kp="2000" kv="0" dampratio="1.1" ctrlrange="-3.14 3.14"/>
    <position name="Joint_Shoulder_Roll_Left_Pos" joint="Joint_Shoulder_Roll_Left" kp="2000" kv="0" dampratio="1.1" ctrlrange="-3.14 3.14"/>
    <position name="Joint_Shoulder_Yaw_Left_Pos" joint="Joint_Shoulder_Yaw_Left" kp="2000" kv="0" dampratio="1.1" ctrlrange="-3.14 3.14"/>
    <position name="Joint_Elbow_Pitch_Left_Pos" joint="Joint_Elbow_Pitch_Left" kp="2000" kv="0" dampratio="1.1" ctrlrange="-3.14 3.14"/>
    <position name="Joint_Wrist_Yaw_Left_Pos" joint="Joint_Wrist_Yaw_Left" kp="2000" kv="0" dampratio="1.1" ctrlrange="-3.14 3.14"/>
    <position name="Joint_Wrist_Motor_Output_Front_Left_Pos" joint="Joint_Wrist_Motor_Output_Front_Left" kp="2000" kv="0" dampratio="1.1" ctrlrange="-3.14 3.14"/>
    <position name="Joint_Wrist_Motor_Output_Back_Left_Pos" joint="Joint_Wrist_Motor_Output_Back_Left" kp="2000" kv="0" dampratio="1.1" ctrlrange="-3.14 3.14"/>
    <!-- Hand actuators are disabled until a dedicated hand controller is wired in.
    <position name="Left_0_Joint_Thumb_Proximal_Pos" joint="Left_0_Joint_Thumb_Proximal" kp="2000" kv="0" dampratio="1.1" ctrlrange="-3.14 3.14"/>
    <position name="Left_1_Joint_Thumb_Middle_Pos" joint="Left_1_Joint_Thumb_Middle" kp="2000" kv="0" dampratio="1.1" ctrlrange="-3.14 3.14"/>
    <position name="Left_2_Joint_Thumb_Distal_Pos" joint="Left_2_Joint_Thumb_Distal" kp="2000" kv="0" dampratio="1.1" ctrlrange="-3.14 3.14"/>
    <position name="Left_3_Joint_Index_Middle_Pos" joint="Left_3_Joint_Index_Middle" kp="2000" kv="0" dampratio="1.1" ctrlrange="-3.14 3.14"/>
    <position name="Left_4_Joint_Index_Distal_Pos" joint="Left_4_Joint_Index_Distal" kp="2000" kv="0" dampratio="1.1" ctrlrange="-3.14 3.14"/>
    <position name="Left_5_Joint_Middle_Middle_Pos" joint="Left_5_Joint_Middle_Middle" kp="2000" kv="0" dampratio="1.1" ctrlrange="-3.14 3.14"/>
    <position name="Left_6_Joint_Middle_Distal_Pos" joint="Left_6_Joint_Middle_Distal" kp="2000" kv="0" dampratio="1.1" ctrlrange="-3.14 3.14"/>
    <position name="Left_7_Joint_Ring_Middle_Pos" joint="Left_7_Joint_Ring_Middle" kp="2000" kv="0" dampratio="1.1" ctrlrange="-3.14 3.14"/>
    <position name="Left_8_Joint_Ring_Distal_Pos" joint="Left_8_Joint_Ring_Distal" kp="2000" kv="0" dampratio="1.1" ctrlrange="-3.14 3.14"/>
    <position name="Left_9_Joint_Little_Middle_Pos" joint="Left_9_Joint_Little_Middle" kp="2000" kv="0" dampratio="1.1" ctrlrange="-3.14 3.14"/>
    <position name="Left_10_Joint_Little_Distal_Pos" joint="Left_10_Joint_Little_Distal" kp="2000" kv="0" dampratio="1.1" ctrlrange="-3.14 3.14"/>
    -->
    <position name="Joint_Shoulder_Pitch_Right_Pos" joint="Joint_Shoulder_Pitch_Right" kp="2000" kv="0" dampratio="1.1" ctrlrange="-3.14 3.14"/>
    <position name="Joint_Shoulder_Roll_Right_Pos" joint="Joint_Shoulder_Roll_Right" kp="2000" kv="0" dampratio="1.1" ctrlrange="-3.14 3.14"/>
    <position name="Joint_Shoulder_Yaw_Right_Pos" joint="Joint_Shoulder_Yaw_Right" kp="2000" kv="0" dampratio="1.1" ctrlrange="-3.14 3.14"/>
    <position name="Joint_Elbow_Pitch_Right_Pos" joint="Joint_Elbow_Pitch_Right" kp="2000" kv="0" dampratio="1.1" ctrlrange="-3.14 3.14"/>
    <position name="Joint_Wrist_Yaw_Right_Pos" joint="Joint_Wrist_Yaw_Right" kp="2000" kv="0" dampratio="1.1" ctrlrange="-3.14 3.14"/>
    <position name="Joint_Wrist_Motor_Output_Front_Right_Pos" joint="Joint_Wrist_Motor_Output_Front_Right" kp="2000" kv="0" dampratio="1.1" ctrlrange="-3.14 3.14"/>
    <position name="Joint_Wrist_Motor_Output_Back_Right_Pos" joint="Joint_Wrist_Motor_Output_Back_Right" kp="2000" kv="0" dampratio="1.1" ctrlrange="-3.14 3.14"/>
    <!-- Hand actuators are disabled until a dedicated hand controller is wired in.
    <position name="Right_0_Joint_Thumb_Proximal_Pos" joint="Right_0_Joint_Thumb_Proximal" kp="2000" kv="0" dampratio="1.1" ctrlrange="-3.14 3.14"/>
    <position name="Right_1_Joint_Thumb_Middle_Pos" joint="Right_1_Joint_Thumb_Middle" kp="2000" kv="0" dampratio="1.1" ctrlrange="-3.14 3.14"/>
    <position name="Right_2_Joint_Thumb_Distal_Pos" joint="Right_2_Joint_Thumb_Distal" kp="2000" kv="0" dampratio="1.1" ctrlrange="-3.14 3.14"/>
    <position name="Right_3_Joint_Index_Middle_Pos" joint="Right_3_Joint_Index_Middle" kp="2000" kv="0" dampratio="1.1" ctrlrange="-3.14 3.14"/>
    <position name="Right_4_Joint_Index_Distal_Pos" joint="Right_4_Joint_Index_Distal" kp="2000" kv="0" dampratio="1.1" ctrlrange="-3.14 3.14"/>
    <position name="Right_5_Joint_Middle_Middle_Pos" joint="Right_5_Joint_Middle_Middle" kp="2000" kv="0" dampratio="1.1" ctrlrange="-3.14 3.14"/>
    <position name="Right_6_Joint_Middle_Distal_Pos" joint="Right_6_Joint_Middle_Distal" kp="2000" kv="0" dampratio="1.1" ctrlrange="-3.14 3.14"/>
    <position name="Right_7_Joint_Ring_Middle_Pos" joint="Right_7_Joint_Ring_Middle" kp="2000" kv="0" dampratio="1.1" ctrlrange="-3.14 3.14"/>
    <position name="Right_8_Joint_Ring_Distal_Pos" joint="Right_8_Joint_Ring_Distal" kp="2000" kv="0" dampratio="1.1" ctrlrange="-3.14 3.14"/>
    <position name="Right_9_Joint_Little_Middle_Pos" joint="Right_9_Joint_Little_Middle" kp="2000" kv="0" dampratio="1.1" ctrlrange="-3.14 3.14"/>
    <position name="Right_10_Joint_Little_Distal_Pos" joint="Right_10_Joint_Little_Distal" kp="2000" kv="0" dampratio="1.1" ctrlrange="-3.14 3.14"/>
    -->
    <position name="Joint_Neck_Yaw_Pos" joint="Joint_Neck_Yaw" class="actuator_7" kp="2000" kv="0" dampratio="1.1" ctrlrange="-3.14 3.14"/>
    <position name="Joint_Neck_Pitch_Pos" joint="Joint_Neck_Pitch" class="actuator_7" kp="2000" kv="0" dampratio="1.1" ctrlrange="-3.14 3.14"/>
    <!-- VELOCITY CONTROL -->
    <velocity name="Joint_Waist_Yaw_Vel" joint="Joint_Waist_Yaw" kv="0" ctrlrange="-50 50"/>
    <velocity name="Joint_Waist_Flange_Left_Vel" joint="Joint_Waist_Flange_Left" kv="0" ctrlrange="-50 50"/>
    <velocity name="Joint_Waist_Flange_Right_Vel" joint="Joint_Waist_Flange_Right" kv="0" ctrlrange="-50 50"/>
    <velocity name="Joint_Hip_Pitch_Left_Vel" joint="Joint_Hip_Pitch_Left" kv="0" ctrlrange="-50 50"/>
    <velocity name="Joint_Hip_Roll_Left_Vel" joint="Joint_Hip_Roll_Left" kv="0" ctrlrange="-50 50"/>
    <velocity name="Joint_Hip_Yaw_Left_Vel" joint="Joint_Hip_Yaw_Left" kv="0" ctrlrange="-50 50"/>
    <velocity name="Joint_Knee_Pitch_Left_Vel" joint="Joint_Knee_Pitch_Left" kv="0" ctrlrange="-50 50"/>
    <velocity name="Joint_Ankle_Flange_Out_Left_Vel" joint="Joint_Ankle_Flange_Out_Left" kv="0" ctrlrange="-50 50"/>
    <velocity name="Joint_Ankle_Flange_In_Left_Vel" joint="Joint_Ankle_Flange_In_Left" kv="0" ctrlrange="-50 50"/>
    <velocity name="Joint_Hip_Pitch_Right_Vel" joint="Joint_Hip_Pitch_Right" kv="0" ctrlrange="-50 50"/>
    <velocity name="Joint_Hip_Roll_Right_Vel" joint="Joint_Hip_Roll_Right" kv="0" ctrlrange="-50 50"/>
    <velocity name="Joint_Hip_Yaw_Right_Vel" joint="Joint_Hip_Yaw_Right" kv="0" ctrlrange="-50 50"/>
    <velocity name="Joint_Knee_Pitch_Right_Vel" joint="Joint_Knee_Pitch_Right" kv="0" ctrlrange="-50 50"/>
    <velocity name="Joint_Ankle_Flange_Out_Right_Vel" joint="Joint_Ankle_Flange_Out_Right" kv="0" ctrlrange="-50 50"/>
    <velocity name="Joint_Ankle_Flange_In_Right_Vel" joint="Joint_Ankle_Flange_In_Right" kv="0" ctrlrange="-50 50"/>
    <velocity name="Joint_Shoulder_Pitch_Left_Vel" joint="Joint_Shoulder_Pitch_Left" kv="0" ctrlrange="-50 50"/>
    <velocity name="Joint_Shoulder_Roll_Left_Vel" joint="Joint_Shoulder_Roll_Left" kv="0" ctrlrange="-50 50"/>
    <velocity name="Joint_Shoulder_Yaw_Left_Vel" joint="Joint_Shoulder_Yaw_Left" kv="0" ctrlrange="-50 50"/>
    <velocity name="Joint_Elbow_Pitch_Left_Vel" joint="Joint_Elbow_Pitch_Left" kv="0" ctrlrange="-50 50"/>
    <velocity name="Joint_Wrist_Yaw_Left_Vel" joint="Joint_Wrist_Yaw_Left" kv="0" ctrlrange="-50 50"/>
    <velocity name="Joint_Wrist_Motor_Output_Front_Left_Vel" joint="Joint_Wrist_Motor_Output_Front_Left" kv="0" ctrlrange="-50 50"/>
    <velocity name="Joint_Wrist_Motor_Output_Back_Left_Vel" joint="Joint_Wrist_Motor_Output_Back_Left" kv="0" ctrlrange="-50 50"/>
    <!-- Hand actuators are disabled until a dedicated hand controller is wired in.
    <velocity name="Left_0_Joint_Thumb_Proximal_Vel" joint="Left_0_Joint_Thumb_Proximal" kv="0" ctrlrange="-50 50"/>
    <velocity name="Left_1_Joint_Thumb_Middle_Vel" joint="Left_1_Joint_Thumb_Middle" kv="0" ctrlrange="-50 50"/>
    <velocity name="Left_2_Joint_Thumb_Distal_Vel" joint="Left_2_Joint_Thumb_Distal" kv="0" ctrlrange="-50 50"/>
    <velocity name="Left_3_Joint_Index_Middle_Vel" joint="Left_3_Joint_Index_Middle" kv="0" ctrlrange="-50 50"/>
    <velocity name="Left_4_Joint_Index_Distal_Vel" joint="Left_4_Joint_Index_Distal" kv="0" ctrlrange="-50 50"/>
    <velocity name="Left_5_Joint_Middle_Middle_Vel" joint="Left_5_Joint_Middle_Middle" kv="0" ctrlrange="-50 50"/>
    <velocity name="Left_6_Joint_Middle_Distal_Vel" joint="Left_6_Joint_Middle_Distal" kv="0" ctrlrange="-50 50"/>
    <velocity name="Left_7_Joint_Ring_Middle_Vel" joint="Left_7_Joint_Ring_Middle" kv="0" ctrlrange="-50 50"/>
    <velocity name="Left_8_Joint_Ring_Distal_Vel" joint="Left_8_Joint_Ring_Distal" kv="0" ctrlrange="-50 50"/>
    <velocity name="Left_9_Joint_Little_Middle_Vel" joint="Left_9_Joint_Little_Middle" kv="0" ctrlrange="-50 50"/>
    <velocity name="Left_10_Joint_Little_Distal_Vel" joint="Left_10_Joint_Little_Distal" kv="0" ctrlrange="-50 50"/>
    -->
    <velocity name="Joint_Shoulder_Pitch_Right_Vel" joint="Joint_Shoulder_Pitch_Right" kv="0" ctrlrange="-50 50"/>
    <velocity name="Joint_Shoulder_Roll_Right_Vel" joint="Joint_Shoulder_Roll_Right" kv="0" ctrlrange="-50 50"/>
    <velocity name="Joint_Shoulder_Yaw_Right_Vel" joint="Joint_Shoulder_Yaw_Right" kv="0" ctrlrange="-50 50"/>
    <velocity name="Joint_Elbow_Pitch_Right_Vel" joint="Joint_Elbow_Pitch_Right" kv="0" ctrlrange="-50 50"/>
    <velocity name="Joint_Wrist_Yaw_Right_Vel" joint="Joint_Wrist_Yaw_Right" kv="0" ctrlrange="-50 50"/>
    <velocity name="Joint_Wrist_Motor_Output_Front_Right_Vel" joint="Joint_Wrist_Motor_Output_Front_Right" kv="0" ctrlrange="-50 50"/>
    <velocity name="Joint_Wrist_Motor_Output_Back_Right_Vel" joint="Joint_Wrist_Motor_Output_Back_Right" kv="0" ctrlrange="-50 50"/>
    <!-- Hand actuators are disabled until a dedicated hand controller is wired in.
    <velocity name="Right_0_Joint_Thumb_Proximal_Vel" joint="Right_0_Joint_Thumb_Proximal" kv="0" ctrlrange="-50 50"/>
    <velocity name="Right_1_Joint_Thumb_Middle_Vel" joint="Right_1_Joint_Thumb_Middle" kv="0" ctrlrange="-50 50"/>
    <velocity name="Right_2_Joint_Thumb_Distal_Vel" joint="Right_2_Joint_Thumb_Distal" kv="0" ctrlrange="-50 50"/>
    <velocity name="Right_3_Joint_Index_Middle_Vel" joint="Right_3_Joint_Index_Middle" kv="0" ctrlrange="-50 50"/>
    <velocity name="Right_4_Joint_Index_Distal_Vel" joint="Right_4_Joint_Index_Distal" kv="0" ctrlrange="-50 50"/>
    <velocity name="Right_5_Joint_Middle_Middle_Vel" joint="Right_5_Joint_Middle_Middle" kv="0" ctrlrange="-50 50"/>
    <velocity name="Right_6_Joint_Middle_Distal_Vel" joint="Right_6_Joint_Middle_Distal" kv="0" ctrlrange="-50 50"/>
    <velocity name="Right_7_Joint_Ring_Middle_Vel" joint="Right_7_Joint_Ring_Middle" kv="0" ctrlrange="-50 50"/>
    <velocity name="Right_8_Joint_Ring_Distal_Vel" joint="Right_8_Joint_Ring_Distal" kv="0" ctrlrange="-50 50"/>
    <velocity name="Right_9_Joint_Little_Middle_Vel" joint="Right_9_Joint_Little_Middle" kv="0" ctrlrange="-50 50"/>
    <velocity name="Right_10_Joint_Little_Distal_Vel" joint="Right_10_Joint_Little_Distal" kv="0" ctrlrange="-50 50"/>
    -->
    <velocity name="Joint_Neck_Yaw_Vel" joint="Joint_Neck_Yaw" kv="0" ctrlrange="-50 50"/>
    <velocity name="Joint_Neck_Pitch_Vel" joint="Joint_Neck_Pitch" kv="0" ctrlrange="-50 50"/>
  </actuator>
  <contact>
    <exclude body1="base_link" body2="Link_Waist_Pitch"/>
    <exclude body1="Link_Waist_Pitch" body2="Link_Waist_Roll"/>
    <exclude body1="Link_Waist_Roll" body2="Link_Waist_Yaw"/>
    <exclude body1="Link_Waist_Yaw" body2="Link_Neck_Yaw"/>
    <exclude body1="Link_Neck_Yaw" body2="Link_Neck_Pitch"/>
    <exclude body1="base_link" body2="Link_Hip_Pitch_Left"/>
    <exclude body1="Link_Hip_Pitch_Left" body2="Link_Hip_Roll_Left"/>
    <exclude body1="Link_Hip_Roll_Left" body2="Link_Hip_Yaw_Left"/>
    <exclude body1="Link_Hip_Yaw_Left" body2="Link_Knee_Pitch_Left"/>
    <exclude body1="Link_Knee_Pitch_Left" body2="Link_Ankle_Pitch_Left"/>
    <exclude body1="Link_Ankle_Pitch_Left" body2="Link_Ankle_Roll_Left"/>
    <exclude body1="base_link" body2="Link_Hip_Pitch_Right"/>
    <exclude body1="Link_Hip_Pitch_Right" body2="Link_Hip_Roll_Right"/>
    <exclude body1="Link_Hip_Roll_Right" body2="Link_Hip_Yaw_Right"/>
    <exclude body1="Link_Hip_Yaw_Right" body2="Link_Knee_Pitch_Right"/>
    <exclude body1="Link_Knee_Pitch_Right" body2="Link_Ankle_Pitch_Right"/>
    <exclude body1="Link_Ankle_Pitch_Right" body2="Link_Ankle_Roll_Right"/>
    <exclude body1="Link_Waist_Yaw" body2="Link_Shoulder_Pitch_Left"/>
    <exclude body1="Link_Shoulder_Pitch_Left" body2="Link_Shoulder_Roll_Left"/>
    <exclude body1="Link_Shoulder_Roll_Left" body2="Link_Shoulder_Yaw_Left"/>
    <exclude body1="Link_Shoulder_Yaw_Left" body2="Link_Elbow_Pitch_Left"/>
    <exclude body1="Link_Elbow_Pitch_Left" body2="Link_Wrist_Yaw_Left"/>
    <exclude body1="Link_Wrist_Yaw_Left" body2="Link_Wrist_Roll_Left"/>
    <exclude body1="Link_Wrist_Roll_Left" body2="Link_Wrist_Pitch_Left"/>
    <exclude body1="Link_Wrist_Pitch_Left" body2="Left_Hand"/>
    <exclude body1="Link_Waist_Yaw" body2="Link_Shoulder_Pitch_Right"/>
    <exclude body1="Link_Shoulder_Pitch_Right" body2="Link_Shoulder_Roll_Right"/>
    <exclude body1="Link_Shoulder_Roll_Right" body2="Link_Shoulder_Yaw_Right"/>
    <exclude body1="Link_Shoulder_Yaw_Right" body2="Link_Elbow_Pitch_Right"/>
    <exclude body1="Link_Elbow_Pitch_Right" body2="Link_Wrist_Yaw_Right"/>
    <exclude body1="Link_Wrist_Yaw_Right" body2="Link_Wrist_Roll_Right"/>
    <exclude body1="Link_Wrist_Roll_Right" body2="Link_Wrist_Pitch_Right"/>
    <exclude body1="Link_Wrist_Pitch_Right" body2="Right_Hand"/>
  </contact>
  <sensor>
    <gyro site="base_link_imu_site" name="imu-pelvis-angular-velocity" cutoff="34.9" noise="0.0005"/>
    <accelerometer site="base_link_imu_site" name="imu-pelvis-linear-acceleration" cutoff="157" noise="0.01"/>
    <framequat name="imu-pelvis-quat" objtype="site" objname="base_link_imu_site"/>
  </sensor>
  <keyframe>
    <key name="initial" qpos="0 0 0.754 1 0 0 0 -0.15 0 0.0 0.3 -0.15 0 -0. 1 0 0 0 -0. 1 0 0 0 -0.15 0 0.0 0.3 -0.15 0 -0. 1 0 0 0 -0. 1 0 0 0 0 1 0 0 0 0 1 0 0 0 0 0 0 0.13 0.13 0 -0.3 0 0 0 0 0 0 0 0 0 0 0 0 0 0 0 0 0 0 0 0 0 0 0 0 0.13 -0.13 0 -0.3 0 0 0 0 0 0 0 0 0 0 0 0 0 0 0 0 0 0 0 0 0 0 0 0 0 0"/>
  </keyframe>
</mujoco>
